File: ExampleData/T.1.1 Isothermal Section.csv
#EXPORTTYPE:DATA SINGLE,,,,
#FILE:,,,,
#FORMAT:NETZSCH5,,,,
#FTYPE:ANSI,,,,
#IDENTITY:,,,,
#DECIMAL:POINT,,,,
#SEPARATOR:SEMICOLON,,,,
#MTYPE:TG,,,,
#INSTRUMENT:NETZSCH STA 449F1,,,,
#PROJECT:,,,,
#DATE/TIME:25.01.2019 23:17,,,,
#CORR. FILE:,,,,
#TEMPCAL:TGA temperature calibration.ngb-ts1,,,,
#SENSITIVITY:---,,,,
#LABORATORY:,,,,
#OPERATOR:,,,,
#REMARK:,,,,
#SAMPLE:,,,,
#SAMPLE MASS /mg:950.91,,,,
#MATERIAL:,,,,
#REFERENCE:,,,,
#REFERENCE MASS /mg:,,,,
#TYPE OF CRUCIBLE:DTA/TG crucible Al2O3,,,,
#SAMPLE CRUCIBLE MASS /mg:0,,,,
#REFERENCE CRUCIBLE MASS /mg:,,,,
#TG RANGE /mg:5000,,,,
#TAU-R:---,,,,
#CORR. CODE:000,,,,
#EXO:-1,,,,
#RANGE:1200ÁC/04:00/1200ÁC,,,,
#SEGMENT:S4/4,,,,
#SEG. 4:1200ÁC/04:00/1200ÁC,,,,
,,,surface area,2.594946
##Temp./ÁC,Time/min,Mass loss/mg,,
1200.01818,46.5,0.930424,,
1199.97165,46.75,0.929203,,
1199.96979,47,0.943943,,
1199.98014,47.25,0.939301,,
1200.00433,47.5,0.940434,,
1200.01105,47.75,0.944196,,
1200.00574,48,0.949366,,
1199.99552,48.25,0.953854,,
1199.98109,48.5,0.951819,,
1199.97093,48.75,0.958826,,
1199.96201,49,0.960124,,
1199.95622,49.25,0.963765,,
1199.95488,49.5,0.960399,,
1199.95503,49.75,0.959321,,
1199.95592,50,0.964238,,
1199.95533,50.25,0.975172,,
1199.95344,50.5,0.966691,,
1199.95293,50.75,0.96459,,
1199.95738,51,0.968858,,
1199.96266,51.25,0.971729,,
1199.96995,51.5,0.969749,,
1199.96884,51.75,0.976041,,
1199.97079,52,0.976844,,
1199.97137,52.25,0.976063,,
1199.9741,52.5,0.979506,,
1199.97352,52.75,0.979517,,
1199.97094,53,0.980199,,
1199.97314,53.25,0.991617,,
1199.97698,53.5,0.986062,,
1199.98338,53.75,0.991012,,
1199.98447,54,0.990968,,
1199.98344,54.25,1.002782,,
1199.98394,54.5,0.998019,,
1199.98379,54.75,0.99737,,
1199.98563,55,0.996391,,
1199.98658,55.25,0.996655,,
1199.9876,55.5,1.005191,,
1199.98963,55.75,1.00067,,
1199.98986,56,1.010955,,
1199.99084,56.25,1.004828,,
1199.99253,56.5,1.014288,,
1199.99442,56.75,1.012484,,
1199.99908,57,1.013463,,
1199.99619,57.25,1.015289,,
1199.99669,57.5,1.017313,,
1199.99703,57.75,1.017368,,
1199.99958,58,1.015003,,
1200.00244,58.25,1.019744,,
1200.0031,58.5,1.032493,,
1200.00193,58.75,1.025266,,
1199.99989,59,1.017918,,
1200.00021,59.25,1.027939,,
1200.00364,59.5,1.027664,,
1200.00685,59.75,1.019194,,
1200.00886,60,1.030029,,
1200.01056,60.25,1.03422,,
1200.01014,60.5,1.02751,,
1200.01204,60.75,1.033186,,
1200.01179,61,1.030084,,
1200.01244,61.25,1.037905,,
1200.01298,61.5,1.030106,,
1200.01182,61.75,1.0351,,
1200.00997,62,1.035958,,
1200.00998,62.25,1.039071,,
1200.01243,62.5,1.047101,,
1200.01399,62.75,1.031283,,
1200.01609,63,1.041733,,
1200.01414,63.25,1.047167,,
1200.01158,63.5,1.037267,,
1200.00973,63.75,1.05116,,
1200.0087,64,1.050566,,
1200.00855,64.25,1.047343,,
1200.00799,64.5,1.047937,,
1200.00703,64.75,1.05369,,
1200.01114,65,1.048223,,
1200.01,65.25,1.059498,,
1200.01444,65.5,1.054834,,
1200.01551,65.75,1.054944,,
1200.01318,66,1.063205,,
1200.01489,66.25,1.068089,,
1200.01288,66.5,1.071499,,
1200.01528,66.75,1.067132,,
1200.01659,67,1.062259,,
1200.01662,67.25,1.060125,,
1200.01936,67.5,1.069299,,
1200.01944,67.75,1.073446,,
1200.02058,68,1.071895,,
1200.02131,68.25,1.070289,,
1200.0224,68.5,1.068837,,
1200.02006,68.75,1.071301,,
1200.02174,69,1.082169,,
1200.02146,69.25,1.077857,,
1200.02153,69.5,1.076878,,
1200.02404,69.75,1.075459,,
1200.02074,70,1.078693,,
1200.02101,70.25,1.086778,,
1200.01991,70.5,1.082807,,
1200.02378,70.75,1.081938,,
1200.02204,71,1.075921,,
1200.0209,71.25,1.097943,,
1200.01694,71.5,1.08196,,
1200.01633,71.75,1.092498,,
1200.01926,72,1.092993,,
1200.02114,72.25,1.072632,,
1200.02102,72.5,1.090892,,
1200.01938,72.75,1.102805,,
1200.01637,73,1.108184,,
1200.01572,73.25,1.102662,,
1200.01415,73.5,1.100231,,
1200.01381,73.75,1.093664,,
1200.01036,74,1.102772,,
1200.00804,74.25,1.104521,,
1200.0087,74.5,1.104246,,
1200.0073,74.75,1.103828,,
1200.01198,75,1.105984,,
1200.01064,75.25,1.111418,,
1200.01168,75.5,1.10539,,
1200.01153,75.75,1.101936,,
1200.0105,76,1.113002,,
1200.00719,76.25,1.107007,,
1200.00621,76.5,1.111913,,
1200.00846,76.75,1.112881,,
1200.01018,77,1.117105,,
1200.01246,77.25,1.117798,,
1200.01357,77.5,1.119382,,
1200.01312,77.75,1.121241,,
1200.01418,78,1.123903,,
1200.01268,78.25,1.118227,,
1200.0127,78.5,1.116643,,
1200.01153,78.75,1.130382,,
1200.01405,79,1.122374,,
1200.01734,79.25,1.126477,,
1200.02198,79.5,1.130129,,
1200.01889,79.75,1.125938,,
1200.01465,80,1.131449,,
1200.01007,80.25,1.132846,,
1200.01084,80.5,1.131053,,
1200.01154,80.75,1.134276,,
1200.01512,81,1.133506,,
1200.01411,81.25,1.132241,,
1200.0157,81.5,1.13806,,
1200.01771,81.75,1.140183,,
1200.01679,82,1.133,,
1200.01575,82.25,1.137818,,
1200.0181,82.5,1.141712,,
1200.02083,82.75,1.143692,,
1200.02193,83,1.147157,,
1200.01925,83.25,1.149335,,
1200.01923,83.5,1.148488,,
1200.01864,83.75,1.118975,,
1200.02097,84,1.148202,,
1200.01865,84.25,1.152305,,
1200.01688,84.5,1.151557,,
1200.01635,84.75,1.151744,,
1200.01316,85,1.153427,,
1200.01224,85.25,1.137444,,
1200.00822,85.5,1.154087,,
1200.01125,85.75,1.156804,,
1200.01643,86,1.144594,,
1200.01882,86.25,1.161941,,
1200.0172,86.5,1.174536,,
1200.01597,86.75,1.166418,,
1200.01449,87,1.165978,,
1200.01527,87.25,1.161105,,
1200.01565,87.5,1.171874,,
1200.01812,87.75,1.166506,,
1200.01915,88,1.157838,,
1200.01776,88.25,1.172622,,
1200.01337,88.5,1.170499,,
1200.01462,88.75,1.168365,,
1200.01868,89,1.173018,,
1200.0233,89.25,1.170587,,
1200.0214,89.5,1.164515,,
1200.0207,89.75,1.174591,,
1200.01959,90,1.174173,,
1200.01765,90.25,1.163998,,
1200.01717,90.5,1.176131,,
1200.01638,90.75,1.179123,,
1200.01348,91,1.173062,,
1200.01481,91.25,1.174833,,
1200.01459,91.5,1.179046,,
1200.01836,91.75,1.185866,,
1200.0193,92,1.185338,,
1200.01881,92.25,1.178738,,
1200.01713,92.5,1.182984,,
1200.01512,92.75,1.187032,,
1200.01623,93,1.194754,,
1200.01404,93.25,1.188869,,
1200.01244,93.5,1.187505,,
1200.01539,93.75,1.188792,,
1200.01568,94,1.189936,,
1200.01801,94.25,1.19273,,
1200.01477,94.5,1.207008,,
1200.01419,94.75,1.198857,,
1200.0133,95,1.162579,,
1200.0169,95.25,1.185426,,
1200.01838,95.5,1.187692,,
1200.02072,95.75,1.193335,,
1200.01887,96,1.170829,,
1200.01625,96.25,1.185591,,
1200.0173,96.5,1.207822,,
1200.01742,96.75,1.196107,,
1200.02163,97,1.203059,,
1200.01994,97.25,1.205589,,
1200.01846,97.5,1.201706,,
1200.01774,97.75,1.202575,,
1200.01644,98,1.214873,,
1200.01746,98.25,1.208768,,
1200.01882,98.5,1.215929,,
1200.02029,98.75,1.212849,,
1200.02107,99,1.205358,,
1200.02264,99.25,1.210814,,
1200.02379,99.5,1.213399,,
1200.02316,99.75,1.213542,,
1200.02219,100,1.212123,,
1200.02059,100.25,1.217634,,
1200.02064,100.5,1.214312,,
1200.01849,100.75,1.210715,,
1200.01706,101,1.214312,,
1200.01661,101.25,1.218481,,
1200.01354,101.5,1.218932,,
1200.01488,101.75,1.218415,,
1200.01582,102,1.212673,,
1200.01913,102.25,1.218415,,
1200.01858,102.5,1.219834,,
1200.01869,102.75,1.226335,,
1200.01853,103,1.223695,,
1200.01752,103.25,1.220065,,
1200.01604,103.5,1.22716,,
1200.01713,103.75,1.223079,,
1200.01711,104,1.227402,,
1200.0168,104.25,1.230218,,
1200.01801,104.5,1.223156,,
1200.01703,104.75,1.223651,,
1200.01755,105,1.227116,,
1200.01542,105.25,1.234068,,
1200.01619,105.5,1.227501,,
1200.01588,105.75,1.239194,,
1200.01772,106,1.231406,,
1200.01737,106.25,1.23024,,
1200.01661,106.5,1.238325,,
1200.01678,106.75,1.234464,,
1200.01485,107,1.240019,,
1200.01683,107.25,1.237819,,
1200.01507,107.5,1.232209,,
1200.01441,107.75,1.235718,,
1200.01501,108,1.239051,,
1200.01651,108.25,1.241482,,
1200.01676,108.5,1.241592,,
1200.01636,108.75,1.245255,,
1200.01837,109,1.243385,,
1200.01389,109.25,1.232506,,
1200.01616,109.5,1.235036,,
1200.01607,109.75,1.24432,,
1200.01885,110,1.261326,,
1200.01509,110.25,1.264626,,
1200.013,110.5,1.259027,,
1200.01167,110.75,1.253164,,
1200.01465,111,1.25279,,
1200.01551,111.25,1.252174,,
1200.0162,111.5,1.251481,,
1200.01427,111.75,1.251019,,
1200.01404,112,1.25741,,
1200.01358,112.25,1.261326,,
1200.01219,112.5,1.264549,,
1200.01328,112.75,1.26665,,
1200.01531,113,1.265748,,
1200.01708,113.25,1.266716,,
1200.02016,113.5,1.260094,,
1200.02281,113.75,1.266441,,
1200.02253,114,1.265341,,
1200.02411,114.25,1.263152,,
1200.02254,114.5,1.264725,,
1200.02116,114.75,1.269202,,
1200.02126,115,1.242043,,
1200.02216,115.25,1.270775,,
1200.02366,115.5,1.273063,,
1200.02522,115.75,1.271677,,
1200.0246,116,1.265847,,
1200.01981,116.25,1.272282,,
1200.01811,116.5,1.272975,,
1200.01582,116.75,1.273184,,
1200.01768,117,1.270852,,
1200.01776,117.25,1.280147,,
1200.0147,117.5,1.27886,,
1200.0136,117.75,1.278354,,
1200.01036,118,1.279245,,
1200.0154,118.25,1.280147,,
1200.0157,118.5,1.280873,,
1200.01587,118.75,1.279267,,
1200.01291,119,1.284261,,
1200.01192,119.25,1.281346,,
1200.01395,119.5,1.283073,,
1200.01767,119.75,1.283491,,
1200.02149,120,1.280466,,
1200.01744,120.25,1.286021,,
1200.01486,120.5,1.292665,,
1200.00994,120.75,1.286758,,
1200.01059,121,1.286923,,
1200.01119,121.25,1.296702,,
1200.01509,121.5,1.296438,,
1200.019,121.75,1.289937,,
1200.01714,122,1.298198,,
1200.01802,122.25,1.296922,,
1200.01754,122.5,1.293897,,
1200.02034,122.75,1.294909,,
1200.02057,123,1.301036,,
1200.01755,123.25,1.294744,,
1200.01747,123.5,1.301608,,
1200.01846,123.75,1.299584,,
1200.02058,124,1.300805,,
1200.02432,124.25,1.292984,,
1200.02175,124.5,1.309319,,
1200.02192,124.75,1.301223,,
1200.02144,125,1.299419,,
1200.02185,125.25,1.301762,,
1200.02148,125.5,1.303082,,
1200.0198,125.75,1.308164,,
1200.01863,126,1.307427,,
1200.01876,126.25,1.305326,,
1200.02177,126.5,1.304644,,
1200.02204,126.75,1.312234,,
1200.02135,127,1.315006,,
1200.02023,127.25,1.313752,,
1200.01859,127.5,1.308912,,
1200.0168,127.75,1.313158,,
1200.01608,128,1.312751,,
1200.01265,128.25,1.322706,,
1200.01338,128.5,1.310639,,
1200.01473,128.75,1.311508,,
1200.01728,129,1.314742,,
1200.01921,129.25,1.314038,,
1200.01839,129.5,1.313873,,
1200.01829,129.75,1.32187,,
1200.01945,130,1.316062,,
1200.01914,130.25,1.317646,,
1200.02058,130.5,1.322288,,
1200.01798,130.75,1.317173,,
1200.01722,131,1.31769,,
1200.01509,131.25,1.324246,,
1200.01803,131.5,1.323036,,
1200.01747,131.75,1.328415,,
1200.02069,132,1.316634,,
1200.02134,132.25,1.329196,,
1200.02279,132.5,1.33111,,
1200.01898,132.75,1.319494,,
1200.01729,133,1.337831,,
1200.0167,133.25,1.325115,,
1200.01577,133.5,1.328558,,
1200.01654,133.75,1.332639,,
1200.01535,134,1.328635,,
1200.01635,134.25,1.333156,,
1200.01676,134.5,1.339569,,
1200.01891,134.75,1.336236,,
1200.01754,135,1.333321,,
1200.01589,135.25,1.337281,,
1200.01513,135.5,1.339074,,
1200.01323,135.75,1.344046,,
1200.01628,136,1.339173,,
1200.01558,136.25,1.334597,,
1200.01205,136.5,1.345564,,
1200.00855,136.75,1.348006,,
1200.00818,137,1.341769,,
1200.00864,137.25,1.346378,,
1200.01578,137.5,1.340592,,
1200.01973,137.75,1.346125,,
1200.02218,138,1.34398,,
1200.02284,138.25,1.346664,,
1200.01992,138.5,1.355189,,
1200.01826,138.75,1.34926,,
1200.01769,139,1.344992,,
1200.01555,139.25,1.338161,,
1200.01743,139.5,1.361646,,
1200.01582,139.75,1.357752,,
1200.01483,140,1.357895,,
1200.01584,140.25,1.35212,,
1200.01439,140.5,1.354606,,
1200.01572,140.75,1.348985,,
1200.01478,141,1.360964,,
1200.01566,141.25,1.355706,,
1200.01773,141.5,1.35201,,
1200.01869,141.75,1.362735,,
1200.01497,142,1.36004,,
1200.01468,142.25,1.35905,,
1200.01494,142.5,1.355167,,
1200.0171,142.75,1.36235,,
1200.0205,143,1.35509,,
1200.0194,143.25,1.35476,,
1200.01985,143.5,1.360832,,
1200.0179,143.75,1.36851,,
1200.01684,144,1.371656,,
1200.01641,144.25,1.367113,,
1200.01769,144.5,1.369071,,
1200.01732,144.75,1.366057,,
1200.01553,145,1.360645,,
1200.0175,145.25,1.366387,,
1200.01551,145.5,1.357444,,
1200.02005,145.75,1.375011,,
1200.01672,146,1.365122,,
1200.01933,146.25,1.371678,,
1200.02174,146.5,1.371073,,
1200.02432,146.75,1.371865,,
1200.02327,147,1.377024,,
1200.01941,147.25,1.368235,,
1200.01613,147.5,1.373075,,
1200.01846,147.75,1.372217,,
1200.0212,148,1.378377,,
1200.02556,148.25,1.375968,,
1200.02282,148.5,1.378476,,
1200.02224,148.75,1.381204,,
1200.02077,149,1.385802,,
1200.01987,149.25,1.380907,,
1200.02015,149.5,1.380841,,
1200.01964,149.75,1.381589,,
1200.0214,150,1.384724,,
1200.02083,150.25,1.385043,,
1200.02285,150.5,1.381325,,
1200.02318,150.75,1.389124,,
1200.01972,151,1.391335,,
1200.01891,151.25,1.383448,,
1200.01816,151.5,1.387276,,
1200.02031,151.75,1.389938,,
1200.02334,152,1.39029,,
1200.02193,152.25,1.39315,,
1200.02034,152.5,1.391841,,
1200.01651,152.75,1.390961,,
1200.01768,153,1.39084,,
1200.01493,153.25,1.392677,,
1200.01655,153.5,1.394052,,
1200.01458,153.75,1.397055,,
1200.01715,154,1.392446,,
1200.01829,154.25,1.402302,,
1200.0204,154.5,1.393414,,
1200.01837,154.75,1.401136,,
1200.01554,155,1.398375,,
1200.01371,155.25,1.400575,,
1200.01388,155.5,1.400927,,
1200.01448,155.75,1.39931,,
1200.015,156,1.400014,,
1200.01579,156.25,1.402071,,
1200.0161,156.5,1.397275,,
1200.01462,156.75,1.400278,,
1200.01301,157,1.393722,,
1200.01307,157.25,1.405822,,
1200.01406,157.5,1.405404,,
1200.01482,157.75,1.405624,,
1200.01682,158,1.40162,,
1200.01669,158.25,1.408836,,
1200.01642,158.5,1.401785,,
1200.01453,158.75,1.410904,,
1200.01639,159,1.409749,,
1200.01493,159.25,1.410926,,
1200.0129,159.5,1.418252,,
1200.01091,159.75,1.409375,,
1200.01184,160,1.40624,,
1200.02068,160.25,1.411608,,
1200.02743,160.5,1.417449,,
1200.02699,160.75,1.414611,,
1200.0232,161,1.413148,,
1200.01899,161.25,1.417757,,
1200.01836,161.5,1.420001,,
1200.01651,161.75,1.404447,,
1200.01432,162,1.420276,,
1200.01599,162.25,1.419572,,
1200.01834,162.5,1.418351,,
1200.02179,162.75,1.423235,,
1200.02296,163,1.422883,,
1200.02281,163.25,1.422322,,
1200.02333,163.5,1.420617,,
1200.02234,163.75,1.4223,,
1200.02043,164,1.427404,,
1200.01966,164.25,1.421629,,
1200.01821,164.5,1.422333,,
1200.02066,164.75,1.423125,,
1200.01839,165,1.428999,,
1200.01797,165.25,1.423224,,
1200.01884,165.5,1.421772,,
1200.01623,165.75,1.428053,,
1200.0177,166,1.432299,,
1200.01939,166.25,1.426766,,
1200.02315,166.5,1.435346,,
1200.02549,166.75,1.427855,,
1200.02377,167,1.428526,,
1200.01977,167.25,1.434367,,
1200.01835,167.5,1.430946,,
1200.01515,167.75,1.434037,,
1200.01804,168,1.435478,,
1200.01713,168.25,1.434048,,
1200.01862,168.5,1.43605,,
1200.02108,168.75,1.432167,,
1200.02351,169,1.438041,,
1200.02303,169.25,1.43352,,
1200.02161,169.5,1.431727,,
1200.01931,169.75,1.436655,,
1200.01694,170,1.440648,,
1200.01621,170.25,1.443607,,
1200.01713,170.5,1.440516,,
1200.01841,170.75,1.438382,,
1200.01921,171,1.441616,,
1200.02116,171.25,1.442859,,
1200.02016,171.5,1.442144,,
1200.01924,171.75,1.446412,,
1200.01873,172,1.441572,,
1200.01714,172.25,1.442034,,
1200.02052,172.5,1.446269,,
1200.01962,172.75,1.44419,,
1200.02103,173,1.444212,,
1200.02208,173.25,1.448975,,
1200.02151,173.5,1.44199,,
1200.02099,173.75,1.451978,,
1200.02049,174,1.427228,,
1200.02088,174.25,1.452429,,
1200.02171,174.5,1.449404,,
1200.02288,174.75,1.454816,,
1200.02399,175,1.450691,,
1200.01979,175.25,1.458842,,
1200.01585,175.5,1.455894,,
1200.01832,175.75,1.455168,,
1200.02305,176,1.450119,,
1200.03152,176.25,1.454233,,
1200.03249,176.5,1.452176,,
1200.0288,176.75,1.457687,,
1200.02486,177,1.455146,,
1200.0205,177.25,1.460415,,
1200.01821,177.5,1.461845,,
1200.01577,177.75,1.461383,,
1200.01993,178,1.458721,,
1200.02008,178.25,1.458754,,
1200.02324,178.5,1.454706,,
1200.02463,178.75,1.461526,,
1200.02462,179,1.451208,,
1200.02503,179.25,1.469127,,
1200.02248,179.5,1.466124,,
1200.01927,179.75,1.460965,,
1200.01742,180,1.471316,,
1200.01387,180.25,1.470568,,
1200.01498,180.5,1.466267,,
1200.01691,180.75,1.468159,,
1200.0222,181,1.474935,,
1200.02063,181.25,1.473945,,
1200.02046,181.5,1.462516,,
1200.01958,181.75,1.482019,,
1200.02062,182,1.482437,,
1200.02416,182.25,1.478004,,
1200.02364,182.5,1.470458,,
1200.02206,182.75,1.473164,,
1200.01779,183,1.471415,,
1200.01567,183.25,1.467851,,
1200.01463,183.5,1.479544,,
1200.01293,183.75,1.477872,,
1200.01344,184,1.480061,,
1200.01601,184.25,1.481128,,
1200.02279,184.5,1.477916,,
1200.02678,184.75,1.484417,,
1200.02661,185,1.478752,,
1200.02541,185.25,1.47466,,
1200.02317,185.5,1.477575,,
1200.024,185.75,1.487255,,
1200.02015,186,1.478455,,
1200.02065,186.25,1.469127,,
1200.01598,186.5,1.478664,,
1200.01395,186.75,1.471338,,
1200.01303,187,1.482976,,
1200.0178,187.25,1.489279,,
1200.02377,187.5,1.479786,,
1200.02915,187.75,1.480248,,
1200.02857,188,1.48071,,
1200.02664,188.25,1.489433,,
1200.02235,188.5,1.482536,,
1200.01917,188.75,1.485836,,
1200.01772,189,1.480523,,
1200.02084,189.25,1.491776,,
1200.01973,189.5,1.483394,,
1200.02055,189.75,1.491083,,
1200.01905,190,1.489873,,
1200.01538,190.25,1.485297,,
1200.01521,190.5,1.495835,,
1200.0104,190.75,1.487486,,
1200.01229,191,1.494559,,
1200.01251,191.25,1.502699,,
1200.01249,191.5,1.492106,,
1200.01561,191.75,1.494361,,
1200.01593,192,1.494449,,
1200.02052,192.25,1.486551,,
1200.02041,192.5,1.501412,,
1200.01871,192.75,1.493888,,
1200.01606,193,1.50139,,
1200.01507,193.25,1.507264,,
1200.01275,193.5,1.494889,,
1200.01303,193.75,1.503975,,
1200.01306,194,1.497507,,
1200.0155,194.25,1.513358,,
1200.01729,194.5,1.511092,,
1200.01662,194.75,1.503161,,
1200.01234,195,1.50469,,
1200.01335,195.25,1.496297,,
1200.01406,195.5,1.513116,,
1200.01703,195.75,1.508672,,
1200.01731,196,1.506329,,
1200.01619,196.25,1.510091,,
1200.0157,196.5,1.503678,,
1200.01667,196.75,1.512654,,
1200.01892,197,1.50711,,
1200.01907,197.25,1.512951,,
1200.02084,197.5,1.514183,,
1200.01974,197.75,1.515701,,
1200.0181,198,1.511565,,
1200.01518,198.25,1.516581,,
1200.01406,198.5,1.522455,,
1200.01158,198.75,1.511521,,
1200.01468,199,1.528318,,
1200.0174,199.25,1.516691,,
1200.02145,199.5,1.515778,,
1200.02236,199.75,1.52273,,
1200.01939,200,1.515701,,
1200.01424,200.25,1.516889,,
1200.01275,200.5,1.516922,,
1200.01499,200.75,1.510047,,
1200.01918,201,1.519518,,
1200.02079,201.25,1.52284,,
1200.02183,201.5,1.522543,,
1200.02307,201.75,1.522389,,
1200.02353,202,1.514579,,
1200.02161,202.25,1.52229,,
1200.01655,202.5,1.521828,,
1200.01368,202.75,1.528142,,
1200.01591,203,1.518814,,
1200.0193,203.25,1.519639,,
1200.02035,203.5,1.520497,,
1200.02095,203.75,1.524985,,
1200.02012,204,1.52812,,
1200.0203,204.25,1.523181,,
1200.01787,204.5,1.533257,,
1200.01671,204.75,1.521091,,
1200.01772,205,1.523192,,
1200.02129,205.25,1.525557,,
1200.01874,205.5,1.53483,,
1200.02126,205.75,1.524853,,
1200.0208,206,1.539516,,
1200.02092,206.25,1.538812,,
1200.021,206.5,1.536568,,
1200.01956,206.75,1.539604,,
1200.01777,207,1.541089,,
1200.01791,207.25,1.539725,,
1200.01685,207.5,1.529528,,
1200.01609,207.75,1.534335,,
1200.01377,208,1.535578,,
1200.01372,208.25,1.544488,,
1200.01435,208.5,1.532894,,
1200.01905,208.75,1.551209,,
1200.02131,209,1.538262,,
1200.0204,209.25,1.533378,,
1200.02121,209.5,1.542904,,
1200.02112,209.75,1.541364,,
1200.01992,210,1.540396,,
1200.01894,210.25,1.539967,,
1200.01997,210.5,1.542728,,
1200.01882,210.75,1.552364,,
1200.01947,211,1.536524,,
1200.01773,211.25,1.539296,,
1200.01597,211.5,1.544686,,
1200.01861,211.75,1.540781,,
1200.02021,212,1.55265,,
1200.0208,212.25,1.547755,,
1200.01726,212.5,1.540374,,
1200.01641,212.75,1.546094,,
1200.01657,213,1.546589,,
1200.01796,213.25,1.562825,,
1200.01843,213.5,1.54517,,
1200.01503,213.75,1.550659,,
1200.01566,214,1.562418,,
1200.01688,214.25,1.554982,,
1200.01887,214.5,1.552419,,
1200.0222,214.75,1.557171,,
1200.02236,215,1.549273,,
1200.02222,215.25,1.559976,,
1200.02101,215.5,1.561208,,
1200.02108,215.75,1.550934,,
1200.02057,216,1.550054,,
1200.01946,216.25,1.5697,,
1200.01691,216.5,1.565113,,
1200.0131,216.75,1.550494,,
1200.01137,217,1.564255,,
1200.01379,217.25,1.560878,,
1200.01449,217.5,1.562385,,
1200.01744,217.75,1.558634,,
1200.01875,218,1.550857,,
1200.01789,218.25,1.563903,,
1200.01758,218.5,1.570327,,
1200.01654,218.75,1.566928,,
1200.01529,219,1.574254,,
1200.01653,219.25,1.562627,,
1200.01275,219.5,1.566862,,
1200.01348,219.75,1.561362,,
1200.01741,220,1.556687,,
1200.02043,220.25,1.569876,,
1200.0208,220.5,1.568457,,
1200.01745,220.75,1.557292,,
1200.01824,221,1.560669,,
1200.01777,221.25,1.562143,,
1200.01721,221.5,1.569425,,
1200.02087,221.75,1.565608,,
1200.01981,222,1.570404,,
1200.02442,222.25,1.559899,,
1200.0245,222.5,1.576597,,
1200.02328,222.75,1.566884,,
1200.02075,223,1.572142,,
1200.01764,223.25,1.580722,,
1200.01522,223.5,1.571636,,
1200.0138,223.75,1.582009,,
1200.01587,224,1.574122,,
1200.01925,224.25,1.566235,,
1200.02002,224.5,1.58312,,
1200.02103,224.75,1.584891,,
1200.01848,225,1.577851,,
1200.01803,225.25,1.569392,,
1200.01737,225.5,1.579006,,
1200.01764,225.75,1.585001,,
1200.01881,226,1.580425,,
1200.02019,226.25,1.575079,,
1200.02001,226.5,1.574551,,
1200.02131,226.75,1.576652,,
1200.02076,227,1.59577,,
1200.02198,227.25,1.573319,,
1200.01938,227.5,1.582669,,
1200.01874,227.75,1.588884,,
1200.01209,228,1.590127,,
1200.01035,228.25,1.575233,,
1200.01294,228.5,1.593075,,
1200.01896,228.75,1.580238,,
1200.02405,229,1.590523,,
1200.02661,229.25,1.589973,,
1200.02371,229.5,1.579765,,
1200.02441,229.75,1.588015,,
1200.02297,230,1.588972,,
1200.02416,230.25,1.589951,,
1200.01945,230.5,1.589093,,
1200.01829,230.75,1.589555,,
1200.01896,231,1.590622,,
1200.02108,231.25,1.584671,,
1200.02374,231.5,1.593779,,
1200.02292,231.75,1.588125,,
1200.02012,232,1.581701,,
1200.01427,232.25,1.598069,,
1200.01305,232.5,1.603052,,
1200.01723,232.75,1.594054,,
1200.01962,233,1.593042,,
1200.02505,233.25,1.600742,,
1200.02069,233.5,1.587674,,
1200.01937,233.75,1.586893,,
1200.01732,234,1.59049,,
1200.01784,234.25,1.605043,,
1200.01881,234.5,1.605087,,
1200.01912,234.75,1.602491,,
1200.01733,235,1.600885,,
1200.01546,235.25,1.593548,,
1200.01743,235.5,1.606649,,
1200.0188,235.75,1.612006,,
1200.01948,236,1.605494,,
1200.01691,236.25,1.597519,,
1200.01457,236.5,1.599356,,
1200.01733,236.75,1.595781,,
1200.01996,237,1.607485,,
1200.0235,237.25,1.616098,,
1200.01938,237.5,1.612853,,
1200.01578,237.75,1.608112,,
1200.01598,238,1.597695,,
1200.01945,238.25,1.602722,,
1200.02231,238.5,1.606627,,
1200.02018,238.75,1.614151,,
1200.01642,239,1.609542,,
1200.01623,239.25,1.598124,,
1200.01536,239.5,1.610763,,
1200.01569,239.75,1.617154,,
1200.01604,240,1.614118,,
1200.01675,240.25,1.605703,,
1200.02049,240.5,1.620916,,
1200.02048,240.75,1.624249,,
1200.01807,241,1.613458,,
1200.01986,241.25,1.624502,,
1200.02268,241.5,1.614899,,
1200.0244,241.75,1.612446,,
1200.02166,242,1.620707,,
1200.01906,242.25,1.61095,,
1200.01557,242.5,1.607386,,
1200.01592,242.75,1.612281,,
1200.01653,243,1.61051,,
1200.01802,243.25,1.620575,,
1200.02081,243.5,1.622291,,
1200.02,243.75,1.608057,,
1200.02028,244,1.613601,,
1200.02222,244.25,1.625239,,
1200.02271,244.5,1.631146,,
1200.02748,244.75,1.619486,,
1200.02664,245,1.62844,,
1200.02581,245.25,1.616109,,
1200.02509,245.5,1.627505,,
1200.02441,245.75,1.621631,,
1200.02586,246,1.623028,,
1200.02706,246.25,1.62514,,
1200.0244,246.5,1.62459,,
1200.01895,246.75,1.618265,,
1200.0176,247,1.629606,,
1200.01884,247.25,1.628418,,
1200.02085,247.5,1.632246,,
1200.02312,247.75,1.631289,,
1200.02295,248,1.629221,,
1200.02571,248.25,1.629925,,
1200.02382,248.5,1.632873,,
1200.02493,248.75,1.634369,,
1200.02503,249,1.629903,,
1200.02453,249.25,1.629584,,
1200.02692,249.5,1.636624,,
1200.02587,249.75,1.629628,,
1200.02358,250,1.633456,,
1200.01662,250.25,1.629056,,
1200.01241,250.5,1.619013,,
1200.0141,250.75,1.638318,,
1200.01853,251,1.63581,,
1200.02219,251.25,1.631729,,
1200.0226,251.5,1.632246,,
1200.02125,251.75,1.632785,,
1200.02256,252,1.63163,,
1200.02354,252.25,1.642366,,
1200.02389,252.5,1.642773,,
1200.02485,252.75,1.642355,,
1200.02427,253,1.638582,,
1200.02375,253.25,1.641794,,
1200.02246,253.5,1.638021,,
1200.01625,253.75,1.641541,,
1200.01138,254,1.630453,,
1200.00944,254.25,1.646403,,
1200.01518,254.5,1.650396,,
1200.02095,254.75,1.644478,,
1200.0274,255,1.643191,,
1200.02576,255.25,1.645963,,
1200.02252,255.5,1.652607,,
1200.01965,255.75,1.6511,,
1200.01619,256,1.647635,,
1200.01451,256.25,1.64373,,
1200.01466,256.5,1.648295,,
1200.01868,256.75,1.646579,,
1200.02004,257,1.648207,,
1200.01999,257.25,1.65253,,
1200.01595,257.5,1.649142,,
1200.01379,257.75,1.649505,,
1200.01407,258,1.651067,,
1200.01429,258.25,1.650935,,
1200.01404,258.5,1.653047,,
1200.01465,258.75,1.65352,,
1200.01621,259,1.647712,,
1200.01564,259.25,1.6566,,
1200.01455,259.5,1.658382,,
1200.01726,259.75,1.65605,,
1200.01395,260,1.656325,,
1200.01576,260.25,1.655863,,
1200.01773,260.5,1.656127,,
1200.01965,260.75,1.656347,,
1200.0257,261,1.655951,,
1200.02241,261.25,1.656545,,
1200.01999,261.5,1.655797,,
1200.01979,261.75,1.659944,,
1200.02071,262,1.653938,,
1200.01746,262.25,1.658492,,
1200.01389,262.5,1.658415,,
1200.01365,262.75,1.658954,,
1200.01922,263,1.661924,,
1200.02368,263.25,1.662155,,
1200.02692,263.5,1.663607,,
1200.02314,263.75,1.664476,,
1200.02082,264,1.659394,,
1200.0222,264.25,1.661583,,
1200.02093,264.5,1.666874,,
1200.02094,264.75,1.666995,,
1200.01767,265,1.66364,,
1200.02148,265.25,1.665037,,
1200.02244,265.5,1.666753,,
1200.02821,265.75,1.671164,,
1200.02345,266,1.671791,,
1200.02261,266.25,1.667776,,
1200.02115,266.5,1.666269,,
1200.02257,266.75,1.659834,,
1200.02514,267,1.672165,,
1200.0205,267.25,1.667963,,
1200.0197,267.5,1.665224,,
1200.01969,267.75,1.675982,,
1200.02271,268,1.676565,,
1200.02857,268.25,1.672759,,
1200.03055,268.5,1.67838,,
1200.02985,268.75,1.66705,,
1200.02619,269,1.669734,,
1200.02469,269.25,1.676433,,
1200.0226,269.5,1.67519,,
1200.02151,269.75,1.6753,,
1200.02292,270,1.684243,,
1200.01907,270.25,1.678061,,
1200.01763,270.5,1.680492,,
1200.01765,270.75,1.676785,,
1200.01896,271,1.682747,,
1200.02002,271.25,1.676499,,
1200.02496,271.5,1.67926,,
1200.02555,271.75,1.675971,,
1200.02784,272,1.674552,,
1200.02537,272.25,1.68234,,
1200.02421,272.5,1.677852,,
1200.02101,272.75,1.682131,,
1200.01962,273,1.684309,,
1200.02108,273.25,1.680316,,
1200.01981,273.5,1.677236,,
1200.02276,273.75,1.689754,,
1200.02172,274,1.687411,,
1200.02305,274.25,1.683484,,
1200.02274,274.5,1.682758,,
1200.02279,274.75,1.691349,,
1200.01583,275,1.683319,,
1200.01447,275.25,1.688445,,
1200.01252,275.5,1.687708,,
1200.01708,275.75,1.691393,,
1200.01992,276,1.688808,,
1200.02186,276.25,1.691085,,
1200.02125,276.5,1.691272,,
1200.02099,276.75,1.699632,,
1200.02047,277,1.684177,,
1200.02029,277.25,1.683418,,
1200.01812,277.5,1.698686,,
1200.01777,277.75,1.694572,,
1200.01671,278,1.68157,,
1200.01827,278.25,1.697278,,
1200.0202,278.5,1.695309,,
1200.02371,278.75,1.694704,,
1200.02242,279,1.705935,,
1200.02051,279.25,1.696827,,
1200.01769,279.5,1.683275,,
1200.01644,279.75,1.696486,,
1200.01731,280,1.690612,,
1200.01754,280.25,1.681955,,
1200.01852,280.5,1.693263,,
1200.01868,280.75,1.695529,,
1200.01927,281,1.699478,,
1200.01804,281.25,1.688676,,
1200.01832,281.5,1.689248,,
1200.01549,281.75,1.709631,,
1200.01766,282,1.685695,,
1200.01444,282.25,1.698884,,
1200.01294,282.5,1.69213,,
1200.01352,282.75,1.700204,,
1200.01787,283,1.704681,,
1200.02179,283.25,1.707519,,
1200.02391,283.5,1.709961,,
1200.0216,283.75,1.706529,,
1200.02134,284,1.707266,,
1200.01765,284.25,1.706991,,
1200.01844,284.5,1.69917,,
1200.01687,284.75,1.703174,,
1200.01903,285,1.703933,,
1200.01682,285.25,1.699973,,
1200.02063,285.5,1.703515,,
1200.02124,285.75,1.708993,,
1200.0275,286,1.706386,,
1200.02804,286.25,1.706375,,