File: ExampleData/T.1.3 Isothermal Section.csv
#EXPORTTYPE:DATA SINGLE,,,,
#FILE:,,,,
#FORMAT:NETZSCH5,,,,
#FTYPE:ANSI,,,,
#IDENTITY:,,,,
#DECIMAL:POINT,,,,
#SEPARATOR:SEMICOLON,,,,
#MTYPE:TG,,,,
#INSTRUMENT:NETZSCH STA 449F1,,,,
#PROJECT:,,,,
#DATE/TIME:29.01.2019 12:06,,,,
#CORR. FILE:,,,,
#TEMPCAL:TGA temperature calibration.ngb-ts1,,,,
#SENSITIVITY:---,,,,
#LABORATORY:,,,,
#OPERATOR:,,,,
#REMARK:,,,,
#SAMPLE:,,,,
#SAMPLE MASS /mg:829.41,,,,
#MATERIAL:,,,,
#REFERENCE:,,,,
#REFERENCE MASS /mg:,,,,
#TYPE OF CRUCIBLE:DTA/TG crucible Al2O3,,,,
#SAMPLE CRUCIBLE MASS /mg:0,,,,
#REFERENCE CRUCIBLE MASS /mg:,,,,
#TG RANGE /mg:5000,,,,
#TAU-R:---,,,,
#CORR. CODE:000,,,,
#EXO:-1,,,,
#RANGE:1200°C/04:00/1200°C,,,,
#SEGMENT:S4/4,,,,
#SEG. 4:1200°C/04:00/1200°C,,,,
,,,surface area,2.469012
##Temp./°C,Time/min,Mass loss(subtr.)/mg,,
1199.99801,46.5,0.4463184,,
1199.88684,46.75,0.5029,,
1199.88887,47,0.5323464,,
1199.92329,47.25,0.5391516,,
1199.97782,47.5,0.543881,,
1199.99689,47.75,0.559182,,
1199.99418,48,0.5637295,,
1199.98684,48.25,0.5724821,,
1199.97465,48.5,0.5822405,,
1199.96566,48.75,0.587751,,
1199.95736,49,0.5886926,,
1199.95007,49.25,0.5957225,,
1199.94513,49.5,0.6040364,,
1199.94254,49.75,0.604443,,
1199.93884,50,0.6129816,,
1199.94195,50.25,0.6243985,,
1199.94396,50.5,0.620493,,
1199.95,50.75,0.6173686,,
1199.95493,51,0.626271,,
1199.9584,51.25,0.6408016,,
1199.96,51.5,0.6336861,,
1199.96236,51.75,0.6477245,,
1199.96871,52,0.6470076,,
1199.97355,52.25,0.6416041,,
1199.97259,52.5,0.64307,,
1199.9716,52.75,0.6457985,,
1199.97482,53,0.6551075,,
1199.9787,53.25,0.6680224,,
1199.98436,53.5,0.669071,,
1199.9859,53.75,0.6742391,,
1199.98631,54,0.6712645,,
1199.98737,54.25,0.6752556,,
1199.98959,54.5,0.680734,,
1199.99171,54.75,0.6773956,,
1199.99107,55,0.685014,,
1199.99566,55.25,0.677952,,
1199.99171,55.5,0.6975116,,
1199.99488,55.75,0.6821785,,
1199.99228,56,0.7017595,,
1199.99736,56.25,0.6931246,,
1200.00283,56.5,0.7032361,,
1200.00524,56.75,0.7077301,,
1200.0073,57,0.7085005,,
1200.00572,57.25,0.7159905,,
1200.00435,57.5,0.7102446,,
1200.00518,57.75,0.7098915,,
1200.00382,58,0.7090141,,
1200.00399,58.25,0.7198425,,
1200.00457,58.5,0.7265621,,
1200.00511,58.75,0.7283704,,
1200.00852,59,0.7144176,,
1200.01099,59.25,0.7312915,,
1200.01176,59.5,0.731666,,
1200.0113,59.75,0.727921,,
1200.00865,60,0.7276535,,
1200.00832,60.25,0.7328965,,
1200.00713,60.5,0.7256419,,
1200.00542,60.75,0.733271,,
1200.00588,61,0.7347155,,
1200.00629,61.25,0.7422055,,
1200.00824,61.5,0.7389955,,
1200.0103,61.75,0.7333245,,
1200.01295,62,0.740761,,
1200.01512,62.25,0.7484971,,
1200.01618,62.5,0.7608449,,
1200.01695,62.75,0.7383321,,
1200.0163,63,0.7612194,,
1200.01641,63.25,0.7618935,,
1200.01631,63.5,0.7519425,,
1200.01672,63.75,0.7564365,,
1200.0163,64,0.7688271,,
1200.01306,64.25,0.7611231,,
1200.00941,64.5,0.757132,,
1200.01017,64.75,0.7781896,,
1200.01465,65,0.7655101,,
1200.01871,65.25,0.7635841,,
1200.01629,65.5,0.7724865,,
1200.01457,65.75,0.772326,,
1200.01138,66,0.7797411,,
1200.01244,66.25,0.7842565,,
1200.01345,66.5,0.7846845,,
1200.01446,66.75,0.7747121,,
1200.01223,67,0.7787995,,
1200.01029,67.25,0.7897991,,
1200.01052,67.5,0.7737491,,
1200.01287,67.75,0.7830046,,
1200.01504,68,0.7817955,,
1200.01398,68.25,0.7915325,,
1200.01374,68.5,0.7912329,,
1200.01575,68.75,0.7825445,,
1200.01742,69,0.7988941,,
1200.02189,69.25,0.797685,,
1200.01836,69.5,0.7926881,,
1200.01606,69.75,0.801216,,
1200.01906,70,0.7968825,,
1200.02193,70.25,0.72225,,
1200.02064,70.5,0.7782431,,
1200.01999,70.75,0.7802654,,
1200.017,71,0.80464,,
1200.01205,71.25,0.8464021,,
1200.01294,71.5,0.8217065,,
1200.01346,71.75,0.833209,,
1200.01723,72,0.8177261,,
1200.01669,72.25,0.7942931,,
1200.01405,72.5,0.824435,,
1200.01594,72.75,0.8434275,,
1200.01688,73,0.869696,,
1200.02329,73.25,0.8388479,,
1200.02482,73.5,0.8294319,,
1200.02523,73.75,0.8245741,,
1200.02375,74,0.8322246,,
1200.02217,74.25,0.8280195,,
1200.01875,74.5,0.8240819,,
1200.01682,74.75,0.8205081,,
1200.01641,75,0.8245955,,
1200.01666,75.25,0.8345465,,
1200.017,75.5,0.825612,,
1200.01642,75.75,0.8273561,,
1200.01501,76,0.8368791,,
1200.01295,76.25,0.8323316,,
1200.01418,76.5,0.8368791,,
1200.01354,76.75,0.837703,,
1200.01593,77,0.8405171,,
1200.01593,77.25,0.8353811,,
1200.01853,77.5,0.8487561,,
1200.01759,77.75,0.847012,,
1200.01723,78,0.8507035,,
1200.01612,78.25,0.8449041,,
1200.01684,78.5,0.8458671,,
1200.01683,78.75,0.856749,,
1200.01764,79,0.854074,,
1200.01429,79.25,0.8537851,,
1200.01676,79.5,0.8557539,,
1200.01559,79.75,0.8539456,,
1200.01771,80,0.8624735,,
1200.02001,80.25,0.8597771,,
1200.01978,80.5,0.854181,,
1200.02583,80.75,0.8542024,,
1200.02424,81,0.860173,,
1200.02282,81.25,0.8682515,,
1200.02105,81.5,0.8720286,,
1200.01758,81.75,0.866914,,
1200.01287,82,0.866272,,
1200.00887,82.25,0.8660366,,
1200.01158,82.5,0.8661971,,
1200.01394,82.75,0.870873,,
1200.01807,83,0.8730879,,
1200.01753,83.25,0.8736015,,
1200.01464,83.5,0.887993,,
1200.01664,83.75,0.8490664,,
1200.01863,84,0.8694285,,
1200.02158,84.25,0.8827821,,
1200.02571,84.5,0.8811236,,
1200.02449,84.75,0.8866341,,
1200.02278,85,0.8860456,,
1200.01853,85.25,0.8709586,,
1200.01776,85.5,0.886388,,
1200.01624,85.75,0.8837665,,
1200.01594,86,0.8797861,,
1200.01348,86.25,0.89559,,
1200.00989,86.5,0.9019886,,
1200.01065,86.75,0.9040644,,
1200.01058,87,0.8944451,,
1200.01434,87.25,0.8936961,,
1200.01527,87.5,0.9001696,,
1200.01433,87.75,0.8950336,,
1200.01675,88,0.8874366,,
1200.01505,88.25,0.8959966,,
1200.0164,88.5,0.900619,,
1200.01863,88.75,0.8979654,,
1200.01692,89,0.9099815,,
1200.01681,89.25,0.899014,,
1200.01676,89.5,0.89131,,
1200.01423,89.75,0.9026199,,
1200.01223,90,0.915599,,
1200.00587,90.25,0.8981366,,
1200.00194,90.5,0.9065254,,
1200.00264,90.75,0.9080234,,
1200.00946,91,0.9046315,,
1200.01275,91.25,0.9025236,,
1200.01728,91.5,0.9104416,,
1200.01593,91.75,0.9182205,,
1200.01645,92,0.9106984,,
1200.01752,92.25,0.913459,,
1200.01887,92.5,0.909714,,
1200.01946,92.75,0.9203926,,
1200.01993,93,0.9280645,,
1200.01952,93.25,0.9205531,,
1200.01822,93.5,0.9202535,,
1200.01741,93.75,0.9222009,,
1200.01559,94,0.9247261,,
1200.01819,94.25,0.9266735,,
1200.01836,94.5,0.9441145,,
1200.01741,94.75,0.9308251,,
1200.01706,95,0.9040216,,
1200.01629,95.25,0.922233,,
1200.01824,95.5,0.9280966,,
1200.01906,95.75,0.9268875,,
1200.01822,96,0.9026841,,
1200.01586,96.25,0.9131915,,
1200.01615,96.5,0.9416856,,
1200.0155,96.75,0.9273155,,
1200.01522,97,0.9354475,,
1200.01357,97.25,0.9381011,,
1200.01416,97.5,0.9324515,,
1200.01451,97.75,0.93732,,
1200.01716,98,0.9455376,,
1200.01722,98.25,0.936785,,
1200.01682,98.5,0.9443071,,
1200.01728,98.75,0.941814,,
1200.01682,99,0.9381011,,
1200.01629,99.25,0.941493,,
1200.0137,99.5,0.9488225,,
1200.01123,99.75,0.9470356,,
1200.01259,100,0.9460405,,
1200.01794,100.25,0.951658,,
1200.02018,100.5,0.9416856,,
1200.01871,100.75,0.9452915,,
1200.01688,101,0.9436116,,
1200.01506,101.25,0.9535626,,
1200.01458,101.5,0.9475599,,
1200.01228,101.75,0.9502135,,
1200.0114,102,0.9466076,,
1200.01122,102.25,0.9532416,,
1200.01453,102.5,0.9488546,,
1200.01918,102.75,0.9620691,,
1200.02136,103,0.951979,,
1200.02258,103.25,0.9536375,,
1200.02,103.5,0.957757,,
1200.01534,103.75,0.9559915,,
1200.01471,104,0.9669911,,
1200.01618,104.25,0.962465,,
1200.02265,104.5,0.9564516,,
1200.02594,104.75,0.9501065,,
1200.026,105,0.9565265,,
1200.02352,105.25,0.9656001,,
1200.02081,105.5,0.9647441,,
1200.01862,105.75,0.9736465,,
1200.01768,106,0.9628716,,
1200.01675,106.25,0.9681895,,
1200.01876,106.5,0.9692916,,
1200.0157,106.75,0.9629251,,
1200.01612,107,0.9744276,,
1200.0147,107.25,0.9715921,,
1200.01523,107.5,0.9639416,,
1200.01975,107.75,0.9719345,,
1200.01934,108,0.9734646,,
1200.01933,108.25,0.9764285,,
1200.0188,108.5,0.9687459,,
1200.02139,108.75,0.9775199,,
1200.02039,109,0.9737321,,
1200.01752,109.25,0.966317,,
1200.01406,109.5,0.9671516,,
1200.0143,109.75,0.9675261,,
1200.01323,110,0.9860264,,
1200.01788,110.25,0.9924785,,
1200.01934,110.5,0.989215,,
1200.02276,110.75,0.9869466,,
1200.02217,111,0.9869466,,
1200.02011,111.25,0.982367,,
1200.01782,111.5,0.9879096,,
1200.01552,111.75,0.9922966,,
1200.01106,112,0.9936555,,
1200.01364,112.25,0.9961165,,
1200.01624,112.5,0.9999685,,
1200.02148,112.75,0.92769,,
1200.02106,113,0.9496785,,
1200.01877,113.25,0.968243,,
1200.01845,113.5,0.9990269,,
1200.01952,113.75,1.0254345,,
1200.02046,114,1.0211866,,
1200.01871,114.25,1.0139641,,
1200.01506,114.5,0.9984491,,
1200.016,114.75,1.0116315,,
1200.01488,115,0.985042,,
1200.01924,115.25,1.0200845,,
1200.01878,115.5,1.0220319,,
1200.02018,115.75,1.0166391,,
1200.01629,116,1.0050831,,
1200.0194,116.25,1.0064741,,
1200.01722,116.5,1.00901,,
1200.01835,116.75,1.0143814,,
1200.01712,117,1.0048049,,
1200.01382,117.25,1.0093631,,
1200.01436,117.5,1.0063136,,
1200.01471,117.75,1.003339,,
1200.01746,118,1.007726,,
1200.01764,118.25,1.0073515,,
1200.01988,118.5,1.0079935,,
1200.01735,118.75,1.0132044,,
1200.01782,119,1.0146275,,
1200.01293,119.25,1.010829,,
1200.01577,119.5,1.0141995,,
1200.01747,119.75,1.0107006,,
1200.01795,120,1.0057786,,
1200.01736,120.25,1.0216146,,
1200.01718,120.5,1.0265045,,
1200.01666,120.75,1.0148629,,
1200.01742,121,1.0164786,,
1200.01778,121.25,1.0233159,,
1200.0186,121.5,1.0292651,,
1200.02041,121.75,1.0205874,,
1200.02217,122,1.0305705,,
1200.02034,122.25,1.0230591,,
1200.01957,122.5,1.030303,,
1200.0164,122.75,1.030089,,
1200.01563,123,1.0354711,,
1200.01651,123.25,1.0259909,,
1200.01644,123.5,1.0301425,,
1200.01692,123.75,1.0272535,,
1200.01722,124,1.0320899,,
1200.01764,124.25,1.019389,,
1200.01723,124.5,1.0409281,,
1200.01647,124.75,1.0239151,,
1200.02023,125,1.0200631,,
1200.02495,125.25,1.029126,,
1200.03065,125.5,1.0303565,,
1200.03177,125.75,1.031908,,
1200.02989,126,1.0354711,,
1200.02753,126.25,1.038114,,
1200.02836,126.5,1.0198384,,
1200.02825,126.75,1.039933,,
1200.02912,127,1.0402005,,
1200.02488,127.25,1.041966,,
1200.02328,127.5,1.038328,,
1200.02147,127.75,1.0389914,,
1200.019,128,1.0418911,,
1200.02035,128.25,1.0492955,,
1200.01776,128.5,1.0389165,,
1200.02047,128.75,1.0412491,,
1200.02194,129,1.043464,,
1200.02376,129.25,1.0472946,,
1200.02434,129.5,1.0396976,,
1200.02152,129.75,1.0546455,,
1200.02371,130,1.0446731,,
1200.02524,130.25,1.044748,,
1200.02824,130.5,1.0501301,,
1200.03054,130.75,1.0462674,,
1200.028,131,1.045925,,
1200.02547,131.25,1.0563789,,
1200.02031,131.5,1.0545171,,
1200.02066,131.75,1.0555015,,
1200.02255,132,1.0455184,,
1200.02324,132.25,1.0533615,,
1200.02288,132.5,1.0597815,,
1200.01976,132.75,1.0484395,,
1200.01741,133,1.0663299,,
1200.01565,133.25,1.0534685,,
1200.01576,133.5,1.0581551,,
1200.01569,133.75,1.0620285,,
1200.01799,134,1.0530191,,
1200.01952,134.25,1.0548595,,
1200.01265,134.5,1.0654525,,
1200.01382,134.75,1.0645965,,
1200.01058,135,1.0607766,,
1200.01665,135.25,1.0666081,,
1200.02017,135.5,1.0655595,,
1200.02212,135.75,1.0733491,,
1200.02235,136,1.0691226,,
1200.02071,136.25,1.0662015,,
1200.0186,136.5,1.0715301,,
1200.01748,136.75,1.0762595,,
1200.01372,137,1.0706741,,
1200.01107,137.25,1.0713375,,
1200.00842,137.5,1.0683201,,
1200.00854,137.75,1.073959,,
1200.01107,138,1.0696041,,
1200.01629,138.25,1.0716906,,
1200.01398,138.5,1.0780036,,
1200.01109,138.75,1.0699465,,
1200.01122,139,1.0709951,,
1200.01123,139.25,1.06037,,
1200.01576,139.5,1.0836746,,
1200.01735,139.75,1.0820375,,
1200.01588,140,1.0808819,,
1200.01224,140.25,1.0766554,,
1200.01258,140.5,1.0767624,,
1200.01177,140.75,1.0716264,,
1200.01282,141,1.0872591,,
1200.01459,141.25,1.088404,,
1200.01571,141.5,1.0810531,,
1200.01917,141.75,1.095038,,
1200.01928,142,1.0834606,,
1200.0211,142.25,1.0823585,,
1200.02288,142.5,1.0794481,,
1200.02242,142.75,1.089367,,
1200.02148,143,1.074708,,
1200.01953,143.25,1.0802399,,
1200.02082,143.5,1.0796835,,
1200.01952,143.75,1.0841775,,
1200.02118,144,1.0928231,,
1200.01641,144.25,1.0943104,,
1200.01636,144.5,1.0882114,,
1200.01606,144.75,1.0954125,,
1200.01219,145,1.0832894,,
1200.01312,145.25,1.097927,,
1200.01129,145.5,1.0762809,,
1200.01323,145.75,1.106701,,
1200.01234,146,1.079844,,
1200.01471,146.25,1.0930371,,
1200.01853,146.5,1.0920955,,
1200.02229,146.75,1.107985,,
1200.0237,147,1.0983336,,
1200.02093,147.25,1.0958405,,
1200.01541,147.5,1.0981196,,
1200.01382,147.75,1.0995855,,
1200.01136,148,1.1025601,,
1200.01447,148.25,1.101565,,
1200.01405,148.5,1.102528,,
1200.01694,148.75,1.1065191,,
1200.01693,149,1.1011905,,
1200.01706,149.25,1.10959,,
1200.01764,149.5,1.1042721,,
1200.01923,149.75,1.099211,,
1200.01669,150,1.1009551,,
1200.01706,150.25,1.1078245,,
1200.01742,150.5,1.102742,,
1200.01919,150.75,1.1076426,,
1200.01766,151,1.1135169,,
1200.01725,151.25,1.1031914,,
1200.01947,151.5,1.104561,,
1200.01977,151.75,1.113335,,
1200.02423,152,1.1152075,,
1200.02211,152.25,1.1114946,,
1200.02347,152.5,1.114512,,
1200.02365,152.75,1.1128535,,
1200.02341,153,1.1114625,,
1200.02617,153.25,1.118043,,
1200.02409,153.5,1.1195731,,
1200.0215,153.75,1.1186529,,
1200.01922,154,1.1154964,,
1200.01794,154.25,1.119541,,
1200.01896,154.5,1.1165771,,
1200.01319,154.75,1.1183105,,
1200.01277,155,1.1199155,,
1200.01242,155.25,1.1219699,,
1200.01723,155.5,1.1257256,,
1200.01975,155.75,1.121253,,
1200.01822,156,1.1261001,,
1200.01892,156.25,1.1189525,,
1200.02046,156.5,1.1140091,,
1200.02099,156.75,1.1211246,,
1200.01959,157,1.1209855,,
1200.01718,157.25,1.1232539,,
1200.01682,157.5,1.1310221,,
1200.01677,157.75,1.137303,,
1200.01458,158,1.1304015,,
1200.01476,158.25,1.1248054,,
1200.01264,158.5,1.125961,,
1200.00999,158.75,1.1296525,,
1200.01234,159,1.1220555,,
1200.0117,159.25,1.1278014,,
1200.01924,159.5,1.1390685,,
1200.02046,159.75,1.1278014,,
1200.02135,160,1.1269026,,
1200.02117,160.25,1.135484,,
1200.01905,160.5,1.1366289,,
1200.01881,160.75,1.1371211,,
1200.01652,161,1.1289035,,
1200.01799,161.25,1.1353021,,
1200.01894,161.5,1.1382125,,
1200.02088,161.75,1.122216,,
1200.01812,162,1.1397105,,
1200.01877,162.25,1.1348741,,
1200.01683,162.5,1.1370355,,
1200.01895,162.75,1.13741,,
1200.01641,163,1.1378594,,
1200.01317,163.25,1.1402455,,
1200.01606,163.5,1.1418505,,
1200.01664,163.75,1.1420966,,
1200.02153,164,1.148217,,
1200.02006,164.25,1.133451,,
1200.01552,164.5,1.1455955,,
1200.01642,164.75,1.139122,,
1200.01318,165,1.1480351,,
1200.01947,165.25,1.1529785,,
1200.01994,165.5,1.129385,,
1200.0207,165.75,1.1459165,,
1200.01895,166,1.1434555,,
1200.01524,166.25,1.14276,,
1200.01394,166.5,1.1447609,,
1200.0103,166.75,1.1419575,,
1200.01207,167,1.1493619,,
1200.01565,167.25,1.159666,,
1200.02235,167.5,1.1517159,,
1200.02541,167.75,1.1427814,,
1200.02488,168,1.1428349,,
1200.02406,168.25,1.1608751,,
1200.02301,168.5,1.1464301,,
1200.02077,168.75,1.1388331,,
1200.01706,169,1.1501109,,
1200.01354,169.25,1.1488055,,
1200.0143,169.5,1.1494154,,
1200.01894,169.75,1.1616134,,
1200.02523,170,1.1633361,,
1200.03029,170.25,1.1551185,,
1200.02871,170.5,1.157847,,
1200.02894,170.75,1.1462589,,
1200.02293,171,1.1589705,,
1200.02047,171.25,1.165016,,
1200.01919,171.5,1.1559745,,
1200.01541,171.75,1.160094,,
1200.01193,172,1.1513521,,
1200.01175,172.25,1.1634966,,
1200.01553,172.5,1.159238,,
1200.02124,172.75,1.158703,,
1200.02166,173,1.1599335,,
1200.02012,173.25,1.1644275,,
1200.02212,173.5,1.1528715,,
1200.02258,173.75,1.162448,,
1200.02342,174,1.1402134,,
1200.02141,174.25,1.1772675,,
1200.02077,174.5,1.1593129,,
1200.02,174.75,1.1708154,,
1200.01828,175,1.1577721,,
1200.01887,175.25,1.1654975,,
1200.0187,175.5,1.1691355,,
1200.01759,175.75,1.1761654,,
1200.01618,176,1.1583606,,
1200.01506,176.25,1.164053,,
1200.0167,176.5,1.164588,,
1200.01776,176.75,1.1695421,,
1200.01722,177,1.1680976,,
1200.01852,177.25,1.1804775,,
1200.01886,177.5,1.181708,,
1200.02057,177.75,1.1705051,,
1200.02193,178,1.1696705,,
1200.02269,178.25,1.165337,,
1200.02204,178.5,1.1681404,,
1200.02158,178.75,1.1815261,,
1200.02164,179,1.159452,,
1200.0217,179.25,1.1831311,,
1200.02141,179.5,1.1837196,,
1200.0224,179.75,1.1701306,,
1200.02188,180,1.1800495,,
1200.02346,180.25,1.1924829,,
1200.02176,180.5,1.1801565,,
1200.02317,180.75,1.1778025,,
1200.02377,181,1.1937241,,
1200.02724,181.25,1.186737,,
1200.02594,181.5,1.1706656,,
1200.02434,181.75,1.1876465,,
1200.02122,182,1.1917446,,
1200.01952,182.25,1.1846505,,
1200.01894,182.5,1.1847361,,
1200.01683,182.75,1.1827245,,
1200.01147,183,1.1782626,,
1200.00947,183.25,1.190054,,
1200.01182,183.5,1.190054,,
1200.01652,183.75,1.1896046,,
1200.02235,184,1.1908351,,
1200.01924,184.25,1.1953505,,
1200.01518,184.5,1.1884276,,
1200.01723,184.75,1.192194,,
1200.0177,185,1.196046,,
1200.02158,185.25,1.1917125,,
1200.02195,185.5,1.191659,,
1200.02106,185.75,1.19519,,
1200.01929,186,1.1843509,,
1200.01817,186.25,1.1777276,,
1200.01787,186.5,1.1902466,,
1200.02081,186.75,1.177642,,
1200.02135,187,1.197865,,
1200.02089,187.25,1.197009,,
1200.02036,187.5,1.1944945,,
1200.02141,187.75,1.1871971,,
1200.02205,188,1.191445,,
1200.0234,188.25,1.197544,,
1200.01847,188.5,1.188984,,
1200.01482,188.75,1.2000264,,
1200.01706,189,1.1860736,,
1200.01659,189.25,1.2050875,,
1200.02141,189.5,1.1901931,,
1200.0217,189.75,1.2032685,,
1200.02316,190,1.207067,,
1200.01776,190.25,1.1930821,,
1200.0184,190.5,1.2009466,,
1200.01936,190.75,1.1961851,,
1200.02306,191,1.2097955,,
1200.02835,191.25,1.210812,,
1200.02948,191.5,1.2025516,,
1200.02701,191.75,1.1992239,,
1200.02242,192,1.2018561,,
1200.02171,192.25,1.1922475,,
1200.0203,192.5,1.2075485,,
1200.02077,192.75,1.20268,,
1200.01723,193,1.208458,,
1200.01941,193.25,1.216911,,
1200.01923,193.5,1.2069386,,
1200.02241,193.75,1.2175851,,
1200.02323,194,1.2007754,,
1200.02423,194.25,1.2158196,,
1200.02612,194.5,1.2256636,,
1200.02382,194.75,1.2133586,,
1200.01864,195,1.2169645,,
1200.01493,195.25,1.20161,,
1200.01105,195.5,1.2165579,,
1200.01046,195.75,1.2097206,,
1200.01258,196,1.2150599,,
1200.0157,196.25,1.2236306,,
1200.0117,196.5,1.213487,,
1200.012,196.75,1.2228816,,
1200.01423,197,1.2070991,,
1200.01782,197.25,1.2173176,,
1200.02034,197.5,1.218088,,
1200.01752,197.75,1.2263591,,
1200.01616,198,1.2254389,,
1200.01387,198.25,1.2170501,,
1200.01458,198.5,1.2243154,,
1200.01065,198.75,1.2165151,,
1200.01265,199,1.2337421,,
1200.01524,199.25,1.2247434,,
1200.01935,199.5,1.228467,,
1200.0207,199.75,1.2281781,,
1200.01923,200,1.2243154,,
1200.01853,200.25,1.2222075,,
1200.01783,200.5,1.2235129,,
1200.01725,200.75,1.2165579,,
1200.01918,201,1.221191,,
1200.02077,201.25,1.2229351,,
1200.02194,201.5,1.226648,,
1200.02353,201.75,1.2297831,,
1200.02077,202,1.220228,,
1200.01771,202.25,1.2238874,,
1200.01476,202.5,1.2290341,,
1200.01799,202.75,1.231891,,
1200.02235,203,1.2252356,,
1200.02505,203.25,1.2219079,,
1200.02329,203.5,1.2319124,,
1200.02118,203.75,1.2269476,,
1200.01883,204,1.233496,,
1200.0193,204.25,1.2275896,,
1200.02059,204.5,1.2408255,,
1200.02076,204.75,1.2215869,,
1200.02152,205,1.2262414,,
1200.02122,205.25,1.2267015,,
1200.02157,205.5,1.2357644,,
1200.02127,205.75,1.2258455,,
1200.02151,206,1.2468496,,
1200.0221,206.25,1.2406971,,
1200.02352,206.5,1.2406436,,
1200.02205,206.75,1.241949,,
1200.02211,207,1.2440141,,
1200.02269,207.25,1.2466035,,
1200.02368,207.5,1.2364171,,
1200.02321,207.75,1.2365134,,
1200.02164,208,1.2392526,,
1200.01988,208.25,1.245373,,
1200.01836,208.5,1.2369949,,
1200.01859,208.75,1.250081,,
1200.01917,209,1.2465821,,
1200.01812,209.25,1.234887,,
1200.01894,209.5,1.242805,,
1200.01983,209.75,1.246336,,
1200.01877,210,1.247299,,
1200.01959,210.25,1.2451055,,
1200.01853,210.5,1.251258,,
1200.01905,210.75,1.2587801,,
1200.02469,211,1.2390386,,
1200.02422,211.25,1.2504341,,
1200.02334,211.5,1.249332,,
1200.02288,211.75,1.2409325,,
1200.02223,212,1.2524136,,
1200.02147,212.25,1.2536655,,
1200.0223,212.5,1.2476735,,
1200.02035,212.75,1.2489254,,
1200.01989,213,1.2510975,,
1200.01947,213.25,1.2656495,,
1200.01936,213.5,1.248369,,
1200.01689,213.75,1.2539009,,
1200.01394,214,1.2706571,,
1200.01319,214.25,1.2586945,,
1200.01813,214.5,1.253612,,
1200.02096,214.75,1.26474,,
1200.02525,215,1.2528951,,
1200.02355,215.25,1.2580525,,
1200.02418,215.5,1.2639161,,
1200.02406,215.75,1.2587266,,
1200.02047,216,1.2576031,,
1200.02006,216.25,1.2722621,,
1200.01865,216.5,1.2672545,,
1200.01711,216.75,1.2492036,,
1200.01476,217,1.267629,,
1200.01016,217.25,1.2620329,,
1200.01657,217.5,1.2613481,,
1200.02187,217.75,1.256608,,
1200.02188,218,1.2558055,,
1200.02036,218.25,1.266559,,
1200.01383,218.5,1.2764351,,
1200.01536,218.75,1.265596,,
1200.01094,219,1.282716,,
1200.01594,219.25,1.2637556,,
1200.01953,219.5,1.2709246,,
1200.02417,219.75,1.2631671,,
1200.02641,220,1.2648256,,
1200.02353,220.25,1.272016,,
1200.02199,220.5,1.2759536,,
1200.0203,220.75,1.2634025,,
1200.01999,221,1.2653499,,
1200.02135,221.25,1.2639589,,
1200.02023,221.5,1.2765849,,
1200.01882,221.75,1.2713526,,
1200.0183,222,1.2720481,,
1200.01965,222.25,1.2644725,,
1200.02024,222.5,1.28079,,
1200.01988,222.75,1.265382,,
1200.0183,223,1.2748515,,
1200.01764,223.25,1.2769059,,
1200.01858,223.5,1.2770771,,
1200.02181,223.75,1.282074,,
1200.02293,224,1.2768845,,
1200.02345,224.25,1.266024,,
1200.02351,224.5,1.2876915,,
1200.02276,224.75,1.2838609,,
1200.02141,225,1.2779866,,
1200.02025,225.25,1.2671796,,
1200.02201,225.5,1.2765849,,
1200.02347,225.75,1.2867606,,
1200.02288,226,1.277366,,
1200.02146,226.25,1.275119,,
1200.01939,226.5,1.2745305,,
1200.0197,226.75,1.2770771,,
1200.01799,227,1.2948926,,
1200.01669,227.25,1.2732251,,
1200.01294,227.5,1.286675,,
1200.01487,227.75,1.2846634,,
1200.01676,228,1.291169,,
1200.02228,228.25,1.2726366,,
1200.02282,228.5,1.291918,,
1200.02371,228.75,1.2792385,,
1200.02324,229,1.2893821,,
1200.02406,229.25,1.2890611,,
1200.02388,229.5,1.2803299,,
1200.02311,229.75,1.286782,,
1200.02247,230,1.2830049,,
1200.02206,230.25,1.28935,,
1200.02029,230.5,1.2878841,,
1200.02177,230.75,1.2882265,,
1200.0213,231,1.289243,,
1200.02001,231.25,1.2825876,,
1200.02118,231.5,1.2943255,,
1200.02041,231.75,1.2816139,,
1200.01922,232,1.2816246,,
1200.01899,232.25,1.3013661,,
1200.01858,232.5,1.298338,,
1200.01752,232.75,1.2919929,,
1200.01511,233,1.2939189,,
1200.0141,233.25,1.296519,,
1200.0161,233.5,1.2889755,,
1200.02051,233.75,1.2828765,,
1200.02369,234,1.2861079,,
1200.01894,234.25,1.3069301,,
1200.01817,234.5,1.300799,,
1200.01577,234.75,1.3011735,,
1200.01759,235,1.2995364,,
1200.01983,235.25,1.2902381,,
1200.01894,235.5,1.3037201,,
1200.022,235.75,1.3054749,,
1200.02017,236,1.3058494,,
1200.01617,236.25,1.2952885,,
1200.01741,236.5,1.2976425,,
1200.01476,236.75,1.2970861,,
1200.01647,237,1.3060741,,
1200.01965,237.25,1.3145485,,
1200.02194,237.5,1.3135855,,
1200.02606,237.75,1.30647,,
1200.02594,238,1.2946251,,
1200.02617,238.25,1.2982096,,
1200.02118,238.5,1.304651,,
1200.01747,238.75,1.313639,,
1200.01547,239,1.3068659,,
1200.017,239.25,1.2985841,,
1200.0197,239.5,1.3080215,,
1200.02206,239.75,1.314923,,
1200.02059,240,1.3077005,,
1200.01835,240.25,1.3016229,,
1200.01859,240.5,1.3208936,,
1200.02053,240.75,1.321022,,
1200.02158,241,1.3079894,,
1200.02029,241.25,1.3168811,,
1200.01983,241.5,1.3132431,,
1200.02166,241.75,1.3093055,,
1200.02088,242,1.3129756,,
1200.01941,242.25,1.306256,,
1200.01682,242.5,1.3052181,,
1200.01952,242.75,1.3046724,,
1200.01883,243,1.305186,,
1200.01949,243.25,1.3172984,,
1200.01567,243.5,1.3178655,,
1200.01319,243.75,1.303367,,
1200.01906,244,1.3113385,,
1200.018,244.25,1.3236756,,
1200.02129,244.5,1.3305771,,
1200.01941,244.75,1.3157041,,
1200.02011,245,1.3223274,,
1200.01952,245.25,1.3075935,,
1200.01906,245.5,1.3196524,,
1200.01776,245.75,1.3152975,,
1200.01876,246,1.3160679,,
1200.01601,246.25,1.3146341,,
1200.01459,246.5,1.3173519,,
1200.01848,246.75,1.3128686,,
1200.02165,247,1.324018,,
1200.02542,247.25,1.3223274,,
1200.02318,247.5,1.3248205,,
1200.02283,247.75,1.3224986,,
1200.01981,248,1.3228731,,
1200.01775,248.25,1.3286511,,
1200.0174,248.5,1.3248954,,
1200.01876,248.75,1.3246814,,
1200.02287,249,1.3292396,,
1200.02016,249.25,1.3256016,,
1200.01976,249.5,1.3269605,,
1200.01911,249.75,1.3209685,,
1200.01953,250,1.3278165,,
1200.01976,250.25,1.3219315,,
1200.01593,250.5,1.3145485,,
1200.01623,250.75,1.3326529,,
1200.01848,251,1.3267251,,
1200.02277,251.25,1.3278165,,
1200.02329,251.5,1.3252485,,
1200.02112,251.75,1.3261794,,
1200.01876,252,1.3250345,,
1200.01575,252.25,1.336109,,
1200.01394,252.5,1.3365905,,
1200.01546,252.75,1.3371576,,
1200.01606,253,1.3311549,,
1200.01982,253.25,1.3348036,,
1200.01995,253.5,1.3315829,,
1200.02089,253.75,1.3320751,,
1200.02265,254,1.3256016,,
1200.02383,254.25,1.3402071,,
1200.02388,254.5,1.3389231,,
1200.02083,254.75,1.3364086,,
1200.02006,255,1.3377675,,
1200.01948,255.25,1.341459,,
1200.02412,255.5,1.343064,,
1200.02277,255.75,1.346167,,
1200.02106,256,1.3322784,,
1200.01654,256.25,1.336323,,
1200.01702,256.5,1.3424541,,
1200.01895,256.75,1.3389124,,
1200.01953,257,1.337393,,
1200.0197,257.25,1.3387091,,
1200.01736,257.5,1.34071,,
1200.01624,257.75,1.3357666,,
1200.01453,258,1.340603,,
1200.01707,258.25,1.3380885,,
1200.01583,258.5,1.3429784,,
1200.01894,258.75,1.3437595,,
1200.01964,259,1.3406886,,
1200.02206,259.25,1.3472156,,
1200.02095,259.5,1.34713,,
1200.01765,259.75,1.34392,,
1200.01629,260,1.345204,,
1200.01346,260.25,1.3463596,,
1200.01558,260.5,1.3454715,,
1200.01712,260.75,1.3455571,,
1200.01659,261,1.343385,,
1200.01906,261.25,1.3455036,,
1200.01977,261.5,1.342743,,
1200.02077,261.75,1.3511639,,
1200.02128,262,1.340068,,
1200.02117,262.25,1.3444871,,
1200.02129,262.5,1.350126,,
1200.02159,262.75,1.3504791,,
1200.01918,263,1.3510569,,
1200.02023,263.25,1.353657,,
1200.01788,263.5,1.351624,,
1200.02082,263.75,1.3566316,,
1200.02158,264,1.3436846,,
1200.02258,264.25,1.3527796,,
1200.02177,264.5,1.3518594,,
1200.02136,264.75,1.3535179,,
1200.02135,265,1.3549089,,
1200.02176,265.25,1.3589535,,
1200.02346,265.5,1.35569,,
1200.02311,265.75,1.3605371,,
1200.02003,266,1.3637471,,
1200.02004,266.25,1.3554011,,
1200.01894,266.5,1.3561715,,
1200.02225,266.75,1.3536356,,
1200.02253,267,1.366176,,
1200.02088,267.25,1.3581831,,
1200.01711,267.5,1.3562036,,
1200.015,267.75,1.3652665,,
1200.01429,268,1.361361,,
1200.014,268.25,1.360505,,
1200.01559,268.5,1.3729919,,
1200.01641,268.75,1.3471086,,
1200.01705,269,1.3627841,,
1200.01723,269.25,1.3677061,,
1200.01369,269.5,1.362431,,
1200.01382,269.75,1.365855,,
1200.0137,270,1.3749286,,
1200.01647,270.25,1.3638755,,
1200.0194,270.5,1.3702955,,
1200.02058,270.75,1.3703811,,
1200.02223,271,1.3730454,,
1200.02165,271.25,1.3708626,,
1200.0236,271.5,1.3682946,,
1200.02224,271.75,1.3606976,,
1200.02341,272,1.3616285,,
1200.02188,272.25,1.3692255,,
1200.02265,272.5,1.366604,,
1200.02319,272.75,1.3660155,,
1200.02337,273,1.370135,,
1200.02336,273.25,1.3679629,,
1200.02212,273.5,1.3648706,,
1200.01957,273.75,1.3729491,,
1200.01704,274,1.3641109,,
1200.01211,274.25,1.3646459,,
1200.00911,274.5,1.362003,,
1200.01012,274.75,1.3736981,,
1200.01659,275,1.3665826,,
1200.021,275.25,1.3690971,,
1200.02324,275.5,1.369065,,
1200.02123,275.75,1.3742224,,
1200.02128,276,1.3733985,,
1200.02123,276.25,1.3788769,,
1200.02229,276.5,1.3780316,,
1200.01812,276.75,1.3873941,,
1200.0184,277,1.3705951,,
1200.01941,277.25,1.3702955,,
1200.02023,277.5,1.3804605,,
1200.024,277.75,1.3753459,,
1200.01976,278,1.3661974,,
1200.01923,278.25,1.3867521,,
1200.02034,278.5,1.385864,,
1200.02352,278.75,1.3768546,,
1200.02381,279,1.388753,,
1200.02258,279.25,1.3804605,,
1200.02146,279.5,1.3692469,,
1200.01788,279.75,1.3864204,,
1200.01629,280,1.3745969,,
1200.01671,280.25,1.3693646,,
1200.01848,280.5,1.3844195,,
1200.01988,280.75,1.390251,,
1200.01918,281,1.3876509,,
1200.01751,281.25,1.3738479,,
1200.01652,281.5,1.3761484,,
1200.01676,281.75,1.3922305,,
1200.01769,282,1.3683695,,
1200.017,282.25,1.3860994,,
1200.01346,282.5,1.3812095,,
1200.01435,282.75,1.3859175,,
1200.01364,283,1.3886995,,
1200.01486,283.25,1.3925836,,
1200.01633,283.5,1.3949269,,
1200.01745,283.75,1.3927976,,
1200.01452,284,1.3912354,,
1200.017,284.25,1.3922091,,
1200.01654,284.5,1.382333,,
1200.01919,284.75,1.3915885,,
1200.02107,285,1.390572,,
1200.02036,285.25,1.3843981,,
1200.0217,285.5,1.3920486,,
1200.02111,285.75,1.3977196,,
1200.01866,286,1.3939639,,
1200.0166,286.25,1.3916955,,