File: ExampleData/T.2.3 Isothermal Section.csv
#EXPORTTYPE:DATA ALL,,,,
#FILE:,,,,
#FORMAT:NETZSCH5,,,,
#FTYPE:ANSI,,,,
#IDENTITY:,,,,
#DECIMAL:POINT,,,,
#SEPARATOR:SEMICOLON,,,,
#MTYPE:TG,,,,
#INSTRUMENT:NETZSCH STA 449F1,,,,
#PROJECT:,,,,
#DATE/TIME:31.01.2019 00:25,,,,
#CORR. FILE:,,,,
#TEMPCAL:TGA temperature calibration.ngb-ts1,,,,
#SENSITIVITY:---,,,,
#LABORATORY:,,,,
#OPERATOR:,,,,
#REMARK:DS,,,,
#SAMPLE:,,,,
#SAMPLE MASS /mg:872.52,,,,
#MATERIAL:,,,,
#REFERENCE:,,,,
#REFERENCE MASS /mg:,,,,
#TYPE OF CRUCIBLE:DTA/TG crucible Al2O3,,,,
#SAMPLE CRUCIBLE MASS /mg:0,,,,
#REFERENCE CRUCIBLE MASS /mg:,,,,
#TG RANGE /mg:5000,,,,
#TAU-R:---,,,,
#CORR. CODE:000,,,,
#EXO:-1,,,,
#RANGE:30°C....1350°C/0.0....50.0K/min,,,,
#SEGMENT:S1-4/4,,,,
#SEG. 1:30°C/50.0(K/min)/1250°C,,,,
#SEG. 2:1250°C/10.0(K/min)/1350°C,,,,
#SEG. 3:1350°C/00:15/1350°C,,,,
#SEG. 4:1350°C/04:00/1350°C,,,,
,,,surface area,2.519378
##Temp./°C,Time/min,Mass loss/mg,,
1350.01191,49.5,2.4671736,,
1350.04566,49.75,2.4819588,,
1350.06066,50,2.4841728,,
1350.05714,50.25,2.4842484,,
1350.05416,50.5,2.4960312,,
1350.03924,50.75,2.4925428,,
1350.0223,51,2.489238,,
1350.01057,51.25,2.499498,,
1349.99832,51.5,2.5041852,,
1349.98915,51.75,2.5035588,,
1349.98765,52,2.5100928,,
1349.98795,52.25,2.5241112,,
1349.99099,52.5,2.5117776,,
1349.99204,52.75,2.5206228,,
1349.99171,53,2.5334208,,
1349.99513,53.25,2.5353108,,
1349.99671,53.5,2.5368552,,
1349.99608,53.75,2.5455384,,
1349.99757,54,2.5393716,,
1349.99888,54.25,2.5518132,,
1350.00175,54.5,2.552202,,
1350.00108,54.75,2.5515972,,
1350.00281,55,2.5595892,,
1350.00372,55.25,2.5605612,,
1350.00412,55.5,2.5629696,,
1350.00342,55.75,2.5721928,,
1350.00373,56,2.5670304,,
1350.00415,56.25,2.5689744,,
1350.00516,56.5,2.5718256,,
1350.00765,56.75,2.5763832,,
1350.0091,57,2.5831224,,
1350.01472,57.25,2.5831224,,
1350.01279,57.5,2.5831656,,
1350.00918,57.75,2.5885764,,
1350.00949,58,2.5936848,,
1350.01078,58.25,2.5940088,,
1350.01281,58.5,2.597292,,
1350.01832,58.75,2.5977996,,
1350.01778,59,2.6078436,,
1350.01916,59.25,2.6104896,,
1350.01878,59.5,2.6148528,,
1350.01373,59.75,2.6237412,,
1350.01315,60,2.60631,,
1350.01289,60.25,2.6222184,,
1350.01341,60.5,2.616624,,
1350.01427,60.75,2.6232228,,
1350.01385,61,2.6364096,,
1350.01369,61.25,2.6461512,,
1350.02016,61.5,2.64033,,
1350.02266,61.75,2.6333856,,
1350.02457,62,2.6404488,,
1350.02541,62.25,2.6609688,,
1350.02216,62.5,2.6600508,,
1350.02252,62.75,2.6672976,,
1350.0232,63,2.6508492,,
1350.02473,63.25,2.6768448,,
1350.02724,63.5,2.65572,,
1350.0262,63.75,2.6523396,,
1350.02974,64,2.668734,,
1350.02742,64.25,2.665062,,
1350.02595,64.5,2.6763156,,
1350.02598,64.75,2.6838216,,
1350.02739,65,2.6767044,,
1350.02815,65.25,2.6775468,,
1350.02769,65.5,2.7006048,,
1350.02318,65.75,2.6804196,,
1350.01848,66,2.6738964,,
1350.01887,66.25,2.6932068,,
1350.0204,66.5,2.6986932,,
1350.02859,66.75,2.697354,,
1350.02819,67,2.7052488,,
1350.02658,67.25,2.7101412,,
1350.0268,67.5,2.7065988,,
1350.02903,67.75,2.7105624,,
1350.03029,68,2.7068904,,
1350.03274,68.25,2.7142236,,
1350.02976,68.5,2.7130356,,
1350.02917,68.75,2.7250344,,
1350.02869,69,2.7243648,,
1350.02978,69.25,2.7200556,,
1350.03099,69.5,2.7221616,,
1350.03122,69.75,2.7270108,,
1350.03165,70,2.7373248,,
1350.03192,70.25,2.7416988,,
1350.03219,70.5,2.7304344,,
1350.0316,70.75,2.7303264,,
1350.02739,71,2.7542808,,
1350.02645,71.25,2.7512568,,
1350.02456,71.5,2.7521964,,
1350.02875,71.75,2.7543132,,
1350.02771,72,2.7529092,,
1350.02682,72.25,2.7628668,,
1350.02574,72.5,2.7559332,,
1350.02765,72.75,2.77344,,
1350.02917,73,2.7768528,,
1350.03089,73.25,2.7652428,,
1350.02715,73.5,2.773008,,
1350.02855,73.75,2.7614088,,
1350.02957,74,2.777868,,
1350.0299,74.25,2.7738288,,
1350.02921,74.5,2.7889164,,
1350.02898,74.75,2.783538,,
1350.0246,75,2.8016064,,
1350.02692,75.25,2.8002888,,
1350.02712,75.5,2.7895752,,
1350.03086,75.75,2.8024812,,
1350.03381,76,2.7912276,,
1350.02982,76.25,2.8029672,,
1350.02929,76.5,2.7986256,,
1350.02809,76.75,2.806488,,
1350.02972,77,2.806056,,
1350.02452,77.25,2.8059696,,
1350.02012,77.5,2.8081512,,
1350.01939,77.75,2.8098252,,
1350.02412,78,2.814804,,
1350.03103,78.25,2.8143936,,
1350.03055,78.5,2.8181628,,
1350.02957,78.75,2.834028,,
1350.02703,79,2.8311336,,
1350.02406,79.25,2.8224504,,
1350.02794,79.5,2.8247724,,
1350.02154,79.75,2.8374732,,
1350.02192,80,2.8280772,,
1350.02364,80.25,2.8414152,,
1350.02631,80.5,2.8445688,,
1350.03022,80.75,2.844396,,
1350.03152,81,2.8500876,,
1350.02737,81.25,2.8490076,,
1350.03032,81.5,2.8523124,,
1350.0304,81.75,2.847474,,
1350.03363,82,2.8592136,,
1350.03223,82.25,2.8584144,,
1350.0287,82.5,2.8600452,,
1350.02727,82.75,2.8674432,,
1350.02537,83,2.8758348,,
1350.02682,83.25,2.8739772,,
1350.02347,83.5,2.8620324,,
1350.02666,83.75,2.873988,,
1350.02822,84,2.8708776,,
1350.03335,84.25,2.8953612,,
1350.03383,84.5,2.8838376,,
1350.03399,84.75,2.8775304,,
1350.03468,85,2.8800036,,
1350.03404,85.25,2.8943136,,
1350.03395,85.5,2.8920024,,
1350.03199,85.75,2.9007072,,
1350.02974,86,2.895156,,
1350.02979,86.25,2.8942596,,
1350.03031,86.5,2.9039364,,
1350.03203,86.75,2.8992168,,
1350.03037,87,2.9000916,,
1350.0294,87.25,2.9132676,,
1350.03189,87.5,2.926044,,
1350.0316,87.75,2.9007072,,
1350.0291,88,2.9134836,,
1350.02748,88.25,2.9264004,,
1350.02601,88.5,2.9200608,,
1350.02734,88.75,2.9241108,,
1350.02816,89,2.9332908,,
1350.02984,89.25,2.9331828,,
1350.02909,89.5,2.9391876,,
1350.02686,89.75,2.925936,,
1350.02453,90,2.9178684,,
1350.02614,90.25,2.941488,,
1350.0293,90.5,2.9378052,,
1350.03461,90.75,2.9447712,,
1350.03357,91,2.9334636,,
1350.03099,91.25,2.9283012,,
1350.02839,91.5,2.9404296,,
1350.02878,91.75,2.9423844,,
1350.02767,92,2.9495124,,
1350.02751,92.25,2.9548692,,
1350.02809,92.5,2.951424,,
1350.02848,92.75,2.9559816,,
1350.0301,93,2.949372,,
1350.03022,93.25,2.9619432,,
1350.03419,93.5,2.9585088,,
1350.03634,93.75,2.9525364,,
1350.03787,94,2.9648916,,
1350.0345,94.25,2.9714796,,
1350.03152,94.5,2.9668032,,
1350.02876,94.75,2.980368,,
1350.02617,95,2.990358,,
1350.02505,95.25,2.9858544,,
1350.0253,95.5,2.98539,,
1350.02566,95.75,2.9883384,,
1350.0289,96,2.9836728,,
1350.02851,96.25,2.9987388,,
1350.0298,96.5,2.9939004,,
1350.0306,96.75,2.9951316,,
1350.03181,97,2.9936628,,
1350.03197,97.25,3.005802,,
1350.03068,97.5,3.0057696,,
1350.02266,97.75,3.0109212,,
1350.01743,98,3.0111588,,
1350.02101,98.25,3.0111156,,
1350.02667,98.5,3.0078,,
1350.03415,98.75,3.0113856,,
1350.0333,99,3.0188484,,
1350.03068,99.25,3.015846,,
1350.03004,99.5,3.0166452,,
1350.03117,99.75,3.031668,,
1350.03,100,3.0317436,,
1350.03059,100.25,3.0247884,,
1350.03084,100.5,3.022812,,
1350.03052,100.75,3.0249396,,
1350.03144,101,3.0263004,,
1350.03111,101.25,3.0322404,,
1350.0324,101.5,3.0256956,,
1350.03198,101.75,3.0242268,,
1350.03051,102,3.0208896,,
1350.0286,102.25,3.0384828,,
1350.02716,102.5,3.0442176,,
1350.02901,102.75,3.0348108,,
1350.02449,103,3.03561,,
1350.02794,103.25,3.0435588,,
1350.0276,103.5,3.0410316,,
1350.03131,103.75,3.0508704,,
1350.02908,104,3.04506,,
1350.02916,104.25,3.051162,,
1350.02567,104.5,3.046032,,
1350.0263,104.75,3.0509676,,
1350.02677,105,3.0526524,,
1350.02916,105.25,3.0628044,,
1350.0289,105.5,3.0623184,,
1350.02888,105.75,3.0696084,,
1350.02807,106,3.06477,,
1350.02871,106.25,3.0574476,,
1350.03275,106.5,3.0708288,,
1350.03281,106.75,3.069144,,
1350.03224,107,3.067632,,
1350.03206,107.25,3.0726756,,
1350.03137,107.5,3.062232,,
1350.03084,107.75,3.0795984,,
1350.03013,108,3.0801492,,
1350.03024,108.25,3.0807972,,
1350.03217,108.5,3.0760236,,
1350.03355,108.75,3.0733668,,
1350.03656,109,3.081456,,
1350.03489,109.25,3.0908952,,
1350.03377,109.5,3.0899556,,
1350.03105,109.75,3.0883788,,
1350.0296,110,3.088476,,
1350.02814,110.25,3.0897072,,
1350.02719,110.5,3.0885408,,
1350.02911,110.75,3.0986496,,
1350.03033,111,3.1062852,,
1350.02847,111.25,3.1028616,,
1350.02246,111.5,3.101112,,
1350.0196,111.75,3.1025916,,
1350.01799,112,3.1139856,,
1350.02563,112.25,3.1173768,,
1350.03214,112.5,3.110724,,
1350.03776,112.75,3.1107024,,
1350.0366,113,3.1198824,,
1350.03319,113.25,3.1087044,,
1350.03349,113.5,3.1151412,,
1350.0324,113.75,3.1302396,,
1350.03,114,3.1291056,,
1350.03097,114.25,3.1199148,,
1350.02707,114.5,3.1172688,,
1350.03035,114.75,3.1249044,,
1350.0273,115,3.126492,,
1350.02775,115.25,3.1337064,,
1350.02858,115.5,3.1345596,,
1350.03148,115.75,3.1252608,,
1350.03469,116,3.1304664,,
1350.03663,116.25,3.135402,,
1350.03325,116.5,3.1380696,,
1350.03011,116.75,3.1380048,,
1350.02753,117,3.1376592,,
1350.02165,117.25,3.1315032,,
1350.01935,117.5,3.1348188,,
1350.02483,117.75,3.137022,,
1350.03092,118,3.1480488,,
1350.035,118.25,3.1437828,,
1350.03811,118.5,3.1477356,,
1350.03519,118.75,3.1529304,,
1350.037,119,3.1571424,,
1350.0347,119.25,3.1560408,,
1350.03357,119.5,3.1545612,,
1350.0315,119.75,3.1597236,,
1350.03028,120,3.1697352,,
1350.03051,120.25,3.1677156,,
1350.03278,120.5,3.1644756,,
1350.0299,120.75,3.1474764,,
1350.0317,121,3.173796,,
1350.03209,121.25,3.1705884,,
1350.03516,121.5,3.1806648,,
1350.03364,121.75,3.179142,,
1350.0327,122,3.1884624,,
1350.0323,122.25,3.1845096,,
1350.03233,122.5,3.1824036,,
1350.03236,122.75,3.1812048,,
1350.03084,123,3.177792,,
1350.03176,123.25,3.1890996,,
1350.03004,123.5,3.190482,,
1350.02612,123.75,3.1953852,,
1350.02447,124,3.1892184,,
1350.02556,124.25,3.1899744,,
1350.02821,124.5,3.1875228,,
1350.03166,124.75,3.194964,,
1350.03215,125,3.1981608,,
1350.02801,125.25,3.2058288,,
1350.02854,125.5,3.205872,,
1350.02982,125.75,3.2052888,,
1350.03107,126,3.1983012,,
1350.03056,126.25,3.1982472,,
1350.02952,126.5,3.1972752,,
1350.02536,126.75,3.2069844,,
1350.02683,127,3.2127948,,
1350.03028,127.25,3.2206788,,
1350.03181,127.5,3.2249664,,
1350.03406,127.75,3.2049,,
1350.03336,128,3.2091552,,
1350.03064,128.25,3.2200632,,
1350.028,128.5,3.2210028,,
1350.03024,128.75,3.2231952,,
1350.03166,129,3.2233896,,
1350.03587,129.25,3.2237568,,
1350.02999,129.5,3.2251392,,
1350.02792,129.75,3.237192,,
1350.02749,130,3.2359284,,
1350.02749,130.25,3.2212728,,
1350.03395,130.5,3.2342868,,
1350.03065,130.75,3.2322888,,
1350.0324,131,3.231468,,
1350.02719,131.25,3.2349996,,
1350.02897,131.5,3.2423976,,
1350.03183,131.75,3.2369976,,
1350.03385,132,3.234492,,
1350.03069,132.25,3.237192,,
1350.02852,132.5,3.2406264,,
1350.02293,132.75,3.2414364,,
1350.0222,133,3.2441688,,
1350.02521,133.25,3.243996,,
1350.03177,133.5,3.2465448,,
1350.03678,133.75,3.2545584,,
1350.03616,134,3.2497416,,
1350.03542,134.25,3.2510052,,
1350.03653,134.5,3.2533164,,
1350.03325,134.75,3.2546016,,
1350.03197,135,3.2586624,,
1350.02963,135.25,3.2543316,,
1350.02785,135.5,3.2588892,,
1350.02468,135.75,3.26457,,
1350.02528,136,3.2589108,,
1350.02828,136.25,3.2568156,,
1350.02969,136.5,3.2680152,,
1350.03401,136.75,3.2662008,,
1350.02714,137,3.2670432,,
1350.02821,137.25,3.265056,,
1350.0284,137.5,3.272346,,
1350.02724,137.75,3.2736636,,
1350.0292,138,3.28374,,
1350.02925,138.25,3.2711148,,
1350.02927,138.5,3.2769144,,
1350.03322,138.75,3.2943024,,
1350.0326,139,3.291786,,
1350.03305,139.25,3.294,,
1350.03184,139.5,3.287412,,
1350.03034,139.75,3.2926392,,
1350.02408,140,3.302478,,
1350.02345,140.25,3.3095304,,
1350.02223,140.5,3.3055668,,
1350.02325,140.75,3.2994108,,
1350.02407,141,3.2949936,,
1350.02476,141.25,3.305502,,
1350.03086,141.5,3.3028236,,
1350.03593,141.75,3.3022188,,
1350.03705,142,3.3061824,,
1350.03687,142.25,3.3061932,,
1350.03462,142.5,3.3052536,,
1350.03382,142.75,3.3054804,,
1350.03022,143,3.3074136,,
1350.02577,143.25,3.3054048,,
1350.02369,143.5,3.3094008,,
1350.02856,143.75,3.3153516,,
1350.03122,144,3.3095196,,
1350.03069,144.25,3.3071436,,
1350.03089,144.5,3.3169392,,
1350.02625,144.75,3.3232248,,
1350.0307,145,3.3241968,,
1350.03127,145.25,3.3176088,,
1350.03279,145.5,3.3276096,,
1350.03265,145.75,3.3281604,,
1350.03307,146,3.3253848,,
1350.03064,146.25,3.3278904,,
1350.03118,146.5,3.3310872,,
1350.03338,146.75,3.3344136,,
1350.03415,147,3.3349428,,
1350.03599,147.25,3.3339816,,
1350.03317,147.5,3.3366708,,
1350.03266,147.75,3.3263028,,
1350.03145,148,3.3366276,,
1350.03063,148.25,3.3410988,,
1350.02736,148.5,3.3371892,,
1350.02801,148.75,3.3433452,,
1350.02817,149,3.3521688,,
1350.03281,149.25,3.3518556,,
1350.03321,149.5,3.3367464,,
1350.03203,149.75,3.3529572,,
1350.02835,150,3.3580332,,
1350.02442,150.25,3.3529032,,
1350.0214,150.5,3.3509808,,
1350.0247,150.75,3.3555168,,
1350.03068,151,3.3544368,,
1350.03664,151.25,3.3596856,,
1350.03429,151.5,3.3595452,,
1350.03397,151.75,3.3580548,,
1350.03263,152,3.359772,,
1350.03123,152.25,3.3707664,,
1350.02948,152.5,3.3634656,,
1350.02958,152.75,3.365334,,
1350.03014,153,3.36366,,
1350.02808,153.25,3.362094,,
1350.02821,153.5,3.372786,,
1350.02652,153.75,3.3827112,,
1350.02617,154,3.3843528,,
1350.02793,154.25,3.3766092,,
1350.02521,154.5,3.373272,,
1350.02524,154.75,3.376512,,
1350.02525,155,3.3786396,,
1350.02729,155.25,3.3855516,,
1350.03021,155.5,3.38661,,
1350.03029,155.75,3.3905844,,
1350.03047,156,3.3838452,,
1350.03107,156.25,3.3782832,,
1350.02979,156.5,3.3878844,,
1350.0317,156.75,3.3873336,,
1350.03243,157,3.3901524,,
1350.0293,157.25,3.385098,,
1350.0305,157.5,3.3786072,,
1350.03097,157.75,3.3890724,,
1350.03203,158,3.400542,,
1350.03443,158.25,3.3979824,,
1350.03379,158.5,3.3876792,,
1350.03278,158.75,3.391038,,
1350.03104,159,3.396222,,
1350.03022,159.25,3.4034688,,
1350.02921,159.5,3.398814,,
1350.03043,159.75,3.4039332,,
1350.03164,160,3.4114932,,
1350.02946,160.25,3.4027344,,
1350.03016,160.5,3.415284,,
1350.03087,160.75,3.4176924,,
1350.03214,161,3.4118712,,
1350.0311,161.25,3.401676,,
1350.02892,161.5,3.4090092,,
1350.02789,161.75,3.4144092,,
1350.02695,162,3.4163316,,
1350.02652,162.25,3.426246,,
1350.02675,162.5,3.431484,,
1350.02815,162.75,3.4243452,,
1350.02992,163,3.4246368,,
1350.02875,163.25,3.4249824,,
1350.02807,163.5,3.4256088,,
1350.02775,163.75,3.424572,,
1350.02463,164,3.43386,,
1350.02231,164.25,3.4326828,,
1350.02601,164.5,3.4317648,,
1350.03056,164.75,3.4304796,,
1350.03292,165,3.4371,,
1350.03052,165.25,3.4354692,,
1350.02828,165.5,3.4435368,,
1350.02914,165.75,3.44682,,
1350.02958,166,3.439854,,
1350.03032,166.25,3.4332552,,
1350.02908,166.5,3.4392168,,
1350.02891,166.75,3.4394112,,
1350.02924,167,3.452166,,
1350.02946,167.25,3.4574364,,
1350.03132,167.5,3.4460532,,
1350.02948,167.75,3.4347456,,
1350.03027,168,3.4415712,,
1350.02877,168.25,3.4526736,,
1350.02792,168.5,3.4581492,,
1350.02815,168.75,3.4477056,,
1350.02732,169,3.4470468,,
1350.02745,169.25,3.4534512,,
1350.02782,169.5,3.452706,,
1350.02721,169.75,3.4609788,,
1350.02713,170,3.4549416,,
1350.0295,170.25,3.4599528,,
1350.02982,170.5,3.4587432,,
1350.0326,170.75,3.4582896,,
1350.02802,171,3.45897,,
1350.02429,171.25,3.4663356,,
1350.02503,171.5,3.4683336,,
1350.02706,171.75,3.4734744,,
1350.033,172,3.4665732,,
1350.03422,172.25,3.4734744,,
1350.03447,172.5,3.4802028,,
1350.0344,172.75,3.477384,,
1350.03425,173,3.4645212,,
1350.03432,173.25,3.4723512,,
1350.03149,173.5,3.4826652,,
1350.03294,173.75,3.4835832,,
1350.03155,174,3.4738632,,
1350.0318,174.25,3.4747488,,
1350.03197,174.5,3.4783236,,
1350.02832,174.75,3.4848144,,
1350.02683,175,3.4891236,,
1350.02738,175.25,3.4844364,,
1350.02874,175.5,3.4885512,,
1350.03261,175.75,3.486456,,
1350.03173,176,3.4999128,,
1350.03307,176.25,3.4970076,,
1350.03404,176.5,3.4893288,,
1350.03542,176.75,3.5003772,,
1350.03444,177,3.4881948,,
1350.03173,177.25,3.5090496,,
1350.02727,177.5,3.4963056,,
1350.02724,177.75,3.4993404,,
1350.02867,178,3.5041248,,
1350.03478,178.25,3.500334,,
1350.03761,178.5,3.5012088,,
1350.0369,178.75,3.5018244,,
1350.03892,179,3.4998912,,
1350.03959,179.25,3.5088444,,
1350.03531,179.5,3.5046,,
1350.03407,179.75,3.5032608,,
1350.02996,180,3.5063172,,
1350.02936,180.25,3.5169876,,
1350.02897,180.5,3.510378,,
1350.02889,180.75,3.514644,,
1350.03026,181,3.5040492,,
1350.02678,181.25,3.5094384,,
1350.02845,181.5,3.5159184,,
1350.03029,181.75,3.5222148,,
1350.03313,182,3.5235972,,
1350.03223,182.25,3.529386,,
1350.02961,182.5,3.531708,,
1350.02998,182.75,3.5319456,,
1350.02991,183,3.5226036,,
1350.03357,183.25,3.5267184,,
1350.03149,183.5,3.5268696,,
1350.03028,183.75,3.5367624,,
1350.03189,184,3.5410068,,
1350.03047,184.25,3.539484,,
1350.03106,184.5,3.537918,,
1350.03036,184.75,3.5380584,,
1350.03139,185,3.5308116,,
1350.02928,185.25,3.5313084,,
1350.02798,185.5,3.5375184,,
1350.0264,185.75,3.5420868,,
1350.02512,186,3.5374104,,
1350.02115,186.25,3.53673,,
1350.02335,186.5,3.5416656,,
1350.02534,186.75,3.5351316,,
1350.03165,187,3.539484,,
1350.03394,187.25,3.5415684,,
1350.03272,187.5,3.5432964,,
1350.0318,187.75,3.5514828,,
1350.0303,188,3.5552952,,
1350.02937,188.25,3.5525844,,
1350.03262,188.5,3.55509,,
1350.03062,188.75,3.5626716,,
1350.03458,189,3.5628552,,
1350.03322,189.25,3.556008,,
1350.03421,189.5,3.5570232,,
1350.03414,189.75,3.5607816,,
1350.03241,190,3.5619588,,
1350.03074,190.25,3.56589,,
1350.02975,190.5,3.572532,,
1350.02814,190.75,3.5698212,,
1350.02981,191,3.5609436,,
1350.03199,191.25,3.5672292,,
1350.03376,191.5,3.5766684,,
1350.03255,191.75,3.5728452,,
1350.03208,192,3.5715708,,
1350.03127,192.25,3.5733312,,
1350.03218,192.5,3.5779752,,
1350.03157,192.75,3.5764416,,
1350.03126,193,3.5773596,,
1350.03137,193.25,3.5784504,,
1350.02965,193.5,3.5826408,,
1350.02902,193.75,3.5884944,,
1350.02744,194,3.5880192,,
1350.02982,194.25,3.5856648,,
1350.03239,194.5,3.5815392,,
1350.0343,194.75,3.5897796,,
1350.03496,195,3.5843256,,
1350.03237,195.25,3.5917344,,
1350.02962,195.5,3.5935164,,
1350.02838,195.75,3.593268,,
1350.02461,196,3.5871444,,
1350.02299,196.25,3.5923392,,
1350.02693,196.5,3.5933544,,
1350.0299,196.75,3.5939484,,
1350.03659,197,3.589218,,
1350.03676,197.25,3.5961516,,
1350.03323,197.5,3.597966,,
1350.03068,197.75,3.59883,,
1350.02913,198,3.6022752,,
1350.02926,198.25,3.6031824,,
1350.0282,198.5,3.6040788,,
1350.02763,198.75,3.6079344,,
1350.02886,199,3.6041436,,
1350.02966,199.25,3.6069516,,
1350.03017,199.5,3.6124812,,
1350.03059,199.75,3.6059796,,
1350.0307,200,3.6132804,,
1350.0275,200.25,3.6139284,,
1350.02581,200.5,3.6201276,,
1350.02895,200.75,3.6158508,,
1350.03262,201,3.6168228,,
1350.03523,201.25,3.6183024,,
1350.03639,201.5,3.6168444,,
1350.0359,201.75,3.621186,,
1350.03175,202,3.6233784,,
1350.03047,202.25,3.6215856,,
1350.02867,202.5,3.6215964,,
1350.02917,202.75,3.6238104,,
1350.02611,203,3.624048,,
1350.02752,203.25,3.6260784,,
1350.03042,203.5,3.625992,,
1350.02948,203.75,3.6246852,,
1350.031,204,3.6301932,,
1350.03255,204.25,3.6377748,,
1350.03542,204.5,3.634956,,
1350.03367,204.75,3.6345024,,
1350.03266,205,3.6362304,,
1350.03059,205.25,3.629016,,
1350.03051,205.5,3.6317484,,
1350.03385,205.75,3.631878,,
1350.03359,206,3.6430344,,
1350.03288,206.25,3.6450756,,
1350.03421,206.5,3.6460908,,
1350.03221,206.75,3.642354,,
1350.03051,207,3.6430236,,
1350.02822,207.25,3.6458424,,
1350.02778,207.5,3.6532404,,
1350.02743,207.75,3.6561888,,
1350.02753,208,3.6543528,,
1350.02636,208.25,3.6484344,,
1350.02373,208.5,3.64635,,
1350.02457,208.75,3.64932,,
1350.02591,209,3.6510912,,
1350.03221,209.25,3.6592452,,
1350.03316,209.5,3.6545472,,
1350.03067,209.75,3.6499572,,
1350.02861,210,3.6475164,,
1350.02769,210.25,3.6607248,,
1350.02715,210.5,3.6547956,,
1350.02491,210.75,3.6565452,,
1350.02702,211,3.6619128,,
1350.02835,211.25,3.6616104,,
1350.0343,211.5,3.673458,,
1350.0345,211.75,3.665682,,
1350.03341,212,3.672324,,
1350.0317,212.25,3.67362,,
1350.02935,212.5,3.6710496,,
1350.02928,212.75,3.665952,,
1350.02877,213,3.6730152,,
1350.02858,213.25,3.6714384,,
1350.02876,213.5,3.6777672,,
1350.02878,213.75,3.6779832,,
1350.02989,214,3.6790092,,
1350.03251,214.25,3.6815148,,
1350.03405,214.5,3.682044,,
1350.03571,214.75,3.682908,,
1350.03409,215,3.6793332,,
1350.03294,215.25,3.6838692,,
1350.03154,215.5,3.6779508,,
1350.03076,215.75,3.6837612,,
1350.03299,216,3.6902952,,
1350.03478,216.25,3.6886104,,
1350.0317,216.5,3.687282,,
1350.02958,216.75,3.681936,,
1350.02768,217,3.6901332,,
1350.02792,217.25,3.7010628,,
1350.03022,217.5,3.6984816,,
1350.03212,217.75,3.691656,,
1350.03452,218,3.695922,,
1350.03107,218.25,3.6971208,,
1350.02596,218.5,3.7005768,,
1350.02299,218.75,3.698352,,
1350.02158,219,3.7030716,,
1350.02782,219.25,3.7021536,,
1350.02983,219.5,3.6940644,,
1350.03065,219.75,3.6991404,,
1350.03237,220,3.7023264,,
1350.03361,220.25,3.7102752,,
1350.03475,220.5,3.707856,,
1350.03398,220.75,3.7033632,,
1350.03359,221,3.7031256,,
1350.03534,221.25,3.6961812,,
1350.03452,221.5,3.7064304,,
1350.03297,221.75,3.7072836,,
1350.03114,222,3.7144332,,
1350.03254,222.25,3.7089252,,
1350.03459,222.5,3.7086768,,
1350.03453,222.75,3.7079316,,
1350.03432,223,3.71115,,
1350.03458,223.25,3.71331,,
1350.03292,223.5,3.7142172,,
1350.03174,223.75,3.7201572,,
1350.02771,224,3.7204272,,
1350.02463,224.25,3.7120464,,
1350.02288,224.5,3.716064,,
1350.02515,224.75,3.7220688,,
1350.02539,225,3.7204596,,
1350.02851,225.25,3.722598,,
1350.02776,225.5,3.7178676,,
1350.02411,225.75,3.7306224,,
1350.02254,226,3.7317672,,
1350.0217,226.25,3.7306008,,
1350.02706,226.5,3.736152,,
1350.03501,226.75,3.7380312,,
1350.03513,227,3.7340892,,
1350.03311,227.25,3.7369404,,
1350.03353,227.5,3.7396188,,
1350.03144,227.75,3.7422972,,
1350.03072,228,3.7472328,,
1350.02974,228.25,3.7445544,,
1350.02525,228.5,3.744522,,
1350.03025,228.75,3.744252,,
1350.03118,229,3.7476432,,
1350.03314,229.25,3.7447488,,
1350.03357,229.5,3.740634,,
1350.03113,229.75,3.7432368,,
1350.02918,230,3.7508616,,
1350.02599,230.25,3.7460664,,
1350.02635,230.5,3.7455048,,
1350.02625,230.75,3.735504,,
1350.029,231,3.7448352,,
1350.02723,231.25,3.748248,,
1350.02793,231.5,3.7544688,,
1350.03293,231.75,3.7606464,,
1350.0321,232,3.7591236,,
1350.03124,232.25,3.7510668,,
1350.0282,232.5,3.7563912,,
1350.02547,232.75,3.7596204,,
1350.02684,233,3.7605924,,
1350.02771,233.25,3.7688436,,
1350.02705,233.5,3.7616184,,
1350.02916,233.75,3.7621368,,
1350.02971,234,3.772062,,
1350.02822,234.25,3.7665432,,
1350.03104,234.5,3.7695672,,
1350.0347,234.75,3.7716408,,
1350.03554,235,3.7753668,,
1350.0354,235.25,3.7738008,,
1350.03502,235.5,3.7727424,,
1350.0379,235.75,3.770712,,
1350.03564,236,3.76677,,
1350.03337,236.25,3.7763604,,
1350.03345,236.5,3.77163,,
1350.03256,236.75,3.7760364,,
1350.03505,237,3.7766844,,
1350.0311,237.25,3.7726884,,
1350.03,237.5,3.770658,,
1350.02943,237.75,3.7779588,,
1350.03124,238,3.7829808,,
1350.02685,238.25,3.7842768,,
1350.02741,238.5,3.7847628,,
1350.0293,238.75,3.7788012,,
1350.03114,239,3.7773108,,
1350.0331,239.25,3.7798812,,
1350.03237,239.5,3.7909188,,
1350.03441,239.75,3.7964808,,
1350.03356,240,3.7901088,,
1350.03212,240.25,3.78702,,
1350.02741,240.5,3.7932624,,
1350.02745,240.75,3.7939104,,
1350.02599,241,3.7816308,,
1350.03134,241.25,3.7922688,,
1350.0329,241.5,3.7933704,,
1350.03495,241.75,3.7875168,,
1350.03651,242,3.7937376,,
1350.03653,242.25,3.7958004,,
1350.03551,242.5,3.8002284,,
1350.03396,242.75,3.8038572,,
1350.03336,243,3.800682,,
1350.03272,243.25,3.8025504,,
1350.02821,243.5,3.8056068,,
1350.02681,243.75,3.8116008,,
1350.027,244,3.8147652,,
1350.02918,244.25,3.810672,,
1350.03182,244.5,3.8116548,,
1350.03226,244.75,3.8175192,,
1350.03047,245,3.8091816,,
1350.03023,245.25,3.810888,,
1350.02999,245.5,3.8123892,,
1350.03187,245.75,3.8111904,,
1350.03333,246,3.8095812,,
1350.03339,246.25,3.8047212,,
1350.03139,246.5,3.8065464,,
1350.03098,246.75,3.8081664,,
1350.03048,247,3.8042892,,
1350.03021,247.25,3.8091816,,
1350.03021,247.5,3.81807,,
1350.0311,247.75,3.818826,,
1350.03098,248,3.8180592,,
1350.03001,248.25,3.8149272,,
1350.03027,248.5,3.823578,,
1350.02807,248.75,3.8288916,,
1350.02942,249,3.8232972,,
1350.02863,249.25,3.8316132,,
1350.02937,249.5,3.8406204,,
1350.03123,249.75,3.8323584,,
1350.0359,250,3.831732,,
1350.03176,250.25,3.825576,,
1350.03,250.5,3.830544,,
1350.02908,250.75,3.8286216,,
1350.02997,251,3.8325744,,
1350.03108,251.25,3.8351124,,
1350.0292,251.5,3.83481,,
1350.0301,251.75,3.8373912,,
1350.03117,252,3.8389356,,
1350.03359,252.25,3.8458476,,
1350.03303,252.5,3.8344968,,
1350.03171,252.75,3.8418192,,
1350.0309,253,3.848634,,
1350.02777,253.25,3.8377584,,
1350.02578,253.5,3.847014,,
1350.02669,253.75,3.850848,,
1350.02502,254,3.8447244,,
1350.02511,254.25,3.8488392,,
1350.02995,254.5,3.8517984,,
1350.032,254.75,3.8512476,,
1350.03497,255,3.8531592,,
1350.0348,255.25,3.8536668,,
1350.03205,255.5,3.8508588,,
1350.03454,255.75,3.8504592,,
1350.03849,256,3.8577276,,
1350.04151,256.25,3.855168,,
1350.03926,256.5,3.8579112,,
1350.03391,256.75,3.8598336,,
1350.03021,257,3.857328,,
1350.02628,257.25,3.8595312,,
1350.02732,257.5,3.8637324,,
1350.02758,257.75,3.8596932,,
1350.02932,258,3.8665404,,
1350.0331,258.25,3.8562048,,
1350.03409,258.5,3.8609676,,
1350.03681,258.75,3.8679768,,
1350.03581,259,3.8669292,,
1350.03571,259.25,3.8658276,,
1350.03236,259.5,3.8622204,,
1350.03004,259.75,3.86721,,
1350.03151,260,3.8767464,,
1350.0291,260.25,3.8724264,,
1350.03295,260.5,3.8721132,,
1350.03107,260.75,3.8753964,,
1350.03129,261,3.8707524,,
1350.03488,261.25,3.8851812,,
1350.0323,261.5,3.8728908,,
1350.03183,261.75,3.87396,,
1350.02849,262,3.8751264,,
1350.02825,262.25,3.8749644,,
1350.03004,262.5,3.877848,,
1350.03106,262.75,3.8802348,,
1350.03169,263,3.8810664,,
1350.02571,263.25,3.89043,,
1350.02539,263.5,3.8795544,,
1350.02555,263.75,3.8856672,,
1350.02933,264,3.8807532,,
1350.03073,264.25,3.896424,,
1350.03227,264.5,3.8873628,,
1350.03407,264.75,3.8859804,,
1350.03306,265,3.8868876,,
1350.03393,265.25,3.8934108,,
1350.03415,265.5,3.8945664,,
1350.03453,265.75,3.8872008,,
1350.02731,266,3.8857968,,
1350.02645,266.25,3.8875356,,
1350.02669,266.5,3.889188,,
1350.03269,266.75,3.8942532,,
1350.03762,267,3.8901384,,
1350.03598,267.25,3.8957868,,
1350.0335,267.5,3.906198,,
1350.0278,267.75,3.9037032,,
1350.02627,268,3.896964,,
1350.02887,268.25,3.8970396,,
1350.0311,268.5,3.8991672,,
1350.03469,268.75,3.897018,,
1350.03565,269,3.896856,,
1350.03615,269.25,3.9026016,,
1350.03668,269.5,3.90987,,
1350.03298,269.75,3.9071916,,
1350.03328,270,3.9050748,,
1350.03228,270.25,3.9102048,,
1350.03536,270.5,3.9055176,,
1350.03192,270.75,3.9086064,,
1350.02807,271,3.9087036,,
1350.02807,271.25,3.9175272,,
1350.02761,271.5,3.9155724,,
1350.03078,271.75,3.905442,,
1350.0301,272,3.9088332,,
1350.02641,272.25,3.9107232,,
1350.0269,272.5,3.9156048,,
1350.02997,272.75,3.9130992,,
1350.02792,273,3.9186504,,
1350.02576,273.25,3.91932,,
1350.02656,273.5,3.9236076,,
1350.02671,273.75,3.9212748,,
1350.03054,274,3.927312,,
1350.03216,274.25,3.9257244,,
1350.03086,274.5,3.9312972,,
1350.03019,274.75,3.9271932,,
1350.03096,275,3.930012,,
1350.02932,275.25,3.9373776,,
1350.0254,275.5,3.940488,,
1350.02383,275.75,3.931038,,
1350.02825,276,3.9276036,,
1350.0317,276.25,3.9305628,,
1350.03098,276.5,3.9251628,,
1350.02965,276.75,3.933144,,
1350.02901,277,3.9386844,,
1350.03469,277.25,3.9391812,,
1350.0362,277.5,3.9409524,,
1350.03598,277.75,3.9289104,,
1350.03558,278,3.925908,,
1350.03414,278.25,3.9367944,,
1350.03441,278.5,3.9309516,,
1350.03276,278.75,3.9320208,,
1350.02966,279,3.9310812,,
1350.02931,279.25,3.93147,,
1350.02899,279.5,3.9452616,,
1350.02923,279.75,3.9489552,,
1350.03232,280,3.9470328,,
1350.03374,280.25,3.9544848,,
1350.03298,280.5,3.956364,,
1350.03274,280.75,3.9579192,,
1350.02984,281,3.9540636,,
1350.03046,281.25,3.9491928,,
1350.03331,281.5,3.9479292,,
1350.03398,281.75,3.94686,,
1350.0327,282,3.95631,,
1350.03078,282.25,3.9549384,,
1350.02971,282.5,3.9515688,,
1350.02966,282.75,3.9488796,,
1350.02707,283,3.952476,,
1350.02782,283.25,3.9546792,,
1350.02725,283.5,3.9620016,,
1350.03152,283.75,3.953772,,
1350.03413,284,3.959442,,
1350.03421,284.25,3.9629088,,
1350.03412,284.5,3.9638268,,
1350.03302,284.75,3.9578004,,
1350.03222,285,3.9630384,,
1350.03126,285.25,3.969,,
1350.03134,285.5,3.9674448,,
1350.03135,285.75,3.968568,,
1350.02883,286,3.967704,,
1350.03068,286.25,3.9700584,,
1350.03004,286.5,3.9724128,,
1350.03146,286.75,3.9751776,,
1350.03106,287,3.9725208,,
1350.03001,287.25,3.9698208,,
1350.02915,287.5,3.976128,,
1350.02906,287.75,3.9777912,,
1350.02874,288,3.9776832,,
1350.0294,288.25,3.9780504,,
1350.03306,288.5,3.9743784,,
1350.03078,288.75,3.9695832,,
1350.02913,289,3.9774996,,
1350.02217,289.25,3.9829104,,