File: ExampleData/T.3.2 Isothermal Section.csv
#EXPORTTYPE:DATA ALL,,,,
#FILE:,,,,
#FORMAT:NETZSCH5,,,,
#FTYPE:ANSI,,,,
#IDENTITY:,,,,
#DECIMAL:POINT,,,,
#SEPARATOR:SEMICOLON,,,,
#MTYPE:TG,,,,
#INSTRUMENT:NETZSCH STA 449F1,,,,
#PROJECT:,,,,
#DATE/TIME:31.01.2019 21:55,,,,
#CORR. FILE:,,,,
#TEMPCAL:TGA temperature calibration.ngb-ts1,,,,
#SENSITIVITY:---,,,,
#LABORATORY:,,,,
#OPERATOR:,,,,
#REMARK:,,,,
#SAMPLE:,,,,
#SAMPLE MASS /mg:963.94,,,,
#MATERIAL:FeCrAl-ODS,,,,
#REFERENCE:,,,,
#REFERENCE MASS /mg:,,,,
#TYPE OF CRUCIBLE:DTA/TG crucible Al2O3,,,,
#SAMPLE CRUCIBLE MASS /mg:0,,,,
#REFERENCE CRUCIBLE MASS /mg:,,,,
#TG RANGE /mg:5000,,,,
#TAU-R:---,,,,
#CORR. CODE:000,,,,
#EXO:-1,,,,
#RANGE:30°C....1400°C/0.0....50.0K/min,,,,
#SEGMENT:S1-4/4,,,,
#SEG. 1:30°C/50.0(K/min)/1300°C,,,,
#SEG. 2:1300°C/10.0(K/min)/1400°C,,,,
#SEG. 3:1400°C/00:15/1400°C,,,,
#SEG. 4:1400°C/04:00/1400°C,,,,
,,,surface area,2.856472
##Temp./°C,Time/min,Mass loss(subtr.)/mg,,
1400.02981,50.5,0.56014,,
1400.01255,50.75,0.77467,,
1400.01766,51,0.98555,,
1400.02193,51.25,1.10065,,
1400.01899,51.5,1.14427,,
1400.00959,51.75,1.1799,,
1399.99988,52,1.1877,,
1399.99374,52.25,1.2079,,
1399.98968,52.5,1.22341,,
1399.98346,52.75,1.23304,,
1399.982,53,1.24016,,
1399.98357,53.25,1.24928,,
1399.98746,53.5,1.25415,,
1399.99499,53.75,1.26609,,
1399.99547,54,1.2734,,
1399.99249,54.25,1.2836,,
1399.99077,54.5,1.29098,,
1399.99367,54.75,1.29961,,
1399.99842,55,1.30167,,
1400.00378,55.25,1.31129,,
1400.00382,55.5,1.31724,,
1400.00345,55.75,1.33014,,
1400.00578,56,1.32605,,
1400.00833,56.25,1.33685,,
1400.01047,56.5,1.33611,,
1400.01224,56.75,1.34501,,
1400.01076,57,1.34404,,
1400.0126,57.25,1.34797,,
1400.00969,57.5,1.35078,,
1400.01094,57.75,1.35795,,
1400.01129,58,1.35908,,
1400.01074,58.25,1.36305,,
1400.01161,58.5,1.36035,,
1400.01073,58.75,1.36559,,
1400.00588,59,1.3734,,
1400.00598,59.25,1.37553,,
1400.00466,59.5,1.37371,,
1400.00846,59.75,1.38129,,
1400.00532,60,1.36601,,
1400.00803,60.25,1.39217,,
1400.01169,60.5,1.39538,,
1400.01523,60.75,1.40371,,
1400.01843,61,1.40636,,
1400.01439,61.25,1.4095,,
1400.01416,61.5,1.40125,,
1400.01478,61.75,1.41203,,
1400.01943,62,1.41606,,
1400.02079,62.25,1.41911,,
1400.02185,62.5,1.41728,,
1400.02122,62.75,1.42005,,
1400.0191,63,1.42987,,
1400.01803,63.25,1.43347,,
1400.01784,63.5,1.42669,,
1400.0204,63.75,1.43834,,
1400.02353,64,1.43914,,
1400.02403,64.25,1.44932,,
1400.02357,64.5,1.44008,,
1400.02565,64.75,1.4511,,
1400.02517,65,1.45313,,
1400.0272,65.25,1.45855,,
1400.02574,65.5,1.46003,,
1400.02543,65.75,1.46308,,
1400.02527,66,1.46883,,
1400.02225,66.25,1.47468,,
1400.01943,66.5,1.46992,,
1400.01748,66.75,1.47509,,
1400.01901,67,1.4795,,
1400.02318,67.25,1.4782,,
1400.0243,67.5,1.48826,,
1400.02134,67.75,1.49534,,
1400.02189,68,1.49267,,
1400.0205,68.25,1.49474,,
1400.02084,68.5,1.50163,,
1400.01945,68.75,1.49846,,
1400.01935,69,1.50488,,
1400.01991,69.25,1.50545,,
1400.02219,69.5,1.51065,,
1400.02409,69.75,1.51302,,
1400.02639,70,1.51664,,
1400.02345,70.25,1.51695,,
1400.02168,70.5,1.52254,,
1400.01949,70.75,1.52066,,
1400.02155,71,1.52618,,
1400.02374,71.25,1.52937,,
1400.02225,71.5,1.53413,,
1400.02159,71.75,1.53569,,
1400.01931,72,1.53956,,
1400.02561,72.25,1.54619,,
1400.02913,72.5,1.55141,,
1400.03173,72.75,1.54908,,
1400.03021,73,1.55406,,
1400.02635,73.25,1.55778,,
1400.02276,73.5,1.56049,,
1400.01848,73.75,1.55549,,
1400.01879,74,1.56743,,
1400.02039,74.25,1.56625,,
1400.02336,74.5,1.57107,,
1400.02401,74.75,1.57564,,
1400.02397,75,1.57666,,
1400.02383,75.25,1.58238,,
1400.02423,75.5,1.58495,,
1400.0235,75.75,1.59125,,
1400.02326,76,1.59035,,
1400.02358,76.25,1.60051,,
1400.02381,76.5,1.59746,,
1400.02476,76.75,1.60117,,
1400.02605,77,1.60454,,
1400.02687,77.25,1.60678,,
1400.02752,77.5,1.59528,,
1400.0278,77.75,1.61312,,
1400.02823,78,1.61391,,
1400.02795,78.25,1.61472,,
1400.02746,78.5,1.61349,,
1400.02577,78.75,1.61967,,
1400.02467,79,1.62862,,
1400.02408,79.25,1.63546,,
1400.02454,79.5,1.62911,,
1400.02504,79.75,1.63169,,
1400.02499,80,1.6351,,
1400.02598,80.25,1.64265,,
1400.02746,80.5,1.64189,,
1400.02607,80.75,1.6465,,
1400.02431,81,1.64895,,
1400.02356,81.25,1.64386,,
1400.02337,81.5,1.65218,,
1400.02408,81.75,1.65574,,
1400.02599,82,1.6604,,
1400.02572,82.25,1.66011,,
1400.02755,82.5,1.66885,,
1400.02728,82.75,1.66924,,
1400.02461,83,1.66295,,
1400.02178,83.25,1.67684,,
1400.02024,83.5,1.67483,,
1400.02073,83.75,1.68001,,
1400.02267,84,1.67761,,
1400.02363,84.25,1.68179,,
1400.02491,84.5,1.68726,,
1400.02547,84.75,1.68918,,
1400.02444,85,1.68508,,
1400.0253,85.25,1.69565,,
1400.02536,85.5,1.69791,,
1400.02745,85.75,1.69612,,
1400.02808,86,1.7033,,
1400.02729,86.25,1.70262,,
1400.02624,86.5,1.71215,,
1400.02468,86.75,1.7132,,
1400.02566,87,1.71131,,
1400.02645,87.25,1.7254,,
1400.02752,87.5,1.71773,,
1400.0278,87.75,1.71739,,
1400.0271,88,1.72331,,
1400.02599,88.25,1.72624,,
1400.0251,88.5,1.72321,,
1400.02435,88.75,1.72747,,
1400.02551,89,1.73338,,
1400.02698,89.25,1.74086,,
1400.02879,89.5,1.73418,,
1400.02719,89.75,1.73985,,
1400.02786,90,1.74581,,
1400.02698,90.25,1.73899,,
1400.02618,90.5,1.74676,,
1400.02792,90.75,1.75413,,
1400.02894,91,1.74655,,
1400.02782,91.25,1.75078,,
1400.02697,91.5,1.75844,,
1400.02454,91.75,1.75969,,
1400.02411,92,1.75782,,
1400.02548,92.25,1.76584,,
1400.02644,92.5,1.76499,,
1400.0278,92.75,1.76752,,
1400.0274,93,1.76703,,
1400.02857,93.25,1.77323,,
1400.02898,93.5,1.7766,,
1400.02778,93.75,1.78022,,
1400.0265,94,1.78699,,
1400.02557,94.25,1.78825,,
1400.02508,94.5,1.78576,,
1400.02484,94.75,1.7857,,
1400.02366,95,1.79528,,
1400.0231,95.25,1.79656,,
1400.0255,95.5,1.79599,,
1400.02805,95.75,1.79949,,
1400.03029,96,1.80728,,
1400.03035,96.25,1.80221,,
1400.0291,96.5,1.79828,,
1400.02738,96.75,1.80741,,
1400.02592,97,1.8098,,
1400.02519,97.25,1.81537,,
1400.02443,97.5,1.81317,,
1400.02451,97.75,1.82226,,
1400.025,98,1.81199,,
1400.02527,98.25,1.82498,,
1400.02607,98.5,1.8282,,
1400.02518,98.75,1.82785,,
1400.02556,99,1.82371,,
1400.02626,99.25,1.83251,,
1400.02774,99.5,1.83692,,
1400.02778,99.75,1.83548,,
1400.02626,100,1.8359,,
1400.02424,100.25,1.83895,,
1400.02444,100.5,1.84438,,
1400.02551,100.75,1.84488,,
1400.02563,101,1.84284,,
1400.0274,101.25,1.85098,,
1400.0265,101.5,1.85349,,
1400.02736,101.75,1.84941,,
1400.02691,102,1.85531,,
1400.02521,102.25,1.86365,,
1400.02392,102.5,1.85872,,
1400.02205,102.75,1.8576,,
1400.02209,103,1.86285,,
1400.02133,103.25,1.85465,,
1400.02104,103.5,1.86632,,
1400.02096,103.75,1.87076,,
1400.02246,104,1.86881,,
1400.02281,104.25,1.87439,,
1400.02321,104.5,1.87677,,
1400.02607,104.75,1.87851,,
1400.02908,105,1.87895,,
1400.03189,105.25,1.88008,,
1400.03234,105.5,1.88777,,
1400.032,105.75,1.88121,,
1400.02909,106,1.88017,,
1400.02738,106.25,1.89918,,
1400.02696,106.5,1.89577,,
1400.02865,106.75,1.89314,,
1400.02892,107,1.89414,,
1400.02896,107.25,1.9012,,
1400.02656,107.5,1.90065,,
1400.02445,107.75,1.90443,,
1400.02618,108,1.90572,,
1400.02454,108.25,1.90194,,
1400.02531,108.5,1.91197,,
1400.02334,108.75,1.91456,,
1400.02456,109,1.91195,,
1400.02494,109.25,1.90899,,
1400.02544,109.5,1.92468,,
1400.02728,109.75,1.92148,,
1400.02845,110,1.92328,,
1400.02925,110.25,1.92711,,
1400.02853,110.5,1.92357,,
1400.0271,110.75,1.92644,,
1400.02506,111,1.93156,,
1400.02268,111.25,1.9335,,
1400.0237,111.5,1.93286,,
1400.02532,111.75,1.93845,,
1400.02681,112,1.93577,,
1400.02813,112.25,1.94045,,
1400.02962,112.5,1.94265,,
1400.02976,112.75,1.94806,,
1400.02785,113,1.95083,,
1400.02603,113.25,1.94876,,
1400.0234,113.5,1.94569,,
1400.02379,113.75,1.95423,,
1400.02395,114,1.95575,,
1400.02366,114.25,1.95465,,
1400.02384,114.5,1.95622,,
1400.02197,114.75,1.96425,,
1400.02356,115,1.96074,,
1400.02302,115.25,1.9665,,
1400.02507,115.5,1.97056,,
1400.02401,115.75,1.9744,,
1400.02566,116,1.97819,,
1400.02444,116.25,1.9703,,
1400.02452,116.5,1.96969,,
1400.02558,116.75,1.97575,,
1400.02666,117,1.97953,,
1400.02735,117.25,1.97705,,
1400.02747,117.5,1.97769,,
1400.02511,117.75,1.98335,,
1400.02598,118,1.98322,,
1400.0241,118.25,1.98252,,
1400.02517,118.5,1.99022,,
1400.02554,118.75,1.99607,,
1400.02682,119,1.99769,,
1400.03035,119.25,1.99858,,
1400.03219,119.5,2.01168,,
1400.0335,119.75,1.99643,,
1400.03385,120,2.00147,,
1400.03281,120.25,2.0021,,
1400.03105,120.5,2.00593,,
1400.02976,120.75,2.00523,,
1400.02718,121,2.00654,,
1400.02647,121.25,2.0085,,
1400.02688,121.5,2.01306,,
1400.02721,121.75,2.01718,,
1400.02822,122,2.01655,,
1400.02659,122.25,2.01795,,
1400.02612,122.5,2.01888,,
1400.02396,122.75,2.01801,,
1400.02453,123,2.02549,,
1400.02581,123.25,2.02607,,
1400.02664,123.5,2.02771,,
1400.02472,123.75,2.02804,,
1400.02463,124,2.02839,,
1400.02518,124.25,2.03621,,
1400.02756,124.5,2.0358,,
1400.0283,124.75,2.0364,,
1400.02862,125,2.03932,,
1400.02913,125.25,2.03675,,
1400.02695,125.5,2.04002,,
1400.0259,125.75,2.0367,,
1400.02623,126,2.04101,,
1400.02918,126.25,2.04628,,
1400.03189,126.5,2.05151,,
1400.0304,126.75,2.04907,,
1400.02808,127,2.04717,,
1400.02647,127.25,2.05798,,
1400.0257,127.5,2.05821,,
1400.02448,127.75,2.06405,,
1400.02463,128,2.05976,,
1400.02529,128.25,2.06384,,
1400.02707,128.5,2.06673,,
1400.02799,128.75,2.06756,,
1400.03,129,2.06414,,
1400.03054,129.25,2.06623,,
1400.02948,129.5,2.07117,,
1400.02882,129.75,2.07722,,
1400.02774,130,2.0731,,
1400.02779,130.25,2.07963,,
1400.02915,130.5,2.07634,,
1400.02876,130.75,2.08275,,
1400.027,131,2.08263,,
1400.02632,131.25,2.08553,,
1400.02547,131.5,2.0835,,
1400.02771,131.75,2.09209,,
1400.02649,132,2.08737,,
1400.02404,132.25,2.08975,,
1400.0219,132.5,2.08943,,
1400.0232,132.75,2.09649,,
1400.02566,133,2.10301,,
1400.02888,133.25,2.09832,,
1400.02961,133.5,2.09729,,
1400.02928,133.75,2.1014,,
1400.02728,134,2.10517,,
1400.02474,134.25,2.105,,
1400.02592,134.5,2.11618,,
1400.02686,134.75,2.11374,,
1400.02784,135,2.11103,,
1400.02693,135.25,2.1183,,
1400.02859,135.5,2.11117,,
1400.02876,135.75,2.11818,,
1400.02961,136,2.11475,,
1400.03112,136.25,2.11914,,
1400.03165,136.5,2.12421,,
1400.03251,136.75,2.12253,,
1400.03154,137,2.12052,,
1400.0294,137.25,2.12632,,
1400.02807,137.5,2.12614,,
1400.0249,137.75,2.12851,,
1400.02531,138,2.13114,,
1400.02592,138.25,2.1334,,
1400.02839,138.5,2.13519,,
1400.03035,138.75,2.14033,,
1400.02981,139,2.14172,,
1400.02832,139.25,2.13954,,
1400.03159,139.5,2.13946,,
1400.03313,139.75,2.12748,,
1400.03274,140,2.15192,,
1400.03219,140.25,2.14955,,
1400.02941,140.5,2.14913,,
1400.02824,140.75,2.15326,,
1400.02639,141,2.15212,,
1400.02718,141.25,2.15133,,
1400.02788,141.5,2.15729,,
1400.02636,141.75,2.15564,,
1400.02721,142,2.15771,,
1400.03054,142.25,2.16126,,
1400.03209,142.5,2.14106,,
1400.03359,142.75,2.16377,,
1400.03111,143,2.16529,,
1400.0295,143.25,2.16345,,
1400.02983,143.5,2.16662,,
1400.02956,143.75,2.16887,,
1400.02549,144,2.17319,,
1400.02544,144.25,2.17362,,
1400.02696,144.5,2.17897,,
1400.03015,144.75,2.1745,,
1400.0282,145,2.18464,,
1400.02516,145.25,2.18188,,
1400.0242,145.5,2.17202,,
1400.02234,145.75,2.18016,,
1400.02263,146,2.18384,,
1400.02209,146.25,2.18898,,
1400.02176,146.5,2.18619,,
1400.0262,146.75,2.18615,,
1400.02763,147,2.1815,,
1400.02814,147.25,2.1968,,
1400.02672,147.5,2.19299,,
1400.02732,147.75,2.19583,,
1400.02901,148,2.19117,,
1400.02663,148.25,2.19825,,
1400.02313,148.5,2.20324,,
1400.01891,148.75,2.20003,,
1400.02513,149,2.20321,,
1400.02601,149.25,2.21308,,
1400.03112,149.5,2.20625,,
1400.03298,149.75,2.21205,,
1400.03021,150,2.20776,,
1400.02836,150.25,2.21158,,
1400.02391,150.5,2.215,,
1400.02062,150.75,2.21392,,
1400.02153,151,2.21621,,
1400.02387,151.25,2.21969,,
1400.02535,151.5,2.22692,,
1400.03032,151.75,2.22027,,
1400.0292,152,2.22439,,
1400.0266,152.25,2.22581,,
1400.02208,152.5,2.22795,,
1400.02269,152.75,2.22839,,
1400.02351,153,2.23021,,
1400.02894,153.25,2.23164,,
1400.02788,153.5,2.23365,,
1400.03027,153.75,2.23789,,
1400.0276,154,2.23376,,
1400.02443,154.25,2.23531,,
1400.02041,154.5,2.23651,,
1400.0212,154.75,2.23878,,
1400.02538,155,2.24168,,
1400.03074,155.25,2.2461,,
1400.03344,155.5,2.25046,,
1400.03062,155.75,2.25199,,
1400.02856,156,2.25649,,
1400.0265,156.25,2.2516,,
1400.02662,156.5,2.25715,,
1400.02734,156.75,2.24961,,
1400.02837,157,2.25021,,
1400.02812,157.25,2.25536,,
1400.02723,157.5,2.25802,,
1400.02568,157.75,2.26044,,
1400.02705,158,2.26527,,
1400.02882,158.25,2.26117,,
1400.02783,158.5,2.27059,,
1400.02842,158.75,2.26407,,
1400.02776,159,2.26604,,
1400.03039,159.25,2.27228,,
1400.02959,159.5,2.26988,,
1400.02888,159.75,2.2665,,
1400.02701,160,2.27295,,
1400.02394,160.25,2.27629,,
1400.02192,160.5,2.27507,,
1400.02575,160.75,2.27188,,
1400.02257,161,2.29209,,
1400.02916,161.25,2.27634,,
1400.02836,161.5,2.28793,,
1400.02898,161.75,2.28528,,
1400.02762,162,2.28934,,
1400.01987,162.25,2.28565,,
1400.02149,162.5,2.28979,,
1400.02153,162.75,2.28722,,
1400.02237,163,2.29096,,
1400.02294,163.25,2.2899,,
1400.02003,163.5,2.297,,
1400.02296,163.75,2.29793,,
1400.02542,164,2.29891,,
1400.02925,164.25,2.2992,,
1400.03017,164.5,2.30421,,
1400.02885,164.75,2.30366,,
1400.02995,165,2.3019,,
1400.02905,165.25,2.30511,,
1400.02821,165.5,2.3075,,
1400.02801,165.75,2.30975,,
1400.0308,166,2.31456,,
1400.03393,166.25,2.31002,,
1400.03324,166.5,2.31615,,
1400.02632,166.75,2.31864,,
1400.02279,167,2.31635,,
1400.0244,167.25,2.3178,,
1400.02934,167.5,2.32263,,
1400.03104,167.75,2.32432,,
1400.02827,168,2.32899,,
1400.02458,168.25,2.32745,,
1400.0245,168.5,2.32611,,
1400.02572,168.75,2.32225,,
1400.02634,169,2.32862,,
1400.02684,169.25,2.32745,,
1400.02722,169.5,2.32719,,
1400.02916,169.75,2.33376,,
1400.03095,170,2.33451,,
1400.03205,170.25,2.33828,,
1400.02835,170.5,2.34041,,
1400.02451,170.75,2.3336,,
1400.02168,171,2.34096,,
1400.02425,171.25,2.34241,,
1400.02613,171.5,2.34403,,
1400.03165,171.75,2.34996,,
1400.03015,172,2.34943,,
1400.0282,172.25,2.35783,,
1400.02613,172.5,2.35321,,
1400.02507,172.75,2.35638,,
1400.02372,173,2.35345,,
1400.02597,173.25,2.33444,,
1400.02401,173.5,2.36949,,
1400.02299,173.75,2.35681,,
1400.02512,174,2.3571,,
1400.02618,174.25,2.36093,,
1400.03049,174.5,2.3656,,
1400.02995,174.75,2.36574,,
1400.02762,175,2.36119,,
1400.02644,175.25,2.36454,,
1400.02496,175.5,2.37462,,
1400.02029,175.75,2.36927,,
1400.0184,176,2.37325,,
1400.01957,176.25,2.36575,,
1400.02634,176.5,2.37195,,
1400.03122,176.75,2.38352,,
1400.03372,177,2.36575,,
1400.03314,177.25,2.36404,,
1400.03336,177.5,2.39163,,
1400.03485,177.75,2.38892,,
1400.03465,178,2.38877,,
1400.03072,178.25,2.38369,,
1400.03081,178.5,2.38369,,
1400.02732,178.75,2.3911,,
1400.02574,179,2.38218,,
1400.02371,179.25,2.39453,,
1400.02499,179.5,2.38762,,
1400.02808,179.75,2.39929,,
1400.02761,180,2.40134,,
1400.02785,180.25,2.39769,,
1400.02692,180.5,2.40073,,
1400.02747,180.75,2.39551,,
1400.02764,181,2.40097,,
1400.02426,181.25,2.41319,,
1400.02537,181.5,2.40045,,
1400.02181,181.75,2.40291,,
1400.02451,182,2.40552,,
1400.02171,182.25,2.41236,,
1400.02223,182.5,2.40202,,
1400.02381,182.75,2.41194,,
1400.02641,183,2.40806,,
1400.02678,183.25,2.40149,,
1400.02528,183.5,2.42134,,
1400.02549,183.75,2.41016,,
1400.02231,184,2.41373,,
1400.02094,184.25,2.41864,,
1400.02387,184.5,2.43889,,
1400.02374,184.75,2.41649,,
1400.02656,185,2.42482,,
1400.03026,185.25,2.42857,,
1400.03228,185.5,2.42529,,
1400.03508,185.75,2.42892,,
1400.03329,186,2.42585,,
1400.03152,186.25,2.42777,,
1400.03167,186.5,2.43553,,
1400.0287,186.75,2.43527,,
1400.02846,187,2.43932,,
1400.02981,187.25,2.44311,,
1400.03003,187.5,2.42444,,
1400.0253,187.75,2.44686,,
1400.02445,188,2.44814,,
1400.02364,188.25,2.44074,,
1400.02655,188.5,2.44039,,
1400.02819,188.75,2.44812,,
1400.02639,189,2.43718,,
1400.02646,189.25,2.44339,,
1400.02678,189.5,2.44961,,
1400.0267,189.75,2.45585,,
1400.03054,190,2.45613,,
1400.03062,190.25,2.461,,
1400.03083,190.5,2.46187,,
1400.02865,190.75,2.44751,,
1400.02997,191,2.45164,,
1400.03042,191.25,2.45603,,
1400.02692,191.5,2.45722,,
1400.02525,191.75,2.46332,,
1400.02416,192,2.46633,,
1400.02668,192.25,2.46725,,
1400.03046,192.5,2.4596,,
1400.03289,192.75,2.47557,,
1400.03214,193,2.46951,,
1400.03055,193.25,2.47296,,
1400.02665,193.5,2.46724,,
1400.02409,193.75,2.46115,,
1400.02109,194,2.46843,,
1400.0215,194.25,2.47634,,
1400.02239,194.5,2.47581,,
1400.02402,194.75,2.48675,,
1400.02323,195,2.48263,,
1400.02176,195.25,2.47562,,
1400.02433,195.5,2.48499,,
1400.02605,195.75,2.47875,,
1400.03097,196,2.47727,,
1400.02915,196.25,2.48345,,
1400.02896,196.5,2.49576,,
1400.02777,196.75,2.49718,,
1400.02447,197,2.48164,,
1400.02466,197.25,2.49802,,
1400.02292,197.5,2.49589,,
1400.02533,197.75,2.50464,,
1400.0234,198,2.49658,,
1400.02205,198.25,2.49631,,
1400.02528,198.5,2.50074,,
1400.0297,198.75,2.48936,,
1400.03337,199,2.51119,,
1400.03732,199.25,2.49453,,
1400.03429,199.5,2.50531,,
1400.032,199.75,2.49331,,
1400.03118,200,2.5126,,
1400.02991,200.25,2.50719,,
1400.03294,200.5,2.5077,,
1400.03237,200.75,2.51992,,
1400.03089,201,2.51743,,
1400.03186,201.25,2.52452,,
1400.03192,201.5,2.51797,,
1400.03169,201.75,2.52204,,
1400.0331,202,2.51888,,
1400.03298,202.25,2.5208,,
1400.03103,202.5,2.51319,,
1400.02948,202.75,2.53425,,
1400.02761,203,2.52068,,
1400.02741,203.25,2.5123,,
1400.02801,203.5,2.53552,,
1400.02545,203.75,2.53259,,
1400.0186,204,2.53369,,
1400.01609,204.25,2.53452,,
1400.01635,204.5,2.52562,,
1400.01868,204.75,2.52966,,
1400.02395,205,2.54481,,
1400.02504,205.25,2.53378,,
1400.02672,205.5,2.54083,,
1400.0262,205.75,2.54938,,
1400.02655,206,2.53559,,
1400.02413,206.25,2.54912,,
1400.02334,206.5,2.54958,,
1400.02458,206.75,2.52862,,
1400.02753,207,2.54221,,
1400.03245,207.25,2.54384,,
1400.03172,207.5,2.5564,,
1400.03102,207.75,2.55459,,
1400.02888,208,2.55471,,
1400.02715,208.25,2.54595,,
1400.0239,208.5,2.55531,,
1400.02181,208.75,2.55697,,
1400.02394,209,2.55704,,
1400.02727,209.25,2.55809,,
1400.02817,209.5,2.55744,,
1400.02876,209.75,2.5512,,
1400.0293,210,2.55793,,
1400.03374,210.25,2.55668,,
1400.03313,210.5,2.57014,,
1400.03103,210.75,2.55844,,
1400.03105,211,2.56574,,
1400.03054,211.25,2.56892,,
1400.03107,211.5,2.56669,,
1400.02946,211.75,2.57223,,
1400.02747,212,2.56897,,
1400.02068,212.25,2.5645,,
1400.02064,212.5,2.57401,,
1400.02279,212.75,2.58484,,
1400.02644,213,2.57759,,
1400.02983,213.25,2.59036,,
1400.02672,213.5,2.58318,,
1400.02564,213.75,2.57189,,
1400.02534,214,2.58506,,
1400.03065,214.25,2.58413,,
1400.03128,214.5,2.5782,,
1400.03308,214.75,2.58303,,
1400.03,215,2.59278,,
1400.02746,215.25,2.58895,,
1400.02577,215.5,2.59995,,
1400.02339,215.75,2.59117,,
1400.02475,216,2.58925,,
1400.02689,216.25,2.59295,,
1400.02543,216.5,2.59022,,
1400.02763,216.75,2.59793,,
1400.02341,217,2.60355,,
1400.02577,217.25,2.59246,,
1400.02814,217.5,2.60372,,
1400.03306,217.75,2.5971,,
1400.03693,218,2.60552,,
1400.03454,218.25,2.60489,,
1400.02855,218.5,2.60547,,
1400.02757,218.75,2.60322,,
1400.02933,219,2.6088,,
1400.0322,219.25,2.60915,,
1400.03401,219.5,2.61189,,
1400.03035,219.75,2.60443,,
1400.02963,220,2.60745,,
1400.02662,220.25,2.60849,,
1400.02604,220.5,2.61627,,
1400.0239,220.75,2.6156,,
1400.02711,221,2.61932,,
1400.02864,221.25,2.61824,,
1400.03035,221.5,2.61529,,
1400.02932,221.75,2.61849,,
1400.02902,222,2.6188,,
1400.02667,222.25,2.6191,,
1400.02662,222.5,2.63058,,
1400.02595,222.75,2.62822,,
1400.0263,223,2.62832,,
1400.02905,223.25,2.61915,,
1400.02892,223.5,2.62571,,
1400.03019,223.75,2.625,,
1400.02932,224,2.64201,,
1400.02895,224.25,2.64354,,
1400.02909,224.5,2.63799,,
1400.02684,224.75,2.63243,,
1400.02719,225,2.64535,,
1400.02802,225.25,2.64662,,
1400.02728,225.5,2.65545,,
1400.02783,225.75,2.64337,,
1400.02775,226,2.65322,,
1400.02748,226.25,2.64556,,
1400.02755,226.5,2.64145,,
1400.02662,226.75,2.64178,,
1400.02569,227,2.65832,,
1400.02593,227.25,2.6422,,
1400.02746,227.5,2.64514,,
1400.02855,227.75,2.65047,,
1400.02875,228,2.65777,,
1400.0273,228.25,2.65639,,
1400.02285,228.5,2.65283,,
1400.01989,228.75,2.64524,,
1400.02009,229,2.65535,,
1400.02783,229.25,2.66041,,
1400.03107,229.5,2.66375,,
1400.03,229.75,2.67378,,
1400.02659,230,2.6634,,
1400.02674,230.25,2.6731,,
1400.02944,230.5,2.67071,,
1400.03328,230.75,2.66777,,
1400.03223,231,2.6728,,
1400.02957,231.25,2.67323,,
1400.02972,231.5,2.67683,,
1400.03014,231.75,2.66987,,
1400.02744,232,2.67365,,
1400.03002,232.25,2.67918,,
1400.03216,232.5,2.6866,,
1400.03508,232.75,2.67953,,
1400.03523,233,2.6806,,
1400.03356,233.25,2.68376,,
1400.03109,233.5,2.67682,,
1400.0292,233.75,2.67913,,
1400.02733,234,2.6857,,
1400.02807,234.25,2.68094,,
1400.0289,234.5,2.67895,,
1400.03113,234.75,2.6889,,
1400.03328,235,2.69384,,
1400.03166,235.25,2.69208,,
1400.02934,235.5,2.68887,,
1400.02748,235.75,2.69107,,
1400.02173,236,2.6986,,
1400.02072,236.25,2.7003,,
1400.02335,236.5,2.69804,,
1400.02478,236.75,2.69947,,
1400.02937,237,2.70232,,
1400.0297,237.25,2.70844,,
1400.02699,237.5,2.70296,,
1400.02487,237.75,2.701,,
1400.02749,238,2.71425,,
1400.0275,238.25,2.71461,,
1400.03125,238.5,2.71628,,
1400.02956,238.75,2.71033,,
1400.03052,239,2.70957,,
1400.02742,239.25,2.71538,,
1400.02725,239.5,2.6917,,
1400.02667,239.75,2.71449,,
1400.02562,240,2.70749,,
1400.03126,240.25,2.72314,,
1400.03332,240.5,2.70747,,
1400.03414,240.75,2.71835,,
1400.03349,241,2.71582,,
1400.03158,241.25,2.72819,,
1400.02899,241.5,2.72792,,
1400.02843,241.75,2.73332,,
1400.02912,242,2.72751,,
1400.02936,242.25,2.72452,,
1400.03092,242.5,2.73341,,
1400.03054,242.75,2.72959,,
1400.02937,243,2.73913,,
1400.0275,243.25,2.73957,,
1400.02632,243.5,2.73538,,
1400.02604,243.75,2.74633,,
1400.02884,244,2.72808,,
1400.02945,244.25,2.73354,,
1400.02866,244.5,2.7305,,
1400.02969,244.75,2.7428,,
1400.02806,245,2.75779,,
1400.02899,245.25,2.75009,,
1400.02712,245.5,2.7543,,
1400.02742,245.75,2.73354,,
1400.0261,246,2.7486,,
1400.02697,246.25,2.74913,,
1400.02815,246.5,2.76404,,
1400.02631,246.75,2.75179,,
1400.02548,247,2.76002,,
1400.02482,247.25,2.74457,,
1400.02477,247.5,2.74347,,
1400.02392,247.75,2.7509,,
1400.02657,248,2.76071,,
1400.02591,248.25,2.7593,,
1400.0283,248.5,2.75,,
1400.02624,248.75,2.7471,,
1400.02719,249,2.76916,,
1400.02901,249.25,2.76335,,
1400.02954,249.5,2.7617,,
1400.03012,249.75,2.76118,,
1400.03199,250,2.75577,,
1400.03132,250.25,2.75613,,
1400.03052,250.5,2.76259,,
1400.03147,250.75,2.77938,,
1400.03123,251,2.77005,,
1400.03036,251.25,2.76188,,
1400.03214,251.5,2.77873,,
1400.02941,251.75,2.76731,,
1400.02851,252,2.76145,,
1400.02606,252.25,2.78602,,
1400.02533,252.5,2.78346,,
1400.02364,252.75,2.76951,,
1400.02648,253,2.77996,,
1400.02748,253.25,2.77233,,
1400.02778,253.5,2.77922,,
1400.02845,253.75,2.78946,,
1400.02895,254,2.78958,,
1400.02915,254.25,2.77103,,
1400.02875,254.5,2.78439,,
1400.02567,254.75,2.79109,,
1400.02782,255,2.7924,,
1400.02824,255.25,2.79223,,
1400.02873,255.5,2.8053,,
1400.02968,255.75,2.77718,,
1400.02922,256,2.79431,,
1400.02937,256.25,2.79801,,
1400.02915,256.5,2.79336,,
1400.02347,256.75,2.79675,,
1400.02351,257,2.79813,,
1400.02466,257.25,2.78842,,
1400.02748,257.5,2.79954,,
1400.02894,257.75,2.80772,,
1400.02914,258,2.7949,,
1400.03088,258.25,2.80751,,
1400.03362,258.5,2.76884,,
1400.03464,258.75,2.82799,,
1400.03516,259,2.80446,,
1400.03185,259.25,2.81121,,
1400.03217,259.5,2.80967,,
1400.02979,259.75,2.81232,,
1400.02867,260,2.80546,,
1400.02585,260.25,2.81953,,
1400.02485,260.5,2.80991,,
1400.02052,260.75,2.81778,,
1400.0228,261,2.81865,,
1400.02533,261.25,2.81763,,
1400.03033,261.5,2.81316,,
1400.03422,261.75,2.82272,,
1400.03417,262,2.8214,,
1400.03392,262.25,2.82749,,
1400.03385,262.5,2.83021,,
1400.03203,262.75,2.83051,,
1400.03142,263,2.83304,,
1400.03018,263.25,2.82999,,
1400.02985,263.5,2.82748,,
1400.03112,263.75,2.82898,,
1400.02762,264,2.83659,,
1400.02751,264.25,2.8343,,
1400.02322,264.5,2.82059,,
1400.02231,264.75,2.828,,
1400.02222,265,2.84051,,
1400.02088,265.25,2.83573,,
1400.02171,265.5,2.83991,,
1400.02327,265.75,2.83714,,
1400.0239,266,2.83002,,
1400.02545,266.25,2.83181,,
1400.02814,266.5,2.84157,,
1400.0294,266.75,2.84124,,
1400.03129,267,2.86451,,
1400.03054,267.25,2.83881,,
1400.03011,267.5,2.83125,,
1400.02771,267.75,2.84171,,
1400.02529,268,2.8317,,
1400.0281,268.25,2.85296,,
1400.02715,268.5,2.84483,,
1400.03407,268.75,2.85742,,
1400.03352,269,2.85439,,
1400.0343,269.25,2.85992,,
1400.03343,269.5,2.85131,,
1400.03094,269.75,2.85774,,
1400.03034,270,2.85303,,
1400.02494,270.25,2.86618,,
1400.02718,270.5,2.86145,,
1400.02629,270.75,2.85392,,
1400.02738,271,2.8601,,
1400.02975,271.25,2.86108,,
1400.02828,271.5,2.85903,,
1400.02998,271.75,2.85955,,
1400.02638,272,2.86798,,
1400.02526,272.25,2.86957,,
1400.02508,272.5,2.86963,,
1400.02808,272.75,2.86667,,
1400.02672,273,2.87222,,
1400.02669,273.25,2.87181,,
1400.02759,273.5,2.86999,,
1400.02916,273.75,2.87456,,
1400.0299,274,2.88057,,
1400.02992,274.25,2.88197,,
1400.02804,274.5,2.88133,,
1400.02842,274.75,2.88086,,
1400.024,275,2.86375,,
1400.02561,275.25,2.8729,,
1400.02668,275.5,2.89566,,
1400.03066,275.75,2.88198,,
1400.03301,276,2.87745,,
1400.02576,276.25,2.88591,,
1400.02467,276.5,2.8747,,
1400.02463,276.75,2.89953,,
1400.02905,277,2.87707,,
1400.02971,277.25,2.89206,,
1400.02932,277.5,2.88445,,
1400.0293,277.75,2.88742,,
1400.03093,278,2.9034,,
1400.03212,278.25,2.89277,,
1400.03528,278.5,2.88045,,
1400.03381,278.75,2.90906,,
1400.02604,279,2.897,,
1400.01804,279.25,2.9023,,
1400.01808,279.5,2.89864,,
1400.02128,279.75,2.90839,,
1400.02817,280,2.90424,,
1400.03075,280.25,2.9076,,
1400.0287,280.5,2.90218,,
1400.02782,280.75,2.90935,,
1400.02716,281,2.90458,,
1400.02953,281.25,2.90703,,
1400.02828,281.5,2.91062,,
1400.02768,281.75,2.90924,,
1400.0317,282,2.9151,,
1400.03289,282.25,2.90652,,
1400.03436,282.5,2.91079,,
1400.03143,282.75,2.9173,,
1400.03014,283,2.91212,,
1400.0297,283.25,2.91819,,
1400.02963,283.5,2.91668,,
1400.02977,283.75,2.9288,,
1400.03012,284,2.92051,,
1400.03072,284.25,2.9098,,
1400.03069,284.5,2.92564,,
1400.0303,284.75,2.92758,,
1400.0305,285,2.91947,,
1400.03037,285.25,2.9237,,
1400.02885,285.5,2.91657,,
1400.02678,285.75,2.92306,,
1400.0243,286,2.92486,,
1400.02275,286.25,2.92601,,
1400.02317,286.5,2.92134,,
1400.02804,286.75,2.93441,,
1400.03263,287,2.93879,,
1400.03223,287.25,2.93895,,
1400.02645,287.5,2.94494,,
1400.02613,287.75,2.9478,,
1400.02787,288,2.94256,,
1400.0296,288.25,2.94148,,
1400.03121,288.5,2.93739,,
1400.02808,288.75,2.93679,,
1400.02829,289,2.93757,,
1400.02811,289.25,2.94068,,
1400.02738,289.5,2.93469,,
1400.02772,289.75,2.95318,,
1400.02779,290,2.9459,,
1400.03039,290.25,2.95038,,