File: ExampleData/T.3.1 Isothermal Section.csv
#EXPORTTYPE:DATA ALL,,,,
#FILE:,,,,
#FORMAT:NETZSCH5,,,,
#FTYPE:ANSI,,,,
#IDENTITY:,,,,
#DECIMAL:POINT,,,,
#SEPARATOR:SEMICOLON,,,,
#MTYPE:TG,,,,
#INSTRUMENT:NETZSCH STA 449F1,,,,
#PROJECT:,,,,
#DATE/TIME:31.01.2019 10:49,,,,
#CORR. FILE:,,,,
#TEMPCAL:TGA temperature calibration.ngb-ts1,,,,
#SENSITIVITY:---,,,,
#LABORATORY:,,,,
#OPERATOR:,,,,
#REMARK:,,,,
#SAMPLE:,,,,
#SAMPLE MASS /mg:942.11,,,,
#MATERIAL:,,,,
#REFERENCE:,,,,
#REFERENCE MASS /mg:,,,,
#TYPE OF CRUCIBLE:DTA/TG crucible Al2O3,,,,
#SAMPLE CRUCIBLE MASS /mg:0,,,,
#REFERENCE CRUCIBLE MASS /mg:,,,,
#TG RANGE /mg:5000,,,,
#TAU-R:---,,,,
#CORR. CODE:000,,,,
#EXO:-1,,,,
#RANGE:30°C....1400°C/0.0....50.0K/min,,,,
#SEGMENT:S1-4/4,,,,
#SEG. 1:30°C/50.0(K/min)/1300°C,,,,
#SEG. 2:1300°C/10.0(K/min)/1400°C,,,,
#SEG. 3:1400°C/00:15/1400°C,,,,
#SEG. 4:1400°C/04:00/1400°C,,,,
,,,surface area,2.68956
##Temp./°C,Time/min,Mass loss(subtr.)/mg,,
1400.03148,50.5,1.005611,,
1400.06442,50.75,1.0462484,,
1400.06462,51,1.0563766,,
1400.04674,51.25,1.070136,,
1400.0267,51.5,1.0787601,,
1400.01231,51.75,1.0906416,,
1400.00254,52,1.1013038,,
1400.00104,52.25,1.1099635,,
1400.00035,52.5,1.1171369,,
1399.99534,52.75,1.1232245,,
1399.99309,53,1.1287692,,
1399.99262,53.25,1.1393958,,
1399.99424,53.5,1.1404638,,
1399.99602,53.75,1.1464891,,
1399.99648,54,1.1492392,,
1399.99723,54.25,1.1628918,,
1399.99927,54.5,1.1713201,,
1399.99812,54.75,1.1799709,,
1399.9951,55,1.1786982,,
1399.99245,55.25,1.1839047,,
1399.99113,55.5,1.1854444,,
1399.99953,55.75,1.1878652,,
1400.0052,56,1.1992483,,
1400.01114,56.25,1.210934,,
1400.01226,56.5,1.2137998,,
1400.01164,56.75,1.2043925,,
1400.01046,57,1.2187215,,
1400.00865,57.25,1.2173064,,
1400.00775,57.5,1.2245421,,
1400.00773,57.75,1.2345635,,
1400.00773,58,1.2390936,,
1400.00273,58.25,1.2432766,,
1400.00905,58.5,1.2478245,,
1400.0131,58.75,1.2535205,,
1400.01922,59,1.2623404,,
1400.02078,59.25,1.2556743,,
1400.01674,59.5,1.2476732,,
1400.0142,59.75,1.2625718,,
1400.0116,60,1.2642628,,
1400.01212,60.25,1.2657224,,
1400.01718,60.5,1.2762333,,
1400.01813,60.75,1.2843857,,
1400.01882,61,1.2873583,,
1400.01713,61.25,1.2904466,,
1400.01292,61.5,1.3134264,,
1400.01126,61.75,1.2907047,,
1400.01291,62,1.3017407,,
1400.01769,62.25,1.30207,,
1400.02304,62.5,1.3099109,,
1400.02253,62.75,1.308745,,
1400.02216,63,1.3160697,,
1400.0211,63.25,1.3170487,,
1400.01985,63.5,1.3220238,,
1400.02402,63.75,1.3353204,,
1400.01915,64,1.321917,,
1400.01663,64.25,1.3261623,,
1400.01722,64.5,1.3295621,,
1400.01652,64.75,1.3396814,,
1400.02262,65,1.3421111,,
1400.02176,65.25,1.3431524,,
1400.02469,65.5,1.3468993,,
1400.02004,65.75,1.3491065,,
1400.02042,66,1.3516786,,
1400.02085,66.25,1.3652155,,
1400.02192,66.5,1.3529068,,
1400.02292,66.75,1.3572589,,
1400.02352,67,1.3702974,,
1400.02398,67.25,1.3647082,,
1400.0234,67.5,1.3654825,,
1400.0218,67.75,1.374071,,
1400.02252,68,1.3791173,,
1400.02151,68.25,1.3794911,,
1400.02188,68.5,1.3840301,,
1400.02159,68.75,1.3861394,,
1400.01935,69,1.3885958,,
1400.02264,69.25,1.3934107,,
1400.02329,69.5,1.3898418,,
1400.02638,69.75,1.402373,,
1400.02724,70,1.3993025,,
1400.02651,70.25,1.4064937,,
1400.02901,70.5,1.4064759,,
1400.02629,70.75,1.4103207,,
1400.02609,71,1.4095286,,
1400.02542,71.25,1.4207604,,
1400.0273,71.5,1.4094396,,
1400.02327,71.75,1.4273731,,
1400.02274,72,1.426848,,
1400.02036,72.25,1.4318142,,
1400.02451,72.5,1.4364689,,
1400.02731,72.75,1.4348936,,
1400.02814,73,1.4361574,,
1400.02937,73.25,1.4378484,,
1400.03048,73.5,1.4401446,,
1400.03048,73.75,1.4477185,,
1400.02873,74,1.4439093,,
1400.02832,74.25,1.4519193,,
1400.02568,74.5,1.44625,,
1400.02386,74.75,1.4548919,,
1400.02362,75,1.4525512,,
1400.02306,75.25,1.45693,,
1400.02701,75.5,1.4749881,,
1400.02508,75.75,1.4775869,,
1400.02477,76,1.4713124,,
1400.02466,76.25,1.4598848,,
1400.02242,76.5,1.4646819,,
1400.02145,76.75,1.4848048,,
1400.01939,77,1.481049,,
1400.01956,77.25,1.4754153,,
1400.02325,77.5,1.4936959,,
1400.0238,77.75,1.4854456,,
1400.027,78,1.4865848,,
1400.02579,78.25,1.4894061,,
1400.02632,78.5,1.4866649,,
1400.0258,78.75,1.4857838,,
1400.02618,79,1.4973894,,
1400.02701,79.25,1.5036906,,
1400.02641,79.5,1.5060491,,
1400.02426,79.75,1.5061203,,
1400.02414,80,1.5109263,,
1400.02475,80.25,1.5162574,,
1400.02119,80.5,1.5002196,,
1400.02389,80.75,1.5157857,,
1400.02426,81,1.5242941,,
1400.02731,81.25,1.5250684,,
1400.02798,81.5,1.5199865,,
1400.02737,81.75,1.524481,,
1400.02701,82,1.5188206,,
1400.02704,82.25,1.5208409,,
1400.02592,82.5,1.5311827,,
1400.0253,82.75,1.5290823,,
1400.02489,83,1.5326779,,
1400.02527,83.25,1.5383739,,
1400.02697,83.5,1.5361667,,
1400.02782,83.75,1.5441589,,
1400.02666,84,1.5495078,,
1400.02113,84.25,1.5371724,,
1400.02153,84.5,1.5467043,,
1400.02372,84.75,1.5584256,,
1400.02603,85,1.5513679,,
1400.02544,85.25,1.5602679,,
1400.0228,85.5,1.5542426,,
1400.02219,85.75,1.5604103,,
1400.02199,86,1.563196,,
1400.02409,86.25,1.5659105,,
1400.02441,86.5,1.5709657,,
1400.02708,86.75,1.561861,,
1400.02809,87,1.5769376,,
1400.02704,87.25,1.575478,,
1400.0243,87.5,1.5809337,,
1400.02452,87.75,1.5697197,,
1400.0249,88,1.5757183,,
1400.02654,88.25,1.5886233,,
1400.02467,88.5,1.5823043,,
1400.02496,88.75,1.5895934,,
1400.0222,89,1.5901719,,
1400.02571,89.25,1.603869,,
1400.02995,89.5,1.5850455,,
1400.02735,89.75,1.5972474,,
1400.02702,90,1.6042606,,
1400.02573,90.25,1.5992054,,
1400.02538,90.5,1.603157,,
1400.02589,90.75,1.6082567,,
1400.02457,91,1.6103927,,
1400.02471,91.25,1.6061919,,
1400.02569,91.5,1.5952716,,
1400.02614,91.75,1.6116743,,
1400.02766,92,1.6130449,,
1400.02814,92.25,1.6089598,,
1400.0272,92.5,1.611167,,
1400.02617,92.75,1.6132674,,
1400.02633,93,1.6202984,,
1400.02704,93.25,1.6236003,,
1400.02462,93.5,1.6372262,,
1400.02623,93.75,1.637155,,
1400.02152,94,1.6387926,,
1400.02094,94.25,1.6257986,,
1400.02342,94.5,1.6427976,,
1400.02707,94.75,1.6514039,,
1400.02853,95,1.6392287,,
1400.02618,95.25,1.6450137,,
1400.02456,95.5,1.6478172,,
1400.02437,95.75,1.6485826,,
1400.02462,96,1.6523651,,
1400.02402,96.25,1.6537535,,
1400.02355,96.5,1.6519379,,
1400.02317,96.75,1.6510924,,
1400.02234,97,1.6553822,,
1400.0227,97.25,1.6539493,,
1400.02361,97.5,1.6572601,,
1400.02154,97.75,1.6585951,,
1400.02117,98,1.6655282,,
1400.01852,98.25,1.6639529,,
1400.02002,98.5,1.6634545,,
1400.02232,98.75,1.6719985,,
1400.0256,99,1.6726571,,
1400.02552,99.25,1.6754784,,
1400.02289,99.5,1.6842894,,
1400.02512,99.75,1.6808006,,
1400.02493,100,1.6823492,,
1400.02865,100.25,1.6856511,,
1400.02768,100.5,1.6774809,,
1400.02814,100.75,1.6903147,,
1400.02862,101,1.6857223,,
1400.02895,101.25,1.69367,,
1400.02785,101.5,1.6903592,,
1400.02632,101.75,1.6895226,,
1400.02627,102,1.6960819,,
1400.02642,102.25,1.6962777,,
1400.02868,102.5,1.7012973,,
1400.02992,102.75,1.7025522,,
1400.02902,103,1.7029082,,
1400.02752,103.25,1.7037092,,
1400.02818,103.5,1.7038071,,
1400.02761,103.75,1.7137128,,
1400.02963,104,1.7113187,,
1400.02981,104.25,1.7120574,,
1400.0298,104.5,1.7127249,,
1400.0287,104.75,1.7176555,,
1400.02816,105,1.7218563,,
1400.02685,105.25,1.7231735,,
1400.02277,105.5,1.7233693,,
1400.02455,105.75,1.7214736,,
1400.02218,106,1.7201475,,
1400.02657,106.25,1.7270628,,
1400.02533,106.5,1.7300087,,
1400.02525,106.75,1.7314416,,
1400.02539,107,1.72749,,
1400.02717,107.25,1.7346456,,
1400.02657,107.5,1.740395,,
1400.02679,107.75,1.7426289,,
1400.02219,108,1.7440707,,
1400.02275,108.25,1.7443822,,
1400.02462,108.5,1.7459664,,
1400.02927,108.75,1.7489746,,
1400.02842,109,1.744489,,
1400.02751,109.25,1.750096,,
1400.02592,109.5,1.7454146,,
1400.02377,109.75,1.7566464,,
1400.02516,110,1.7767248,,
1400.02719,110.25,1.7655375,,
1400.03088,110.5,1.7545193,,
1400.03329,110.75,1.7644517,,
1400.02967,111,1.7501227,,
1400.02685,111.25,1.7718209,,
1400.02548,111.5,1.7716874,,
1400.02279,111.75,1.7699163,,
1400.02002,112,1.7670594,,
1400.02146,112.25,1.7700854,,
1400.02268,112.5,1.7661872,,
1400.02433,112.75,1.7765023,,
1400.02699,113,1.7780153,,
1400.02525,113.25,1.7732182,,
1400.02865,113.5,1.7789053,,
1400.02979,113.75,1.775906,,
1400.03101,114,1.7879477,,
1400.03153,114.25,1.7836579,,
1400.02897,114.5,1.7786205,,
1400.0282,114.75,1.7843788,,
1400.0275,115,1.7753097,,
1400.0258,115.25,1.7885084,,
1400.02405,115.5,1.7882948,,
1400.02462,115.75,1.7915522,,
1400.02561,116,1.7923621,,
1400.02616,116.25,1.7976932,,
1400.02522,116.5,1.8047331,,
1400.0253,116.75,1.8037986,,
1400.02714,117,1.8078659,,
1400.02795,117.25,1.8028908,,
1400.02763,117.5,1.7980759,,
1400.02752,117.75,1.808302,,
1400.0285,118,1.813108,,
1400.02936,118.25,1.8175046,,
1400.02935,118.5,1.8006391,,
1400.02901,118.75,1.8151194,,
1400.02825,119,1.8223996,,
1400.02737,119.25,1.8259062,,
1400.02669,119.5,1.8203259,,
1400.02658,119.75,1.8192312,,
1400.02547,120,1.8276239,,
1400.02176,120.25,1.8219813,,
1400.02395,120.5,1.8335691,,
1400.02607,120.75,1.8304185,,
1400.03045,121,1.8346727,,
1400.03051,121.25,1.8322252,,
1400.02779,121.5,1.8339251,,
1400.02617,121.75,1.8450857,,
1400.02718,122,1.8226399,,
1400.02699,122.25,1.8375385,,
1400.02892,122.5,1.8332398,,
1400.0261,122.75,1.8410718,,
1400.02179,123,1.8409205,,
1400.02216,123.25,1.8458422,,
1400.02582,123.5,1.8419173,,
1400.03111,123.75,1.848708,,
1400.03097,124,1.8444805,,
1400.03038,124.25,1.8548223,,
1400.02709,124.5,1.8512445,,
1400.02672,124.75,1.8481206,,
1400.02532,125,1.8518319,,
1400.02652,125.25,1.8532381,,
1400.02867,125.5,1.8615685,,
1400.02918,125.75,1.8592011,,
1400.02694,126,1.8615329,,
1400.02442,126.25,1.87078,,
1400.0236,126.5,1.8675938,,
1400.02401,126.75,1.8708957,,
1400.02529,127,1.8655913,,
1400.02543,127.25,1.8643186,,
1400.02615,127.5,1.8719281,,
1400.02645,127.75,1.881371,,
1400.02582,128,1.8801072,,
1400.02599,128.25,1.877633,,
1400.02743,128.5,1.8800093,,
1400.02793,128.75,1.878612,,
1400.02913,129,1.8777487,,
1400.02907,129.25,1.8774372,,
1400.02963,129.5,1.8935017,,
1400.02895,129.75,1.8871204,,
1400.03105,130,1.8916416,,
1400.03034,130.25,1.8856964,,
1400.02735,130.5,1.8916861,,
1400.02925,130.75,1.9002123,,
1400.02751,131,1.8988684,,
1400.02936,131.25,1.9004615,,
1400.02907,131.5,1.8974978,,
1400.02533,131.75,1.9045466,,
1400.02456,132,1.8886334,,
1400.02408,132.25,1.9062732,,
1400.02636,132.5,1.8986103,,
1400.02607,132.75,1.9049471,,
1400.02422,133,1.8962785,,
1400.02701,133.25,1.9080799,,
1400.02693,133.5,1.9073056,,
1400.03245,133.75,1.9171045,,
1400.02745,134,1.9176563,,
1400.02803,134.25,1.9162234,,
1400.02654,134.5,1.9228806,,
1400.02804,134.75,1.9119959,,
1400.02571,135,1.9251056,,
1400.02793,135.25,1.926138,,
1400.02612,135.5,1.9188489,,
1400.02446,135.75,1.9232544,,
1400.02064,136,1.9278646,,
1400.02076,136.25,1.9295378,,
1400.02254,136.5,1.9361505,,
1400.02756,136.75,1.9262181,,
1400.02488,137,1.934593,,
1400.02212,137.25,1.9399152,,
1400.02221,137.5,1.9380818,,
1400.02293,137.75,1.9333559,,
1400.02635,138,1.934771,,
1400.03063,138.25,1.941357,,
1400.02945,138.5,1.9270547,,
1400.0277,138.75,1.9524019,,
1400.0276,139,1.9503816,,
1400.03033,139.25,1.9513784,,
1400.03062,139.5,1.9509779,,
1400.02901,139.75,1.937085,,
1400.0286,140,1.9552855,,
1400.02919,140.25,1.9575639,,
1400.0291,140.5,1.9577864,,
1400.02687,140.75,1.9522951,,
1400.0243,141,1.9570388,,
1400.02614,141.25,1.9643724,,
1400.02803,141.5,1.9669267,,
1400.02799,141.75,1.9657519,,
1400.02798,142,1.9645326,,
1400.02683,142.25,1.961293,,
1400.0268,142.5,1.9564069,,
1400.02716,142.75,1.9718395,,
1400.0276,143,1.9635091,,
1400.02736,143.25,1.9608925,,
1400.02514,143.5,1.9715458,,
1400.0262,143.75,1.964497,,
1400.0264,144,1.9766811,,
1400.02733,144.25,1.9759157,,
1400.02764,144.5,1.9820389,,
1400.02743,144.75,1.9834362,,
1400.02807,145,1.9838456,,
1400.02619,145.25,1.9785857,,
1400.02501,145.5,1.9698904,,
1400.02627,145.75,1.9791553,,
1400.02748,146,1.9961899,,
1400.03082,146.25,1.998228,,
1400.02656,146.5,1.9839346,,
1400.02457,146.75,1.9811222,,
1400.02605,147,1.9926833,,
1400.03018,147.25,2.0039418,,
1400.03746,147.5,1.9859282,,
1400.03615,147.75,1.9965637,,
1400.03403,148,1.9974715,,
1400.03194,148.25,2.0110262,,
1400.02663,148.5,2.0060244,,
1400.02552,148.75,2.0166866,,
1400.02376,149,2.0059443,,
1400.02498,149.25,1.9936267,,
1400.022,149.5,2.0101718,,
1400.02413,149.75,2.0236998,,
1400.02441,150,2.002233,,
1400.03038,150.25,2.0105812,,
1400.02947,150.5,2.0046894,,
1400.02991,150.75,2.0215549,,
1400.02682,151,2.0249636,,
1400.0254,151.25,2.0143281,,
1400.02623,151.5,2.0206649,,
1400.02433,151.75,2.0305172,,
1400.02828,152,2.0245275,,
1400.02382,152.25,2.0154584,,
1400.02586,152.5,2.0292534,,
1400.02573,152.75,2.0304638,,
1400.02839,153,2.0328935,,
1400.03178,153.25,2.0327689,,
1400.02868,153.5,2.0336233,,
1400.02966,153.75,2.0291555,,
1400.02992,154,2.0314873,,
1400.03014,154.25,2.0419893,,
1400.02771,154.5,2.0343353,,
1400.02814,154.75,2.0249547,,
1400.02746,155,2.0546273,,
1400.026,155.25,2.0441876,,
1400.02827,155.5,2.0396397,,
1400.0269,155.75,2.0485219,,
1400.02591,156,2.0507291,,
1400.02665,156.25,2.0497412,,
1400.02644,156.5,2.0464393,,
1400.02422,156.75,2.0499548,,
1400.02741,157,2.0552592,,
1400.03105,157.25,2.0619965,,
1400.03753,157.5,2.045665,,
1400.04177,157.75,2.0576978,,
1400.03676,158,2.0570926,,
1400.03128,158.25,2.0539153,,
1400.03062,158.5,2.0665088,,
1400.02769,158.75,2.059104,,
1400.02519,159,2.075747,,
1400.02475,159.25,2.0607149,,
1400.02559,159.5,2.0584365,,
1400.02578,159.75,2.0523578,,
1400.02606,160,2.0616138,,
1400.02621,160.25,2.0662774,,
1400.03047,160.5,2.0687783,,
1400.0347,160.75,2.0909482,,
1400.02899,161,2.0821995,,
1400.02873,161.25,2.0642037,,
1400.02816,161.5,2.0765569,,
1400.03182,161.75,2.0879667,,
1400.03179,162,2.0821995,,
1400.03105,162.25,2.0748926,,
1400.02794,162.5,2.0794939,,
1400.02726,162.75,2.0766637,,
1400.02601,163,2.0821194,,
1400.02486,163.25,2.1005869,,
1400.02566,163.5,2.0965463,,
1400.02339,163.75,2.0986378,,
1400.0217,164,2.0876552,,
1400.02334,164.25,2.0961458,,
1400.02645,164.5,2.0966887,,
1400.03101,164.75,2.0874416,,
1400.03356,165,2.1018685,,
1400.0338,165.25,2.0964662,,
1400.03218,165.5,2.1063452,,
1400.03102,165.75,2.0993142,,
1400.03172,166,2.1166336,,
1400.02909,166.25,2.1048856,,
1400.02932,166.5,2.1036485,,
1400.02831,166.75,2.1073242,,
1400.02789,167,2.1226856,,
1400.02986,167.25,2.1006314,,
1400.02852,167.5,2.0978635,,
1400.02655,167.75,2.1260053,,
1400.02675,168,2.1162776,,
1400.02787,168.25,2.1232196,,
1400.02654,168.5,2.0998037,,
1400.02841,168.75,2.1108219,,
1400.02688,169,2.1045029,,
1400.02716,169.25,2.110991,,
1400.0268,169.5,2.1226233,,
1400.02526,169.75,2.1289156,,
1400.02602,170,2.1217333,,
1400.02772,170.25,2.1349854,,
1400.03086,170.5,2.1142751,,
1400.03146,170.75,2.1206831,,
1400.0291,171,2.1106083,,
1400.02979,171.25,2.1298234,,
1400.03195,171.5,2.1362225,,
1400.03235,171.75,2.1264503,,
1400.03177,172,2.116509,,
1400.03347,172.25,2.1389726,,
1400.03489,172.5,2.131283,,
1400.03672,172.75,2.1302862,,
1400.03027,173,2.1347095,,
1400.02741,173.25,2.1399516,,
1400.02722,173.5,2.1456654,,
1400.0254,173.75,2.1504269,,
1400.02737,174,2.1471962,,
1400.02307,174.25,2.165993,,
1400.02087,174.5,2.1467334,,
1400.02078,174.75,2.1588641,,
1400.02481,175,2.1488071,,
1400.02843,175.25,2.1382784,,
1400.03467,175.5,2.1685028,,
1400.03291,175.75,2.1420965,,
1400.02881,176,2.1590332,,
1400.02728,176.25,2.1508541,,
1400.02616,176.5,2.1601368,,
1400.02863,176.75,2.1608399,,
1400.0306,177,2.1574668,,
1400.0291,177.25,2.1611959,,
1400.0249,177.5,2.1705676,,
1400.02175,177.75,2.169998,,
1400.02053,178,2.1718759,,
1400.02324,178.25,2.168663,,
1400.02628,178.5,2.1619969,,
1400.0288,178.75,2.1709859,,
1400.02531,179,2.1721963,,
1400.0219,179.25,2.1708702,,
1400.02281,179.5,2.1708168,,
1400.02616,179.75,2.1719382,,
1400.03094,180,2.1703006,,
1400.03648,180.25,2.1833658,,
1400.03343,180.5,2.1848165,,
1400.03436,180.75,2.1874598,,
1400.02972,181,2.1782038,,
1400.03137,181.25,2.1733533,,
1400.03034,181.5,2.1810785,,
1400.03019,181.75,2.1818439,,
1400.03306,182,2.1826182,,
1400.0308,182.25,2.1900141,,
1400.03123,182.5,2.2105286,,
1400.03109,182.75,2.1933249,,
1400.02765,183,2.203996,,
1400.02726,183.25,2.2009077,,
1400.03032,183.5,2.1995994,,
1400.02891,183.75,2.2045478,,
1400.02788,184,2.1844783,,
1400.02172,184.25,2.1954876,,
1400.02055,184.5,2.1944285,,
1400.0243,184.75,2.1938055,,
1400.0235,185,2.1996795,,
1400.02602,185.25,2.1951405,,
1400.02671,185.5,2.2180758,,
1400.03002,185.75,2.186819,,
1400.03512,186,2.2328231,,
1400.03482,186.25,2.2034442,,
1400.03225,186.5,2.2215112,,
1400.02935,186.75,2.2118903,,
1400.02841,187,2.2071466,,
1400.03,187.25,2.2255607,,
1400.02952,187.5,2.1917585,,
1400.03396,187.75,2.2222499,,
1400.03175,188,2.2240032,,
1400.02675,188.25,2.2230242,,
1400.02104,188.5,2.213786,,
1400.0233,188.75,2.2255073,,
1400.02126,189,2.2386615,,
1400.02717,189.25,2.2205322,,
1400.03135,189.5,2.2372731,,
1400.03445,189.75,2.2365344,,
1400.03805,190,2.2353329,,
1400.03937,190.25,2.2161445,,
1400.03725,190.5,2.2339712,,
1400.03399,190.75,2.2441439,,
1400.03204,191,2.247428,,
1400.02789,191.25,2.2344874,,
1400.0268,191.5,2.2392311,,
1400.02585,191.75,2.2495551,,
1400.02828,192,2.2480599,,
1400.02795,192.25,2.2347277,,
1400.02737,192.5,2.2483803,,
1400.02848,192.75,2.2538004,,
1400.02867,193,2.2509079,,
1400.0321,193.25,2.248941,,
1400.02972,193.5,2.2470631,,
1400.02948,193.75,2.2353329,,
1400.02601,194,2.2400677,,
1400.02569,194.25,2.2646851,,
1400.02632,194.5,2.2510058,,
1400.02782,194.75,2.2643202,,
1400.02901,195,2.2572269,,
1400.0292,195.25,2.2435832,,
1400.03121,195.5,2.264605,,
1400.0298,195.75,2.2475081,,
1400.02683,196,2.2523052,,
1400.02638,196.25,2.2505163,,
1400.0256,196.5,2.2694644,,
1400.02445,196.75,2.2761038,,
1400.027,197,2.2544501,,
1400.02662,197.25,2.2675153,,
1400.02985,197.5,2.2652725,,
1400.02933,197.75,2.2753295,,
1400.03086,198,2.292195,,
1400.02989,198.25,2.2924709,,
1400.02901,198.5,2.2721789,,
1400.02958,198.75,2.2428534,,
1400.02822,199,2.2737898,,
1400.028,199.25,2.260066,,
1400.02914,199.5,2.270746,,
1400.02862,199.75,2.2836243,,
1400.02988,200,2.2661803,,
1400.02878,200.25,2.276976,,
1400.028,200.5,2.2831259,,
1400.02992,200.75,2.2867482,,
1400.03128,201,2.2863032,,
1400.03071,201.25,2.2974816,,
1400.03122,201.5,2.2902459,,
1400.0331,201.75,2.2749468,,
1400.03025,202,2.3004186,,
1400.02622,202.25,2.2879853,,
1400.02518,202.5,2.2860451,,
1400.02656,202.75,2.2817464,,
1400.0277,203,2.2901124,,
1400.02898,203.25,2.2879497,,
1400.02977,203.5,2.2954079,,
1400.02961,203.75,2.2950074,,
1400.02445,204,2.2966361,,
1400.02371,204.25,2.3074407,,
1400.02432,204.5,2.3001249,,
1400.02892,204.75,2.2991904,,
1400.03249,205,2.2978732,,
1400.02948,205.25,2.2999647,,
1400.02713,205.5,2.3149879,,
1400.02508,205.75,2.3181474,,
1400.02234,206,2.3074051,,
1400.02335,206.25,2.3125048,,
1400.02545,206.5,2.3225529,,
1400.02817,206.75,2.3059188,,
1400.03009,207,2.3001694,,
1400.03021,207.25,2.3120064,,
1400.02769,207.5,2.3190196,,
1400.02421,207.75,2.311953,,
1400.02133,208,2.3162072,,
1400.02345,208.25,2.3087312,,
1400.02475,208.5,2.3133147,,
1400.02629,208.75,2.3284892,,
1400.02872,209,2.2932719,,
1400.02959,209.25,2.3238701,,
1400.03366,209.5,2.3288808,,
1400.02959,209.75,2.3306341,,
1400.02781,210,2.3270474,,
1400.0283,210.25,2.3295038,,
1400.03195,210.5,2.3315686,,
1400.03094,210.75,2.3270118,,
1400.03255,211,2.3317911,,
1400.03031,211.25,2.3457908,,
1400.02856,211.5,2.3118551,,
1400.02908,211.75,2.3321026,,
1400.02863,212,2.3212446,,
1400.02932,212.25,2.3344878,,
1400.03044,212.5,2.3486299,,
1400.03075,212.75,2.3602355,,
1400.03378,213,2.3530443,,
1400.033,213.25,2.3419727,,
1400.03095,213.5,2.3432098,,
1400.0302,213.75,2.3384127,,
1400.02839,214,2.3444914,,
1400.02891,214.25,2.3432187,,
1400.02907,214.5,2.3532223,,
1400.03055,214.75,2.3463159,,
1400.03267,215,2.3556253,,
1400.0334,215.25,2.3563017,,
1400.02903,215.5,2.3597371,,
1400.02771,215.75,2.3677649,,
1400.02709,216,2.3554206,,
1400.02912,216.25,2.3541835,,
1400.02547,216.5,2.3566755,,
1400.02281,216.75,2.3532223,,
1400.02413,217,2.3621846,,
1400.02668,217.25,2.3540144,,
1400.03003,217.5,2.3668482,,
1400.02886,217.75,2.3637332,,
1400.025,218,2.3598617,,
1400.02368,218.25,2.3620778,,
1400.02729,218.5,2.3795218,,
1400.02817,218.75,2.3707375,,
1400.03462,219,2.3734431,,
1400.03286,219.25,2.3907002,,
1400.03098,219.5,2.3711647,,
1400.02998,219.75,2.3659849,,
1400.02666,220,2.36473,,
1400.02696,220.25,2.3723128,,
1400.02532,220.5,2.3884841,,
1400.02231,220.75,2.3852623,,
1400.0235,221,2.3848796,,
1400.02752,221.25,2.3890626,,
1400.03221,221.5,2.3875941,,
1400.03327,221.75,2.3941089,,
1400.03394,222,2.3796553,,
1400.03102,222.25,2.3724196,,
1400.02694,222.5,2.3742975,,
1400.02887,222.75,2.3837226,,
1400.02925,223,2.3936817,,
1400.03448,223.25,2.389205,,
1400.03007,223.5,2.3908871,,
1400.02793,223.75,2.4058836,,
1400.02618,224,2.3972061,,
1400.02941,224.25,2.406204,,
1400.03336,224.5,2.3963695,,
1400.03437,224.75,2.3969124,,
1400.03708,225,2.4093546,,
1400.03589,225.25,2.4248495,,
1400.03568,225.5,2.4224821,,
1400.03149,225.75,2.4031157,,
1400.02875,226,2.3880302,,
1400.0262,226.25,2.4195184,,
1400.02519,226.5,2.3992175,,
1400.02553,226.75,2.4065333,,
1400.02288,227,2.4243778,,
1400.02648,227.25,2.4014603,,
1400.02985,227.5,2.4081353,,
1400.03099,227.75,2.4285252,,
1400.0329,228,2.4197231,,
1400.03103,228.25,2.4192336,,
1400.03296,228.5,2.4200524,,
1400.0274,228.75,2.4106807,,
1400.02385,229,2.4116508,,
1400.02134,229.25,2.435663,,
1400.02355,229.5,2.4403266,,
1400.02342,229.75,2.4217879,,
1400.02691,230,2.4269232,,
1400.02761,230.25,2.423114,,
1400.02961,230.5,2.4305277,,
1400.02921,230.75,2.4217968,,
1400.02163,231,2.4385733,,
1400.02202,231.25,2.4380215,,
1400.02399,231.5,2.4226245,,
1400.02923,231.75,2.4319962,,
1400.03272,232,2.4465032,,
1400.03281,232.25,2.4215387,,
1400.03361,232.5,2.446877,,
1400.03556,232.75,2.4437442,,
1400.03593,233,2.4386178,,
1400.03533,233.25,2.4352892,,
1400.03493,233.5,2.4426406,,
1400.02982,233.75,2.4425783,,
1400.02411,234,2.4566136,,
1400.02561,234.25,2.4448656,,
1400.02618,234.5,2.4400685,,
1400.03071,234.75,2.4537122,,
1400.02569,235,2.4511846,,
1400.02369,235.25,2.452751,,
1400.02122,235.5,2.4496627,,
1400.02764,235.75,2.4415815,,
1400.03085,236,2.4549404,,
1400.03087,236.25,2.456489,,
1400.03004,236.5,2.447055,,
1400.0264,236.75,2.4564712,,
1400.02666,237,2.4429966,,
1400.02837,237.25,2.4610636,,
1400.0281,237.5,2.4584114,,
1400.02733,237.75,2.4591234,,
1400.02304,238,2.444652,,
1400.02297,238.25,2.4659764,,
1400.02413,238.5,2.4768611,,
1400.0273,238.75,2.452484,,
1400.0269,239,2.4602003,,
1400.02799,239.25,2.4690558,,
1400.02872,239.5,2.4519589,,
1400.03074,239.75,2.4788903,,
1400.03071,240,2.480608,,
1400.03119,240.25,2.4856543,,
1400.03046,240.5,2.4679789,,
1400.03009,240.75,2.4907095,,
1400.02547,241,2.4698924,,
1400.02159,241.25,2.4737728,,
1400.02307,241.5,2.4702217,,
1400.02405,241.75,2.4791573,,
1400.02956,242,2.4720996,,
1400.02992,242.25,2.4838031,,
1400.03123,242.5,2.4681925,,
1400.03144,242.75,2.476514,,
1400.03194,243,2.5036234,,
1400.03187,243.25,2.4842036,,
1400.03261,243.5,2.4941449,,
1400.03282,243.75,2.4834916,,
1400.03174,244,2.4769679,,
1400.02816,244.25,2.4798515,,
1400.02558,244.5,2.5009979,,
1400.02358,244.75,2.4821566,,
1400.02347,245,2.4936999,,
1400.02898,245.25,2.5009623,,
1400.02877,245.5,2.5055814,,
1400.03117,245.75,2.4940737,,
1400.03142,246,2.4892944,,
1400.03257,246.25,2.4873453,,
1400.03319,246.5,2.5064447,,
1400.03684,246.75,2.4949637,,
1400.038,247,2.5199104,,
1400.03669,247.25,2.4992001,,
1400.03644,247.5,2.5126836,,
1400.0355,247.75,2.4991467,,
1400.036,248,2.5093639,,
1400.03014,248.25,2.4932727,,
1400.02614,248.5,2.4948836,,
1400.0267,248.75,2.5102094,,
1400.0278,249,2.5290596,,
1400.03103,249.25,2.5002681,,
1400.0308,249.5,2.5018612,,
1400.02869,249.75,2.5091859,,
1400.02794,250,2.4991823,,
1400.02625,250.25,2.5185131,,
1400.027,250.5,2.5102361,,
1400.02761,250.75,2.5388941,,
1400.02697,251,2.5302611,,
1400.02675,251.25,2.5144903,,
1400.02573,251.5,2.5234526,,
1400.02486,251.75,2.5204889,,
1400.02685,252,2.5274131,,
1400.02454,252.25,2.5176676,,
1400.02798,252.5,2.5193319,,
1400.02608,252.75,2.5252059,,
1400.02407,253,2.5201418,,
1400.02811,253.25,2.5216014,,
1400.02718,253.5,2.5180414,,
1400.03412,253.75,2.5360728,,
1400.03425,254,2.517632,,
1400.03626,254.25,2.5078242,,
1400.02879,254.5,2.5357524,,
1400.02213,254.75,2.5360906,,
1400.01883,255,2.5270482,,
1400.01854,255.25,2.5342483,,
1400.0244,255.5,2.5431305,,
1400.02493,255.75,2.5331091,,
1400.02741,256,2.5365178,,
1400.02275,256.25,2.5469931,,
1400.01876,256.5,2.5460497,,
1400.02256,256.75,2.5484794,,
1400.02995,257,2.5303323,,
1400.03319,257.25,2.5476962,,
1400.03347,257.5,2.5543534,,
1400.03339,257.75,2.553321,,
1400.03363,258,2.5346488,,
1400.0354,258.25,2.5523509,,
1400.03133,258.5,2.5415107,,
1400.0293,258.75,2.5712278,,
1400.02633,259,2.5611085,,
1400.02422,259.25,2.5482391,,
1400.02459,259.5,2.5517279,,
1400.02251,259.75,2.5448571,,
1400.02495,260,2.537746,,
1400.02495,260.25,2.5629152,,
1400.02741,260.5,2.5502416,,
1400.0288,260.75,2.5678458,,
1400.02553,261,2.5453199,,
1400.02535,261.25,2.5676411,,
1400.02105,261.5,2.5581626,,
1400.02082,261.75,2.5622833,,
1400.02341,262,2.5678547,,
1400.02805,262.25,2.5806707,,
1400.03179,262.5,2.5739334,,
1400.03451,262.75,2.5697237,,
1400.03444,263,2.5542644,,
1400.03176,263.25,2.5713524,,
1400.02954,263.5,2.571477,,
1400.03015,263.75,2.5648109,,
1400.03249,264,2.5759804,,
1400.03707,264.25,2.5778939,,
1400.03631,264.5,2.5676767,,
1400.03389,264.75,2.5684421,,
1400.03172,265,2.5884226,,
1400.03287,265.25,2.5764521,,
1400.03449,265.5,2.5673652,,
1400.03514,265.75,2.5884493,,
1400.03604,266,2.5732748,,
1400.03371,266.25,2.5777782,,
1400.0306,266.5,2.5808932,,
1400.02713,266.75,2.5892058,,
1400.02446,267,2.6010873,,
1400.02041,267.25,2.5831627,,
1400.02134,267.5,2.597198,,
1400.02153,267.75,2.579487,,
1400.02455,268,2.57833,,
1400.02365,268.25,2.5865358,,
1400.02455,268.5,2.6005088,,
1400.02491,268.75,2.6059289,,
1400.02595,269,2.5771196,,
1400.02746,269.25,2.6043803,,
1400.02966,269.5,2.6007224,,
1400.0307,269.75,2.5879598,,
1400.02929,270,2.5839904,,
1400.02737,270.25,2.6076644,,
1400.02635,270.5,2.6318457,,
1400.02517,270.75,2.5833585,,
1400.02663,271,2.6014433,,
1400.02895,271.25,2.5998057,,
1400.03251,271.5,2.5953379,,
1400.03196,271.75,2.6050033,,
1400.02836,272,2.6168937,,
1400.02897,272.25,2.5759003,,
1400.02892,272.5,2.6038552,,
1400.02996,272.75,2.6049766,,
1400.03084,273,2.611082,,
1400.03049,273.25,2.6052347,,
1400.02956,273.5,2.6061781,,
1400.02876,273.75,2.6149268,,
1400.02722,274,2.6119987,,
1400.02671,274.25,2.6104234,,
1400.02799,274.5,2.6257492,,
1400.02911,274.75,2.6076377,,
1400.02501,275,2.597465,,
1400.02732,275.25,2.6097559,,
1400.02846,275.5,2.6285349,,
1400.02981,275.75,2.608768,,
1400.03359,276,2.6201689,,
1400.03299,276.25,2.6273245,,
1400.03387,276.5,2.6057153,,
1400.03255,276.75,2.6328158,,
1400.03049,277,2.6170717,,
1400.03105,277.25,2.6137075,,
1400.03115,277.5,2.631997,,
1400.03029,277.75,2.613396,,
1400.0291,278,2.6317389,,
1400.02562,278.25,2.6060802,,
1400.02889,278.5,2.6184868,,
1400.02703,278.75,2.63974,,
1400.03094,279,2.6366072,,
1400.03261,279.25,2.6337859,,
1400.0332,279.5,2.6342665,,
1400.03138,279.75,2.6314274,,
1400.02897,280,2.6305908,,
1400.02488,280.25,2.6329849,,
1400.02579,280.5,2.6384139,,
1400.02645,280.75,2.6519241,,
1400.0266,281,2.6419294,,
1400.02726,281.25,2.6410305,,
1400.02662,281.5,2.6358774,,
1400.02722,281.75,2.639918,,
1400.02856,282,2.6449554,,
1400.02874,282.25,2.6562584,,
1400.02467,282.5,2.6432555,,
1400.02405,282.75,2.6451601,,
1400.02389,283,2.6377108,,
1400.0262,283.25,2.6396955,,
1400.02956,283.5,2.6495923,,
1400.02698,283.75,2.6549234,,
1400.02621,284,2.6546297,,
1400.0239,284.25,2.6326823,,
1400.02408,284.5,2.6554663,,
1400.02621,284.75,2.6420985,,
1400.02735,285,2.644279,,
1400.02701,285.25,2.6438696,,
1400.02592,285.5,2.6493342,,
1400.02531,285.75,2.642143,,
1400.02637,286,2.6716999,,
1400.02709,286.25,2.6636009,,
1400.02753,286.5,2.6581897,,
1400.02792,286.75,2.6467176,,
1400.02895,287,2.6650249,,
1400.03044,287.25,2.6504289,,
1400.02966,287.5,2.652111,,
1400.02769,287.75,2.6862069,,
1400.02968,288,2.6684692,,
1400.03056,288.25,2.6766127,,
1400.03435,288.5,2.6522534,,
1400.03321,288.75,2.6472961,,
1400.0288,289,2.6656657,,
1400.0264,289.25,2.6553773,,
1400.02718,289.5,2.6596048,,
1400.02858,289.75,2.6869545,,
1400.03339,290,2.6641794,,
1400.03249,290.25,2.6795408,,